Workbook

Sheet Sheet1
A1: 序号 | B1: 商品条码 | C1: 品牌名称 | D1: 商品型号 | E1: 能效标识 | F1: 类型 | G1: 国补刷单的能效标识 | H1: 备注 | L1: 型号 | M1: 能效标识
A2: 1 | B2: 6920971957629 | C2: A.O.史密斯 | D2: L1PB20-V3 | E2: 2 | F2: 采暖炉 | G2: 2 | I2: =VLOOKUP(D2,Sheet2!H:I,2,0) -> 二级 | J2: =VLOOKUP(D2,L:M,2,0) -> 2 | L2: EWH-6B2 | M2: 2
A3: 2 | B3: 6920971957582 | C3: A.O.史密斯 | D3: L1PB26-V3 | E3: 2 | F3: 采暖炉 | G3: 2 | I3: =VLOOKUP(D3,Sheet2!H:I,2,0) -> 二级 | J3: =VLOOKUP(D3,L:M,2,0) -> 2 | L3: EWH-10A2 | M3: 3
A4: 3 | B4: 6920971958954 | C4: A.O.史密斯 | D4: L1PB33-V3 | E4: 2 | F4: 采暖炉 | G4: 2 | I4: =VLOOKUP(D4,Sheet2!H:I,2,0) -> 二级 | J4: =VLOOKUP(D4,L:M,2,0) -> 2 | L4: EWH-10B2 | M4: 3
A5: 4 | B5: 6920971961817 | C5: A.O.史密斯 | D5: L1PB26-V9 | E5: 2 | F5: 采暖炉 | G5: 2 | I5: =VLOOKUP(D5,Sheet2!H:I,2,0) -> 二级 | J5: =VLOOKUP(D5,L:M,2,0) -> 2 | L5: EWH-6C2
A6: 5 | B6: 6920971961824 | C6: A.O.史密斯 | D6: L1PB33-V9 | E6: 2 | F6: 采暖炉 | G6: 2 | I6: =VLOOKUP(D6,Sheet2!H:I,2,0) -> 二级 | J6: =VLOOKUP(D6,L:M,2,0) -> 2 | L6: CEWH-60A0 | M6: 1
A7: 6 | B7: 6920971961831 | C7: A.O.史密斯 | D7: L1PB37-V9 | E7: 2 | F7: 采暖炉 | G7: 2 | I7: =VLOOKUP(D7,Sheet2!H:I,2,0) -> 二级 | J7: =VLOOKUP(D7,L:M,2,0) -> 2 | L7: CEWH-80A0 | M7: 1
A8: 7 | B8: 6920971962760 | C8: A.O.史密斯 | D8: LL1GBQ24-V10 | E8: 1 | F8: 采暖炉 | G8: 1 | I8: =VLOOKUP(D8,Sheet2!H:I,2,0) -> 一级 | J8: =VLOOKUP(D8,L:M,2,0) -> 1 | L8: CEWH-60BS-B | M8: 1
A9: 8 | B9: 6920971962777 | C9: A.O.史密斯 | D9: LL1GBQ33-V10 | E9: 1 | F9: 采暖炉 | G9: 1 | I9: =VLOOKUP(D9,Sheet2!H:I,2,0) -> 一级 | J9: =VLOOKUP(D9,L:M,2,0) -> 1 | L9: CEWH-50D0 | M9: 1
A10: 9 | B10: 6920971964672 | C10: A.O.史密斯 | D10: LL1GBQ24-V11 | E10: 1 | F10: 采暖炉 | G10: 1 | I10: =VLOOKUP(D10,Sheet2!H:I,2,0) -> 一级 | J10: =VLOOKUP(D10,L:M,2,0) -> 1 | L10: CEWH-60D0 | M10: 1
A11: 10 | B11: 6920971964689 | C11: A.O.史密斯 | D11: LL1GBQ33-V11 | E11: 1 | F11: 采暖炉 | G11: 1 | I11: =VLOOKUP(D11,Sheet2!H:I,2,0) -> 一级 | J11: =VLOOKUP(D11,L:M,2,0) -> 1 | L11: CEWH-60D0B | M11: 1
A12: 11 | B12: 6920971962876 | C12: A.O.史密斯 | D12: L1PB26-CA | E12: 2 | F12: 采暖炉 | G12: 2 | I12: =VLOOKUP(D12,Sheet2!H:I,2,0) -> 二级 | J12: =VLOOKUP(D12,L:M,2,0) -> 2 | L12: CEWH-80D0 | M12: 1
A13: 12 | B13: 6920971970918 | C13: A.O.史密斯 | D13: L1PB20-A1 | E13: 2 | F13: 采暖炉 | G13: 2 | I13: =VLOOKUP(D13,Sheet2!H:I,2,0) -> 二级 | J13: =VLOOKUP(D13,L:M,2,0) -> 2 | L13: CEWH-60D1BWi | M13: 1
A14: 13 | B14: 6920971970925 | C14: A.O.史密斯 | D14: L1PB26-A1 | E14: 2 | F14: 采暖炉 | G14: 2 | I14: =VLOOKUP(D14,Sheet2!H:I,2,0) -> 二级 | J14: =VLOOKUP(D14,L:M,2,0) -> 2 | L14: CEWH-60D1Wi | M14: 1
A15: 14 | B15: 6920971969509 | C15: A.O.史密斯 | D15: L1PB26-S9 | E15: 2 | F15: 采暖炉 | G15: 2 | I15: =VLOOKUP(D15,Sheet2!H:I,2,0) -> 二级 | J15: =VLOOKUP(D15,L:M,2,0) -> 2 | L15: CEWH-80D1Wi | M15: 1
A16: 15 | B16: 6920971969516 | C16: A.O.史密斯 | D16: L1PB33-S9 | E16: 2 | F16: 采暖炉 | G16: 2 | I16: =VLOOKUP(D16,Sheet2!H:I,2,0) -> 二级 | J16: =VLOOKUP(D16,L:M,2,0) -> 2 | L16: CEWH-50AS | M16: 1
A17: 16 | B17: 6920971969523 | C17: A.O.史密斯 | D17: L1PB37-S9 | E17: 2 | F17: 采暖炉 | G17: 2 | I17: =VLOOKUP(D17,Sheet2!H:I,2,0) -> 二级 | J17: =VLOOKUP(D17,L:M,2,0) -> 2 | L17: CEWH-60AS | M17: 1
... A34: 33 | B34: 6920971969905 | C34: A.O.史密斯 | D34: LN1GBQ52-S15 | E34: 1 | F34: 采暖炉 | G34: 1 | I34: =VLOOKUP(D34,Sheet2!H:I,2,0) -> 一级 | J34: =VLOOKUP(D34,L:M,2,0) -> 1 | L34: CEWH-80K | M34: 1
A35: 34 | B35: 6920971969912 | C35: A.O.史密斯 | D35: LN1GBQ65-S15 | E35: 1 | F35: 采暖炉 | G35: 1 | I35: =VLOOKUP(D35,Sheet2!H:I,2,0) -> 一级 | J35: =VLOOKUP(D35,L:M,2,0) -> 1 | L35: CEWH-100K
A36: 35 | B36: 6951142566234 | C36: A.O.史密斯 | D36: R1200HWi-E | E36: 2 | F36: 净水机 | G36: 2 | I36: =VLOOKUP(D36,Sheet2!H:I,2,0) -> 二级 | J36: =VLOOKUP(D36,L:M,2,0) -> 2 | L36: CEWH-60KBWi | M36: 1
A37: 36 | B37: 6951142564353 | C37: A.O.史密斯 | D37: R1400XF2 | E37: 1 | F37: 净水机 | G37: 1 | I37: =VLOOKUP(D37,Sheet2!H:I,2,0) -> 一级 | J37: =VLOOKUP(D37,L:M,2,0) -> 1 | L37: CEWH-60KWi | M37: 1
A38: 37 | B38: 6951142564476 | C38: A.O.史密斯 | D38: R1700XF2 | E38: 1 | F38: 净水机 | G38: 1 | I38: =VLOOKUP(D38,Sheet2!H:I,2,0) -> 一级 | J38: =VLOOKUP(D38,L:M,2,0) -> 1 | L38: CEWH-80KWi | M38: 1
A39: 38 | B39: 6951142565923 | C39: A.O.史密斯 | D39: R1700XF1 | E39: 1 | F39: 净水机 | G39: 1 | I39: =VLOOKUP(D39,Sheet2!H:I,2,0) -> 一级 | J39: =VLOOKUP(D39,L:M,2,0) -> 1 | L39: CEWH-100KWi | M39: 1
A40: 39 | B40: 6951142565916 | C40: A.O.史密斯 | D40: R2000XF1 | E40: 1 | F40: 净水机 | G40: 1 | I40: =VLOOKUP(D40,Sheet2!H:I,2,0) -> 一级 | J40: =VLOOKUP(D40,L:M,2,0) -> 1 | L40: CEWH-50D5Wi | M40: 1
A41: 40 | B41: 6951142566166 | C41: A.O.史密斯 | D41: R1400F | E41: 1 | F41: 净水机 | G41: 1 | I41: =VLOOKUP(D41,Sheet2!H:I,2,0) -> 一级 | J41: =VLOOKUP(D41,L:M,2,0) -> 1 | L41: CEWH-60D5Wi | M41: 1
A42: 41 | B42: 6951142566159 | C42: A.O.史密斯 | D42: R1700FWi | E42: 1 | F42: 净水机 | G42: 1 | I42: =VLOOKUP(D42,Sheet2!H:I,2,0) -> 一级 | J42: =VLOOKUP(D42,L:M,2,0) -> 1 | L42: CEWH-60D5BWi | M42: 1
A43: 42 | B43: 6951142566630 | C43: A.O.史密斯 | D43: R1600SWi | E43: 1 | F43: 净水机 | G43: 1 | I43: =VLOOKUP(D43,Sheet2!H:I,2,0) -> 一级 | J43: =VLOOKUP(D43,L:M,2,0) -> 1 | L43: CEWH-80D5Wi | M43: 1
A44: 43 | B44: 6951142566647 | C44: A.O.史密斯 | D44: R1800SWi | E44: 1 | F44: 净水机 | G44: 1 | I44: =VLOOKUP(D44,Sheet2!H:I,2,0) -> 一级 | J44: =VLOOKUP(D44,L:M,2,0) -> 1 | L44: CEWH-60TKBWi | M44: 1
A45: 44 | B45: 6951142566142 | C45: A.O.史密斯 | D45: R2000FWi | E45: 1 | F45: 净水机 | G45: 1 | I45: =VLOOKUP(D45,Sheet2!H:I,2,0) -> 一级 | J45: =VLOOKUP(D45,L:M,2,0) -> 1 | L45: CEWH-60TKWi | M45: 1
A46: 45 | B46: 6951142563400 | C46: A.O.史密斯 | D46: R1800RC9 | E46: 1 | F46: 净水机 | G46: 1 | I46: =VLOOKUP(D46,Sheet2!H:I,2,0) -> 一级 | J46: =VLOOKUP(D46,L:M,2,0) -> 1 | L46: CEWH-80TKWi | M46: 1
A47: 46 | B47: 6951142563431 | C47: A.O.史密斯 | D47: R2500RC3 | E47: 1 | F47: 净水机 | G47: 1 | I47: =VLOOKUP(D47,Sheet2!H:I,2,0) -> 一级 | J47: =VLOOKUP(D47,L:M,2,0) -> 1 | L47: CEWH-60WKWi | M47: 1
... A96: 95 | B96: 6951142591434 | C96: A.O.史密斯 | D96: BZR1000-T806 | E96: 1 | F96: 净水机 | G96: 1 | I96: =VLOOKUP(D96,Sheet2!H:I,2,0) -> 一级 | J96: =VLOOKUP(D96,L:M,2,0) -> 1 | L96: EESR-25C8 | M96: 1
A97: 96 | B97: 6951142566777 | C97: A.O.史密斯 | D97: DR1600FS1 | E97: 1 | F97: 净水机 | G97: 1 | I97: =VLOOKUP(D97,Sheet2!H:I,2,0) -> 一级 | J97: =VLOOKUP(D97,L:M,2,0) -> 1 | L97: EES-50-6 | M97: 不适用能效
A98: 97 | B98: 6951142566890 | C98: A.O.史密斯 | D98: ER1600BWi | E98: 1 | F98: 净水器 | G98: 1 | I98: =VLOOKUP(D98,Sheet2!H:I,2,0) -> 一级 | J98: =VLOOKUP(D98,L:M,2,0) -> 1 | L98: EES-80-6 | M98: 不适用能效
A99: 99 | B99: 6920971975944 | C99: 松下 | D99: J13AKR10X | E99: 1 | F99: 空调 | G99: 1 | I99: =VLOOKUP(D99,Sheet2!H:I,2,0) -> 一级 | J99: =VLOOKUP(D99,L:M,2,0) -> 1 | L99: EES-120-6 | M99: 不适用能效
A100: 100 | B100: 6920971975166 | C100: A.O.史密斯 | D100: JZT-F5B2 | E100: 1 | F100: 燃气灶 | G100: 1 | I100: =VLOOKUP(D100,Sheet2!H:I,2,0) -> 一级 | J100: =VLOOKUP(D100,L:M,2,0) -> 1 | L100: EES-30D | M100: 1
A101: 101 | B101: 6920971972356 | C101: A.O.史密斯 | D101: JZT-K5G1 | E101: 1 | F101: 燃气灶 | G101: 1 | I101: =VLOOKUP(D101,Sheet2!H:I,2,0) -> 一级 | J101: =VLOOKUP(D101,L:M,2,0) -> 1 | L101: EES-40D | M101: 1
A102: 102 | B102: 6920971971595 | C102: A.O.史密斯 | D102: JZT-V2B1 | E102: 1 | F102: 燃气灶 | G102: 1 | I102: =VLOOKUP(D102,Sheet2!H:I,2,0) -> 一级 | J102: =VLOOKUP(D102,L:M,2,0) -> 1 | L102: EES-50D | M102: 1
A103: 103 | B103: 6920971960797 | C103: A.O.史密斯 | D103: JZT-F3B1 | E103: 1 | F103: 燃气灶 | G103: 1 | I103: =VLOOKUP(D103,Sheet2!H:I,2,0) -> 一级 | J103: =VLOOKUP(D103,L:M,2,0) -> 1 | L103: EES-80D | M103: 1
A104: 104 | B104: 6920971975715 | C104: A.O.史密斯 | D104: JZT-V2B1S | E104: 1 | F104: 燃气灶 | G104: 1 | I104: =VLOOKUP(D104,Sheet2!H:I,2,0) -> 一级 | J104: =VLOOKUP(D104,L:M,2,0) -> 1 | L104: ACWP-15AE1 | M104: 不适用能效
...

Sheet Sheet2
A1: A.O.史密斯 | B1: JZT-F3G1 | C1: 1 | D1: A08 | E1: 家用灶具 | H1: 商品型号 | I1: 能效等级
A2: A.O.史密斯 | B2: CXW-200-Q5+ | C2: 1 | D2: A07 | E2: 吸油烟机 | H2: L1PB20-V3 | I2: 二级
A3: A.O.史密斯 | B3: CXW-350-E5AWi | C3: 1 | D3: A07 | E3: 吸油烟机 | H3: L1PB26-V3 | I3: 二级
A4: A.O.史密斯 | B4: CXW-200-E6AWi | C4: 1 | D4: A07 | E4: 吸油烟机 | H4: L1PB33-V3 | I4: 二级
A5: A.O.史密斯 | B5: CXW-350-Q2AWi | C5: 1 | D5: A07 | E5: 吸油烟机 | H5: L1PB26-V9 | I5: 二级
A6: A.O.史密斯 | B6: CXW-200-Q3AWi | C6: 1 | D6: A07 | E6: 吸油烟机 | H6: L1PB33-V9 | I6: 二级
A7: A.O.史密斯 | B7: HPA-50D1.0N | C7: 1 | D7: A06 | E7: 热水器 | H7: L1PB37-V9 | I7: 二级
A8: A.O.史密斯 | B8: JSQ24-LSX | C8: 2 | D8: A06 | E8: 热水器 | H8: LL1GBQ24-V10 | I8: 一级
A9: A.O.史密斯 | B9: JSQ26-AJSX | C9: 2 | D9: A06 | E9: 热水器 | H9: LL1GBQ33-V10 | I9: 一级
A10: A.O.史密斯 | B10: JSQ26-CLB | C10: 2 | D10: A06 | E10: 热水器 | H10: LL1GBQ24-V11 | I10: 一级
A11: A.O.史密斯 | B11: JSQ26-HS-CWX | C11: 2 | D11: A06 | E11: 热水器 | H11: LL1GBQ33-V11 | I11: 一级
A12: A.O.史密斯 | B12: JSW26-OSX | C12: 2 | D12: A06 | E12: 热水器 | H12: L1PB26-CA | I12: 二级
... A53: A.O.史密斯 | B53: L1PB37-SA | C53: 2 | D53: A06 | E53: 热水器 | H53: R1700FWi | I53: 一级
H54: R1600SWi | I54: 一级
H55: R1800SWi | I55: 一级
H56: R2000FWi | I56: 一级
H57: R1800RC9 | I57: 一级
H58: R2500RC3 | I58: 一级
H59: R2000RC9 | I59: 一级
H60: R2300RC9 | I60: 一级
H61: R2000AB2 | I61: 一级
H62: R1600AB2 | I62: 一级
H63: R2500AB1 | I63: 一级
H64: R4000AB1 | I64: 一级
H65: R2500AB2 | I65: 一级
... H387: ER1600BWi | I387: 一级
H388: CEWH-60B6A | I388: 1
H389: JSQ31-C3CX | I389: 2
H390: JSW33-OSX | I390: 2
H391: CXW-400-Z3AWi | I391: 1
H392: DWQ15-MR1AWi | I392: 1
H393: DWQ15-RJ100Wi | I393: 1
H394: ER1600BWI | I394: 1
H395: EWH-60HG | I395: 1
H396: EWH-60HGVWi | I396: 1
H397: EWH-80HG | I397: 1
H398: EWH-80HGVWi | I398: 1
H399: JSQ26-QSX（白） | I399: 2
... H403: CXW-350-E3AWi | I403: 1
H404: KZQ45-M3Wi | I404: 不适用能效
...
