Workbook

Sheet Sheet2
A3: 销售订单号 | B3: 求和项:收款金额
A4: 20251015000059 | B4: 2950
A5: 20251027005412 | B5: 8055
A6: A20051025002418 | B6: 770
A7: A20250705000781C | B7: 2951
A8: A20250710003461C | B8: 2745
A9: A20250712005748C | B9: 2450
A10: A20250717001898C | B10: 3247
A11: A20250718002949C | B11: 2542
A12: A20250719001685C | B12: 2975
A13: A20250720003712C | B13: 5098
A14: A20250802002197C | B14: 4124
A15: A20250803001634C | B15: 5988
... A101: A20251012005268 | B101: 4764
A102: A20251012005314
A103: A20251013000189 | B103: 4289
A104: A20251013000313 | B104: 4481
A105: A20251013000424 | B105: 2071
A106: A20251013000458 | B106: 4086
A107: A20251013000973 | B107: 1340
A108: A20251013000974 | B108: 3395
A109: A20251013001055 | B109: 5872
A110: A20251013001594 | B110: 4279
A111: A20251013002496 | B111: 4400
A112: A20251013002814 | B112: 898
A113: A20251014000230 | B113: 6440
A114: A20251014000643 | B114: 5100
... A165: A20251020003506 | B165: 3060
A166: A20251020003601
A167: A20251021001704 | B167: 2379
A168: A20251021002386 | B168: 4059
A169: A20251021002402 | B169: 3360
A170: A20251021003040 | B170: 790
A171: A20251021003315 | B171: 791
A172: A20251021003832 | B172: 4000
A173: A20251021004770 | B173: 2300
A174: A20251021005203 | B174: 5850
A175: A20251021005303 | B175: 2100
A176: A20251021005683 | B176: 898
A177: A20251021006855 | B177: 6291
...

Sheet Sheet3
A3: 往来单位 | B3: 求和项:收款金额 | C3: 收款 | D3: 退款 | E3: 实际 | F3: 销管部
A4: 二轻专卖店以旧换新 | B4: 3745 | C4: 3745 | D4: =VLOOKUP(A4,[1]Sheet2!$A:$B,2,0) -> 1000 | E4: =C4-D4 -> 2745 | F4: =VLOOKUP(A4,[2]杭州!$C:$BJ,60,0) -> #N/A
A5: （新）滨江第六空间专卖店 | B5: 109222 | C5: 109222 | D5: =VLOOKUP(A5,[1]Sheet2!$A:$B,2,0) -> 23893 | E5: =C5-D5 -> 85329 | F5: =VLOOKUP(A5,[2]杭州!$C:$BJ,60,0) -> 85329
A6: :衢州市柯城汇鑫家用电器商行以旧换新 | B6: 8388 | C6: 8388 | D6: =VLOOKUP(A6,[1]Sheet2!$A:$B,2,0) -> 8388 | E6: =C6-D6 -> 0 | F6: =VLOOKUP(A6,[2]杭州!$C:$BJ,60,0) -> #N/A
A7: 艾欧史密斯（中国）水系统有限公司 | B7: 15739.2 | C7: 15739.2 | E7: =C7-D7 -> 15739.2 | F7: =VLOOKUP(A7,[2]杭州!$C:$BJ,60,0) -> #N/A
A8: 贝壳美家供应链管理（浙江）有限责任公司 | B8: 36202 | C8: 36202 | E8: =C8-D8 -> 36202 | F8: =VLOOKUP(A8,[2]杭州!$C:$BJ,60,0) -> 36202
A9: 滨江六空8090店 | B9: 326584 | C9: 326584 | D9: =VLOOKUP(A9,[1]Sheet2!$A:$B,2,0) -> 59722 | E9: =C9-D9 -> 266862 | F9: =VLOOKUP(A9,[2]杭州!$C:$BJ,60,0) -> 266862
A10: 杭州恒大建材超级旗舰店 | B10: 65384 | C10: 65384 | E10: =C10-D10 -> 65384 | F10: =VLOOKUP(A10,[2]杭州!$C:$BJ,60,0) -> 65384
A11: 杭州红星美凯龙一号店 | B11: 358655.6 | C11: 358655.6 | D11: =VLOOKUP(A11,[1]Sheet2!$A:$B,2,0) -> 58364.85 | E11: =C11-D11 -> 300290.75 | F11: =VLOOKUP(A11,[2]杭州!$C:$BJ,60,0) -> 300290.75
A12: 杭州宏信机电有限公司 | B12: 34000 | C12: 34000 | E12: =C12-D12 -> 34000 | F12: =VLOOKUP(A12,[2]杭州!$C:$BJ,60,0) -> 34000
A13: 杭州华东家电市场铁人电器商行 | B13: 1397.6 | C13: 1397.6 | E13: =C13-D13 -> 1397.6 | F13: =VLOOKUP(A13,[2]杭州!$C:$BJ,60,0) -> 1397.6
A14: 杭州金蝶零售 | B14: 344535.76 | C14: 344535.76 | D14: =VLOOKUP(A14,[1]Sheet2!$A:$B,2,0) -> 4400 | E14: =C14-D14 -> 340135.76 | F14: =VLOOKUP(A14,[2]杭州!$C:$BJ,60,0) -> 330288.06
A15: 杭州临安一栋电器有限公司 | B15: 40000 | C15: 40000 | E15: =C15-D15 -> 40000 | F15: =VLOOKUP(A15,[2]杭州!$C:$BJ,60,0) -> 40000
A16: 杭州临平江南家居专卖店 | B16: 55272 | C16: 55272 | D16: =VLOOKUP(A16,[1]Sheet2!$A:$B,2,0) -> 5988 | E16: =C16-D16 -> 49284 | F16: =VLOOKUP(A16,[2]杭州!$C:$BJ,60,0) -> 49284
A17: 杭州瑞艾工程技术服务有限公司 | B17: 9108.1 | C17: 9108.1 | E17: =C17-D17 -> 9108.1 | F17: =VLOOKUP(A17,[2]杭州!$C:$BJ,60,0) -> #N/A
A18: 杭州兴达京昀电器有限公司 | B18: 100000 | C18: 100000 | E18: =C18-D18 -> 100000 | F18: =VLOOKUP(A18,[2]杭州!$C:$BJ,60,0) -> 100000
A19: 杭州允选科技有限公司 | B19: 42126.63 | C19: 42126.63 | E19: =C19-D19 -> 42126.63 | F19: =VLOOKUP(A19,[2]杭州!$C:$BJ,60,0) -> 17360
A20: 杭州中博智能电器有限公司 | B20: 125003.28 | C20: 125003.28 | E20: =C20-D20 -> 125003.28 | F20: =VLOOKUP(A20,[2]杭州!$C:$BJ,60,0) -> 113351.28
A21: 杭州中瑞工程技术有限公司 | B21: 30887.28 | C21: 30887.28 | E21: =C21-D21 -> 30887.28 | F21: =VLOOKUP(A21,[2]杭州!$C:$BJ,60,0) -> 0
A22: 杭州装家百科电器有限公司 | B22: 4590 | C22: 4590 | E22: =C22-D22 -> 4590 | F22: =VLOOKUP(A22,[2]杭州!$C:$BJ,60,0) -> 4590
A23: 湖州金蝶零售 | B23: 21969 | C23: 21969 | E23: =C23-D23 -> 21969 | F23: =VLOOKUP(A23,[2]杭州!$C:$BJ,60,0) -> #N/A
A24: 湖州浙北大厦家电有限公司 | B24: 150000 | C24: 150000 | E24: =C24-D24 -> 150000 | F24: =VLOOKUP(A24,[2]杭州!$C:$BJ,60,0) -> #N/A
A25: 湖州浙北网格家电有限公司 | B25: 24339 | C25: 24339 | E25: =C25-D25 -> 24339 | F25: =VLOOKUP(A25,[2]杭州!$C:$BJ,60,0) -> #N/A
A26: 嘉兴艾通电器有限公司 | B26: 36276.48 | C26: 36276.48 | E26: =C26-D26 -> 36276.48 | F26: =VLOOKUP(A26,[2]杭州!$C:$BJ,60,0) -> #N/A
A27: 金华龙腾建材市场专卖店 | B27: 68993 | C27: 68993 | D27: =VLOOKUP(A27,[1]Sheet2!$A:$B,2,0) -> 11868 | E27: =C27-D27 -> 57125 | F27: =VLOOKUP(A27,[2]杭州!$C:$BJ,60,0) -> #N/A
A28: 金华一启家电有限公司 | B28: 136.9 | C28: 136.9 | E28: =C28-D28 -> 136.9 | F28: =VLOOKUP(A28,[2]杭州!$C:$BJ,60,0) -> #N/A
A29: 京东五星电器集团宁波电器有限公司（台州） | B29: 71511.68 | C29: 71511.68 | E29: =C29-D29 -> 71511.68 | F29: =VLOOKUP(A29,[2]杭州!$C:$BJ,60,0) -> #N/A
A30: 兰溪市泽胜电器有限公司 | B30: 25150 | C30: 25150 | E30: =C30-D30 -> 25150 | F30: =VLOOKUP(A30,[2]杭州!$C:$BJ,60,0) -> #N/A
A31: 衢州市柯城汇鑫家用电器商行 | B31: 19913 | C31: 19913 | E31: =C31-D31 -> 19913 | F31: =VLOOKUP(A31,[2]杭州!$C:$BJ,60,0) -> #N/A
A32: 绍兴晨涛电器有限公司 | B32: 10970 | C32: 10970 | E32: =C32-D32 -> 10970 | F32: =VLOOKUP(A32,[2]杭州!$C:$BJ,60,0) -> #N/A
A33: 史密斯官方商城 | B33: 9287 | C33: 9287 | E33: =C33-D33 -> 9287 | F33: =VLOOKUP(A33,[2]杭州!$C:$BJ,60,0) -> #N/A
A34: 台州中嘉电器有限公司 | B34: 11543.15 | C34: 11543.15 | E34: =C34-D34 -> 11543.15 | F34: =VLOOKUP(A34,[2]杭州!$C:$BJ,60,0) -> #N/A
A35: 桐庐佳尼特水处理设备有限公司 | B35: 100000 | C35: 100000 | E35: =C35-D35 -> 100000 | F35: =VLOOKUP(A35,[2]杭州!$C:$BJ,60,0) -> 100000
A36: 温州吉远电器有限公司 | B36: 66047.06 | C36: 66047.06 | E36: =C36-D36 -> 66047.06 | F36: =VLOOKUP(A36,[2]杭州!$C:$BJ,60,0) -> #N/A
A37: 无人认领 | B37: 0.01 | C37: 0.01 | E37: =C37-D37 -> 0.01 | F37: =VLOOKUP(A37,[2]杭州!$C:$BJ,60,0) -> #N/A
A38: 萧山第六空间专卖店 | B38: 153067 | C38: 153067 | D38: =VLOOKUP(A38,[1]Sheet2!$A:$B,2,0) -> 29639 | E38: =C38-D38 -> 123428 | F38: =VLOOKUP(A38,[2]杭州!$C:$BJ,60,0) -> 126173
A39: 萧山汇德隆家电超市 | B39: 300000 | C39: 300000 | E39: =C39-D39 -> 300000 | F39: =VLOOKUP(A39,[2]杭州!$C:$BJ,60,0) -> #N/A
A40: 萧山汇德隆净水 | B40: 224728.9 | C40: 224728.9 | E40: =C40-D40 -> 224728.9 | F40: =VLOOKUP(A40,[2]杭州!$C:$BJ,60,0) -> 224728.9
A41: 义乌颖亿贸易有限公司 | B41: 8362 | C41: 8362 | E41: =C41-D41 -> 8362 | F41: =VLOOKUP(A41,[2]杭州!$C:$BJ,60,0) -> #N/A
A42: 永康市荣浪家用电器有限公司 | B42: 7490 | C42: 7490 | E42: =C42-D42 -> 7490 | F42: =VLOOKUP(A42,[2]杭州!$C:$BJ,60,0) -> #N/A
...

Sheet Sheet1
A1: 单据类型 | B1: 单据编号 | C1: 客户所属区域 | D1: 业务日期 | E1: 往来单位类型 | F1: 付款单位类型 | G1: 币别 | H1: 表头-应收金额 | I1: 表头-实收金额 | J1: 结算组织 | K1: 部门 | L1: 销售组织 | M1: 往来单位 | N1: 销售部门 | O1: 销售组 | P1: 收款金额 | Q1: 销售员 | R1: 本位币 | S1: 汇率类型 | T1: 汇率 | U1: 表头-应收金额本位币 | V1: 表头-实收金额本位币 | W1: 会计核算体系 | X1: 核销状态 | Y1: 长短款本位币 | Z1: 业务类型 | AA1: 信用检查结果 | AB1: 结算方式 | AC1: 收款用途 | AD1: 预收项目类型 | AE1: 结算汇率 | AF1: 预收销售订单 | AG1: 表体-应收金额 | AH1: 现金折扣 | AI1: 表头-收款金额本位币 | AJ1: 折后金额 | AK1: 手续费 | AL1: 长短款 | AM1: 表体-实收金额 | AN1: 我方账户名称 | AO1: 是否期初单据 | AP1: 我方开户行 | AQ1: 来源系统 | AR1: 对方开户行 | AS1: 付款单位 | AT1: 结算号 | AU1: 对方银行账号 | AV1: 对方账户名称 | AW1: 现金折扣本位币 | AX1: 折后金额本位币 | AY1: 现销 | AZ1: 我方银行账号 | BA1: 表体-应收金额本位币 | BB1: 备注 | BC1: 勾对 | BD1: 关联总金额 | BE1: 表体明细-核销状态 | BF1: 表体明细-已核销金额 | BG1: 手续费本位币 | BH1: 表体-实收金额本位币 | BI1: 单据状态 | BJ1: 创建人 | BK1: 修改人 | BL1: 审核人 | BM1: 创建日期 | BN1: 修改日期 | BO1: 审核日期 | BP1: 作废人 | BQ1: 作废日期 | BR1: 作废状态 | BS1: 收款金额 | BT1: 内部账号 | BU1: 内部账户名称 | BV1: 现金账号 | BW1: 收款组织 | BX1: 退款关联金额 | BY1: 保证金转货款金额 | BZ1: 结算币别 | CA1: B2C业务 | CB1: 登账日期 | CC1: 是否登账 | CD1: 物料编码 | CE1: 物料名称 | CF1: 销售订单号 | CG1: 订单行号 | CH1: 是否转销 | CI1: 核销方式 | CJ1: 扫描点 | CK1: 备注 | CL1: 已核销金额本位币 | CM1: 第三方单据编号 | CN1: 结算本位币 | CO1: 结算汇率类型 | CP1: POS参考号 | CQ1: 收据号码 | CR1: 公司提单号 | CS1: 收款来源 | CT1: 客户分组 | CU1: 安装/维修工单号 | CV1: 销售订单号(核销) | CW1: 凭小票 | CX1: 复核日期 | CY1: 复核状态 | CZ1: 复核人 | DA1: 核对标识 | DB1: 师傅姓名 | DC1: 已转账金额 | DD1: 转账状态 | DE1: 费用承担部门 | DF1: 公司承担减免金额 | DG1: AO承担减免金额 | DH1: 费用项目 | DI1: 商场对账单号 | DJ1: 采暖合同编号 | DK1: 用户姓名(单据头) | DL1: 用户手机(单据头) | DM1: 其他号码(单据头) | DN1: 门店承担费用 | DO1: 费用承担门店（非挂账) | DP1: 费用承担员工(非挂账) | DQ1: 员工承担费用 | DR1: 结算人员备注
A2: 现款现货收款单 | B2: SKD250930106 | C2: 杭州 | D2: 2025/10/9 | E2: 客户 | F2: 客户 | G2: 人民币 | H2: 2855.15 | I2: 2838.02 | J2: 杭州中冠电器有限公司 | L2: 杭州中冠电器有限公司 | M2: 杭州红星美凯龙一号店 | N2: 杭州大区 | P2: 2855.15 | Q2: 吴红玉 | R2: 人民币 | S2: 固定汇率 | T2: 1 | U2: 2855.15 | V2: 2838.02 | X2: 完全 | Z2: 销售业务 | AA2: 信用正常 | AB2: 转账 | AC2: 预收款 | AD2: 销售订单 | AE2: 1 | AF2: A20250920001308C | AG2: 2855.15 | AI2: 2855.15 | AJ2: 2855.15 | AK2: 17.13 | AM2: 2838.02 | AN2: 杭州中冠电器有限公司 | AO2: 否 | AP2: 中信银行杭州钱江支行 | AQ2: 手工新增 | AS2: 杭州红星美凯龙一号店 | AX2: 2855.15 | AY2: 否 | AZ2: 7331710182200026317 | BA2: 2855.15 | BC2: 否 | BD2: 2855.15 | BE2: 完全 | BF2: 2855.15 | BG2: 17.13 | BH2: 2838.02 | BI2: 已审核 | BJ2: 陈联 | BK2: 桑玲 | BL2: 桑玲 | BM2: 2025/9/30 | BN2: 2025-10-17 09:18:50 | BO2: 2025-09-30 12:53:56 | BR2: 否 | BS2: 2855.15 | BW2: 杭州中冠电器有限公司 | BX2: 2855.15 | BZ2: 人民币 | CA2: 否 | CB2: 2025/10/9 | CC2: 是 | CD2: RQRS.00006 | CE2: JSQ31-CLD燃气快速热水器 | CF2: A20250920001308C | CG2: 1 | CH2: 否 | CK2: 9.30刷卡3359元（2855.15+补贴503.85元）【用户姓名:廖永芳；用户手机:13777883190；其他号码: 】 | CL2: 2855.15 | CN2: 人民币 | CO2: 固定汇率 | CT2: 杭州地区客户 | CW2: 否 | DD2: 未关闭 | DK2: 廖永芳 | DL2: 13777883190
A3: 现款现货收款单 | B3: SKD250930107 | C3: 杭州 | D3: 2025/10/9 | E3: 客户 | F3: 客户 | G3: 人民币 | H3: 503.85 | I3: 503.85 | J3: 杭州中冠电器有限公司 | L3: 杭州中冠电器有限公司 | M3: 杭州红星美凯龙一号店 | N3: 杭州大区 | P3: 503.85 | Q3: 吴红玉 | R3: 人民币 | S3: 固定汇率 | T3: 1 | U3: 503.85 | V3: 503.85 | X3: 完全 | Z3: 销售业务 | AA3: 信用正常 | AB3: 转账 | AC3: 预收款 | AD3: 销售订单 | AE3: 1 | AF3: A20250920001308C | AG3: 503.85 | AI3: 503.85 | AJ3: 503.85 | AM3: 503.85 | AN3: 政府以旧换新中转银行 | AO3: 否 | AP3: 政府以旧换新中转银行 | AQ3: 手工新增 | AS3: 杭州红星美凯龙一号店 | AX3: 503.85 | AY3: 否 | AZ3: 9999999 | BA3: 503.85 | BC3: 否 | BD3: 503.85 | BE3: 完全 | BF3: 503.85 | BH3: 503.85 | BI3: 已审核 | BJ3: 陈联 | BK3: 陈联 | BL3: 桑玲 | BM3: 2025/9/30 | BN3: 2025-09-30 11:31:23 | BO3: 2025-09-30 12:54:11 | BR3: 否 | BS3: 503.85 | BW3: 杭州中冠电器有限公司 | BX3: 503.85 | BZ3: 人民币 | CA3: 否 | CB3: 2025/10/9 | CC3: 是 | CD3: RQRS.00006 | CE3: JSQ31-CLD燃气快速热水器 | CF3: A20250920001308C | CG3: 1 | CH3: 否 | CK3: 9.30刷卡3359元（2855.15+补贴503.85元）【用户姓名:廖永芳；用户手机:13777883190；其他号码: 】 | CL3: 503.85 | CN3: 人民币 | CO3: 固定汇率 | CT3: 杭州地区客户 | CW3: 否 | DD3: 未关闭 | DK3: 廖永芳 | DL3: 13777883190
A4: 现款现货收款单 | B4: SKD250930109 | C4: 杭州 | D4: 2025/10/9 | E4: 客户 | F4: 客户 | G4: 人民币 | H4: 2623.2 | I4: 2607.46 | J4: 杭州中冠电器有限公司 | L4: 杭州中冠电器有限公司 | M4: 滨江六空8090店 | N4: 杭州大区 | P4: 2623.2 | R4: 人民币 | S4: 固定汇率 | T4: 1 | U4: 2623.2 | V4: 2607.46 | X4: 完全 | Z4: 销售业务 | AA4: 信用正常 | AB4: 转账 | AC4: 预收款 | AD4: 销售订单 | AE4: 1 | AF4: A20250930000866 | AG4: 2623.2 | AI4: 2623.2 | AJ4: 2623.2 | AK4: 15.74 | AM4: 2607.46 | AN4: 杭州中冠电器有限公司 | AO4: 否 | AP4: 中信银行杭州钱江支行 | AQ4: 手工新增 | AS4: 滨江六空8090店 | AX4: 2623.2 | AY4: 否 | AZ4: 7331710182200026317 | BA4: 2623.2 | BC4: 否 | BD4: 2623.2 | BE4: 完全 | BF4: 2623.2 | BG4: 15.74 | BH4: 2607.46 | BI4: 已审核 | BJ4: 葛 芬 | BK4: 桑玲 | BL4: 桑玲 | BM4: 2025/9/30 | BN4: 2025-10-17 09:19:21 | BO4: 2025-09-30 12:56:06 | BR4: 否 | BS4: 2623.2 | BW4: 杭州中冠电器有限公司 | BX4: 2623.2 | BZ4: 人民币 | CA4: 否 | CB4: 2025/10/9 | CC4: 是 | CD4: DRSQ.00060 | CE4: CEWH-60D5Wi储水式热水器 | CF4: A20250930000866 | CG4: 1 | CH4: 否 | CK4: 9.30刷卡3279元（2623.2元+补贴655.8元）【用户姓名：吴璐瑶】【用户姓名:吴璐瑶；用户手机:18757218931；其他号码: 】 | CL4: 2623.2 | CN4: 人民币 | CO4: 固定汇率 | CT4: 杭州-主城 | CW4: 否 | DD4: 未关闭 | DK4: 吴璐瑶 | DL4: 18757218931
A5: 现款现货收款单 | B5: SKD250930111 | C5: 杭州 | D5: 2025/10/9 | E5: 客户 | F5: 客户 | G5: 人民币 | H5: 655.8 | I5: 655.8 | J5: 杭州中冠电器有限公司 | L5: 杭州中冠电器有限公司 | M5: 滨江六空8090店 | N5: 杭州大区 | P5: 655.8 | Q5: 葛芬 | R5: 人民币 | S5: 固定汇率 | T5: 1 | U5: 655.8 | V5: 655.8 | X5: 完全 | Z5: 销售业务 | AA5: 信用正常 | AB5: 转账 | AC5: 预收款 | AD5: 销售订单 | AE5: 1 | AF5: A20250930000866 | AG5: 655.8 | AI5: 655.8 | AJ5: 655.8 | AM5: 655.8 | AN5: 政府以旧换新中转银行 | AO5: 否 | AP5: 政府以旧换新中转银行 | AQ5: 手工新增 | AS5: 滨江六空8090店 | AX5: 655.8 | AY5: 否 | AZ5: 9999999 | BA5: 655.8 | BC5: 否 | BD5: 655.8 | BE5: 完全 | BF5: 655.8 | BH5: 655.8 | BI5: 已审核 | BJ5: 葛 芬 | BK5: 葛 芬 | BL5: 桑玲 | BM5: 2025/9/30 | BN5: 2025-09-30 11:01:08 | BO5: 2025-09-30 12:56:35 | BR5: 否 | BS5: 655.8 | BW5: 杭州中冠电器有限公司 | BX5: 655.8 | BZ5: 人民币 | CA5: 否 | CB5: 2025/10/9 | CC5: 是 | CD5: DRSQ.00060 | CE5: CEWH-60D5Wi储水式热水器 | CF5: A20250930000866 | CG5: 1 | CH5: 否 | CK5: 9.30刷卡3279元（2623.2元+补贴655.8元）【用户姓名：吴璐瑶】【用户姓名:吴璐瑶；用户手机:18757218931；其他号码: 】 | CL5: 655.8 | CN5: 人民币 | CO5: 固定汇率 | CT5: 杭州-主城 | CW5: 否 | DD5: 未关闭 | DK5: 吴璐瑶 | DL5: 18757218931
A6: 现款现货收款单 | B6: SKD250930134 | C6: 杭州 | D6: 2025/10/9 | E6: 客户 | F6: 客户 | G6: 人民币 | H6: 4799.2 | I6: 4770.4 | J6: 杭州中冠电器有限公司 | L6: 杭州中冠电器有限公司 | M6: 滨江六空8090店 | N6: 杭州大区 | P6: 4799.2 | Q6: 葛芬 | R6: 人民币 | S6: 固定汇率 | T6: 1 | U6: 4799.2 | V6: 4770.4 | X6: 完全 | Z6: 销售业务 | AA6: 信用正常 | AB6: 转账 | AC6: 预收款 | AD6: 销售订单 | AE6: 1 | AF6: A20250930000811 | AG6: 4799.2 | AI6: 4799.2 | AJ6: 4799.2 | AK6: 28.8 | AM6: 4770.4 | AN6: 杭州中冠电器有限公司 | AO6: 否 | AP6: 中信银行杭州钱江支行 | AQ6: 手工新增 | AS6: 滨江六空8090店 | AX6: 4799.2 | AY6: 否 | AZ6: 7331710182200026317 | BA6: 4799.2 | BC6: 否 | BD6: 4799.2 | BE6: 完全 | BF6: 4799.2 | BG6: 28.8 | BH6: 4770.4 | BI6: 已审核 | BJ6: 葛 芬 | BK6: 桑玲 | BL6: 桑玲 | BM6: 2025/9/30 | BN6: 2025-10-17 09:19:56 | BO6: 2025-09-30 12:57:26 | BR6: 否 | BS6: 4799.2 | BW6: 杭州中冠电器有限公司 | BX6: 4799.2 | BZ6: 人民币 | CA6: 否 | CB6: 2025/10/9 | CC6: 是 | CD6: SXX(G.00003 | CE6: 洗衣机XQG100-XE0WI | CF6: A20250930000811 | CG6: 1 | CH6: 否 | CK6: 9.30刷卡5999元（4799.2元+补贴1199.8元）【用户姓名：田昆明】【用户姓名:田昆明；用户手机:13958183811；其他号码: 】 | CL6: 4799.2 | CN6: 人民币 | CO6: 固定汇率 | CT6: 杭州-主城 | CW6: 否 | DD6: 未关闭 | DK6: 田昆明 | DL6: 13958183811
A7: 现款现货收款单 | B7: SKD250930136 | C7: 杭州 | D7: 2025/10/9 | E7: 客户 | F7: 客户 | G7: 人民币 | H7: 1199.8 | I7: 1199.8 | J7: 杭州中冠电器有限公司 | L7: 杭州中冠电器有限公司 | M7: 滨江六空8090店 | N7: 杭州大区 | P7: 1199.8 | Q7: 葛芬 | R7: 人民币 | S7: 固定汇率 | T7: 1 | U7: 1199.8 | V7: 1199.8 | X7: 完全 | Z7: 销售业务 | AA7: 信用正常 | AB7: 转账 | AC7: 预收款 | AD7: 销售订单 | AE7: 1 | AF7: A20250930000811 | AG7: 1199.8 | AI7: 1199.8 | AJ7: 1199.8 | AM7: 1199.8 | AN7: 政府以旧换新中转银行 | AO7: 否 | AP7: 政府以旧换新中转银行 | AQ7: 手工新增 | AS7: 滨江六空8090店 | AX7: 1199.8 | AY7: 否 | AZ7: 9999999 | BA7: 1199.8 | BC7: 否 | BD7: 1199.8 | BE7: 完全 | BF7: 1199.8 | BH7: 1199.8 | BI7: 已审核 | BJ7: 葛 芬 | BK7: 葛 芬 | BL7: 桑玲 | BM7: 2025/9/30 | BN7: 2025-09-30 11:19:53 | BO7: 2025-09-30 12:57:43 | BR7: 否 | BS7: 1199.8 | BW7: 杭州中冠电器有限公司 | BX7: 1199.8 | BZ7: 人民币 | CA7: 否 | CB7: 2025/10/9 | CC7: 是 | CD7: SXX(G.00003 | CE7: 洗衣机XQG100-XE0WI | CF7: A20250930000811 | CG7: 1 | CH7: 否 | CK7: 9.30刷卡5999元（4799.2元+补贴1199.8元）【用户姓名：田昆明】【用户姓名:田昆明；用户手机:13958183811；其他号码: 】 | CL7: 1199.8 | CN7: 人民币 | CO7: 固定汇率 | CT7: 杭州-主城 | CW7: 否 | DD7: 未关闭 | DK7: 田昆明 | DL7: 13958183811
A8: 现款现货收款单 | B8: SKD250930225 | C8: 杭州 | D8: 2025/10/9 | E8: 客户 | F8: 客户 | G8: 人民币 | H8: 2855.15 | I8: 2838.02 | J8: 杭州中冠电器有限公司 | L8: 杭州中冠电器有限公司 | M8: 杭州红星美凯龙一号店 | N8: 杭州大区 | P8: 2855.15 | Q8: 吴红玉 | R8: 人民币 | S8: 固定汇率 | T8: 1 | U8: 2855.15 | V8: 2838.02 | X8: 完全 | Z8: 销售业务 | AA8: 信用正常 | AB8: 转账 | AC8: 预收款 | AD8: 销售订单 | AE8: 1 | AF8: A20250930003028 | AG8: 2855.15 | AI8: 2855.15 | AJ8: 2855.15 | AK8: 17.13 | AM8: 2838.02 | AN8: 杭州中冠电器有限公司 | AO8: 否 | AP8: 中信银行杭州钱江支行 | AQ8: 手工新增 | AS8: 杭州红星美凯龙一号店 | AX8: 2855.15 | AY8: 否 | AZ8: 7331710182200026317 | BA8: 2855.15 | BC8: 否 | BD8: 2855.15 | BE8: 完全 | BF8: 2855.15 | BG8: 17.13 | BH8: 2838.02 | BI8: 已审核 | BJ8: 陈联 | BK8: 桑玲 | BL8: 桑玲 | BM8: 2025/9/30 | BN8: 2025-10-07 09:43:51 | BO8: 2025-10-07 09:43:52 | BR8: 否 | BS8: 2855.15 | BW8: 杭州中冠电器有限公司 | BX8: 2855.15 | BZ8: 人民币 | CA8: 否 | CB8: 2025/10/9 | CC8: 是 | CD8: RQRS.00006 | CE8: JSQ31-CLD燃气快速热水器 | CF8: A20250930003028 | CG8: 1 | CH8: 否 | CK8: 9.30刷卡3359元（2855.15+补贴503.85元）【用户姓名:王静涵；用户手机:15990178595；其他号码: 】 | CL8: 2855.15 | CN8: 人民币 | CO8: 固定汇率 | CT8: 杭州地区客户 | CW8: 否 | DD8: 未关闭 | DK8: 王静涵 | DL8: 15990178595
A9: 现款现货收款单 | B9: SKD250930227 | C9: 杭州 | D9: 2025/10/9 | E9: 客户 | F9: 客户 | G9: 人民币 | H9: 503.85 | I9: 503.85 | J9: 杭州中冠电器有限公司 | L9: 杭州中冠电器有限公司 | M9: 杭州红星美凯龙一号店 | N9: 杭州大区 | P9: 503.85 | Q9: 吴红玉 | R9: 人民币 | S9: 固定汇率 | T9: 1 | U9: 503.85 | V9: 503.85 | X9: 完全 | Z9: 销售业务 | AA9: 信用正常 | AB9: 转账 | AC9: 预收款 | AD9: 销售订单 | AE9: 1 | AF9: A20250930003028 | AG9: 503.85 | AI9: 503.85 | AJ9: 503.85 | AM9: 503.85 | AN9: 政府以旧换新中转银行 | AO9: 否 | AP9: 政府以旧换新中转银行 | AQ9: 手工新增 | AS9: 杭州红星美凯龙一号店 | AX9: 503.85 | AY9: 否 | AZ9: 9999999 | BA9: 503.85 | BC9: 否 | BD9: 503.85 | BE9: 完全 | BF9: 503.85 | BH9: 503.85 | BI9: 已审核 | BJ9: 陈联 | BK9: 陈联 | BL9: 桑玲 | BM9: 2025/9/30 | BN9: 2025-09-30 15:35:08 | BO9: 2025-10-07 09:44:01 | BR9: 否 | BS9: 503.85 | BW9: 杭州中冠电器有限公司 | BX9: 503.85 | BZ9: 人民币 | CA9: 否 | CB9: 2025/10/9 | CC9: 是 | CD9: RQRS.00006 | CE9: JSQ31-CLD燃气快速热水器 | CF9: A20250930003028 | CG9: 1 | CH9: 否 | CK9: 9.30刷卡3359元（2855.15+补贴503.85元）【用户姓名:王静涵；用户手机:15990178595；其他号码: 】 | CL9: 503.85 | CN9: 人民币 | CO9: 固定汇率 | CT9: 杭州地区客户 | CW9: 否 | DD9: 未关闭 | DK9: 王静涵 | DL9: 15990178595
A10: 销售收款单 | B10: SKD250930231 | C10: 杭州 | D10: 2025/10/1 | E10: 客户 | F10: 客户 | G10: 人民币 | H10: 11406 | I10: 11331.86 | J10: 杭州中冠电器有限公司 | L10: 杭州中冠电器有限公司 | M10: 自营以旧换新特别账户 | N10: 销管部 | P10: 11406 | Q10: 罗清 | R10: 人民币 | S10: 固定汇率 | T10: 1 | U10: 11406 | V10: 11331.86 | X10: 部分 | Z10: 销售业务 | AA10: 信用正常 | AB10: 转账 | AC10: 销售收款 | AE10: 1 | AG10: 2686 | AI10: 11406 | AJ10: 2686 | AK10: 17.46 | AM10: 2668.54 | AN10: 杭州中冠电器有限公司 | AO10: 否 | AP10: 中信银行杭州钱江支行 | AQ10: 手工新增 | AS10: 自营以旧换新特别账户 | AX10: 2686 | AY10: 否 | AZ10: 7331710182200026317 | BA10: 2686 | BB10: 2025年10月林骞结算(换新1） | BC10: 否 | BE10: 完全 | BF10: 2686 | BG10: 17.46 | BH10: 2668.54 | BI10: 已审核 | BJ10: 毛银萍 | BK10: 桑玲 | BL10: 桑玲 | BM10: 2025/9/30 | BN10: 2025-10-07 09:45:20 | BO10: 2025-10-07 09:45:21 | BR10: 否 | BS10: 2686 | BW10: 杭州中冠电器有限公司 | BX10: 2686 | BZ10: 人民币 | CA10: 否 | CB10: 2025/10/1 | CC10: 是 | CH10: 否 | CK10: 2025年10月1日中信银行收款【用户姓名:2025年10月结算(换新1-4）；用户手机: ；其他号码: 】 | CL10: 2686 | CN10: 人民币 | CO10: 固定汇率 | CT10: 杭州-主城 | CW10: 否 | DD10: 未关闭 | DK10: 2025年10月结算(换新1-4） | DR10: 2025年10月结算(换新1-4）
AB11: 转账 | AC11: 销售收款 | AG11: 2574 | AJ11: 2574 | AK11: 16.73 | AM11: 2557.27 | AN11: 杭州中冠电器有限公司 | AP11: 中信银行杭州钱江支行 | AX11: 2574 | AZ11: 7331710182200026317 | BA11: 2574 | BB11: 2025年10月客户结算(换新2） | BC11: 否 | BE11: 空 | BG11: 16.73 | BH11: 2557.27 | BS11: 2574 | CB11: 2025/10/1 | CC11: 是 | DD11: 未关闭
AB12: 转账 | AC12: 销售收款 | AG12: 3460 | AJ12: 3460 | AK12: 22.49 | AM12: 3437.51 | AN12: 杭州中冠电器有限公司 | AP12: 中信银行杭州钱江支行 | AX12: 3460 | AZ12: 7331710182200026317 | BA12: 3460 | BB12: 2025年10月吴际华结算(换新3） | BC12: 否 | BE12: 空 | BG12: 22.49 | BH12: 3437.51 | BS12: 3460 | CB12: 2025/10/1 | CC12: 是 | DD12: 未关闭
AB13: 转账 | AC13: 销售收款 | AG13: 2686 | AJ13: 2686 | AK13: 17.46 | AM13: 2668.54 | AN13: 杭州中冠电器有限公司 | AP13: 中信银行杭州钱江支行 | AX13: 2686 | AZ13: 7331710182200026317 | BA13: 2686 | BB13: 2025年10月钱冰结算(换新4） | BC13: 否 | BE13: 空 | BG13: 17.46 | BH13: 2668.54 | BS13: 2686 | CB13: 2025/10/1 | CC13: 是 | DD13: 未关闭
A14: 现款现货收款单 | B14: SKD251001016 | C14: 杭州 | D14: 2025/10/9 | E14: 客户 | F14: 客户 | G14: 人民币 | H14: 2991.2 | I14: 2973.25 | J14: 杭州中冠电器有限公司 | L14: 杭州中冠电器有限公司 | M14: 滨江六空8090店 | N14: 杭州大区 | P14: 2991.2 | Q14: 葛芬 | R14: 人民币 | S14: 固定汇率 | T14: 1 | U14: 2991.2 | V14: 2973.25 | X14: 完全 | Z14: 销售业务 | AA14: 信用正常 | AB14: 转账 | AC14: 预收款 | AD14: 销售订单 | AE14: 1 | AF14: A20251001004169 | AG14: 2991.2 | AI14: 2991.2 | AJ14: 2991.2 | AK14: 17.95 | AM14: 2973.25 | AN14: 杭州中冠电器有限公司 | AO14: 否 | AP14: 中信银行杭州钱江支行 | AQ14: 手工新增 | AS14: 滨江六空8090店 | AX14: 2991.2 | AY14: 否 | AZ14: 7331710182200026317 | BA14: 2991.2 | BC14: 否 | BD14: 2991.2 | BE14: 完全 | BF14: 2991.2 | BG14: 17.95 | BH14: 2973.25 | BI14: 已审核 | BJ14: 葛 芬 | BK14: 桑玲 | BL14: 桑玲 | BM14: 2025/10/1 | BN14: 2025-10-07 09:23:52 | BO14: 2025-10-02 12:41:01 | BR14: 否 | BS14: 2991.2 | BW14: 杭州中冠电器有限公司 | BX14: 2991.2 | BZ14: 人民币 | CA14: 否 | CB14: 2025/10/9 | CC14: 是 | CD14: DR.00103 | CE14: EWH-60DA储水式电热水器 | CF14: A20251001004169 | CG14: 1 | CH14: 否 | CK14: 10.1刷卡3739元(2991.2元+补贴747.8元）【用户姓名：钱江】【用户姓名:钱江；用户手机:15381018947；其他号码: 】 | CL14: 2991.2 | CN14: 人民币 | CO14: 固定汇率 | CT14: 杭州-主城 | CW14: 否 | DD14: 未关闭 | DK14: 钱江 | DL14: 15381018947
A15: 现款现货收款单 | B15: SKD251001018 | C15: 杭州 | D15: 2025/10/9 | E15: 客户 | F15: 客户 | G15: 人民币 | H15: 747.8 | I15: 747.8 | J15: 杭州中冠电器有限公司 | L15: 杭州中冠电器有限公司 | M15: 滨江六空8090店 | N15: 杭州大区 | P15: 747.8 | Q15: 葛芬 | R15: 人民币 | S15: 固定汇率 | T15: 1 | U15: 747.8 | V15: 747.8 | X15: 完全 | Z15: 销售业务 | AA15: 信用正常 | AB15: 转账 | AC15: 预收款 | AD15: 销售订单 | AE15: 1 | AF15: A20251001004169 | AG15: 747.8 | AI15: 747.8 | AJ15: 747.8 | AM15: 747.8 | AN15: 政府以旧换新中转银行 | AO15: 否 | AP15: 政府以旧换新中转银行 | AQ15: 手工新增 | AS15: 滨江六空8090店 | AX15: 747.8 | AY15: 否 | AZ15: 9999999 | BA15: 747.8 | BC15: 否 | BD15: 747.8 | BE15: 完全 | BF15: 747.8 | BH15: 747.8 | BI15: 已审核 | BJ15: 葛 芬 | BK15: 葛 芬 | BL15: 桑玲 | BM15: 2025/10/1 | BN15: 2025-10-01 13:43:52 | BO15: 2025-10-02 12:41:11 | BR15: 否 | BS15: 747.8 | BW15: 杭州中冠电器有限公司 | BX15: 747.8 | BZ15: 人民币 | CA15: 否 | CB15: 2025/10/9 | CC15: 是 | CD15: DR.00103 | CE15: EWH-60DA储水式电热水器 | CF15: A20251001004169 | CG15: 1 | CH15: 否 | CK15: 10.1刷卡3739元(2991.2元+补贴747.8元）【用户姓名：钱江】【用户姓名:钱江；用户手机:15381018947；其他号码: 】 | CL15: 747.8 | CN15: 人民币 | CO15: 固定汇率 | CT15: 杭州-主城 | CW15: 否 | DD15: 未关闭 | DK15: 钱江 | DL15: 15381018947
A16: 现款现货收款单 | B16: SKD251001020 | C16: 杭州 | D16: 2025/10/9 | E16: 客户 | F16: 客户 | G16: 人民币 | H16: 2240 | I16: 2226.56 | J16: 杭州中冠电器有限公司 | L16: 杭州中冠电器有限公司 | M16: 滨江六空8090店 | N16: 杭州大区 | P16: 2240 | Q16: 葛芬 | R16: 人民币 | S16: 固定汇率 | T16: 1 | U16: 2240 | V16: 2226.56 | X16: 空 | Z16: 销售业务 | AA16: 信用正常 | AB16: 转账 | AC16: 预收款 | AD16: 销售订单 | AE16: 1 | AF16: A20251001004530 | AG16: 2240 | AI16: 2240 | AJ16: 2240 | AK16: 13.44 | AM16: 2226.56 | AN16: 杭州中冠电器有限公司 | AO16: 否 | AP16: 中信银行杭州钱江支行 | AQ16: 手工新增 | AS16: 滨江六空8090店 | AX16: 2240 | AY16: 否 | AZ16: 7331710182200026317 | BA16: 2240 | BC16: 否 | BD16: 2240 | BE16: 空 | BG16: 13.44 | BH16: 2226.56 | BI16: 已审核 | BJ16: 葛 芬 | BK16: 桑玲 | BL16: 桑玲 | BM16: 2025/10/1 | BN16: 2025-10-07 09:24:21 | BO16: 2025-10-02 12:41:22 | BR16: 否 | BS16: 2240 | BW16: 杭州中冠电器有限公司 | BZ16: 人民币 | CA16: 否 | CB16: 2025/10/9 | CC16: 是 | CD16: DRSQ.00070 | CE16: CEWH-60D1BWi储水式热水器 | CF16: A20251001004530 | CG16: 1 | CH16: 否 | CK16: 10.1刷卡2800元(2240元+补贴560元）【用户姓名：洪二香】【用户姓名:洪二香；用户手机:13738157701；其他号码: 】 | CN16: 人民币 | CO16: 固定汇率 | CT16: 杭州-主城 | CW16: 否 | DD16: 未关闭 | DK16: 洪二香 | DL16: 13738157701
A17: 现款现货收款单 | B17: SKD251001021 | C17: 杭州 | D17: 2025/10/9 | E17: 客户 | F17: 客户 | G17: 人民币 | H17: 560 | I17: 560 | J17: 杭州中冠电器有限公司 | L17: 杭州中冠电器有限公司 | M17: 滨江六空8090店 | N17: 杭州大区 | P17: 560 | Q17: 葛芬 | R17: 人民币 | S17: 固定汇率 | T17: 1 | U17: 560 | V17: 560 | X17: 空 | Z17: 销售业务 | AA17: 信用正常 | AB17: 转账 | AC17: 预收款 | AD17: 销售订单 | AE17: 1 | AF17: A20251001004530 | AG17: 560 | AI17: 560 | AJ17: 560 | AM17: 560 | AN17: 政府以旧换新中转银行 | AO17: 否 | AP17: 政府以旧换新中转银行 | AQ17: 手工新增 | AS17: 滨江六空8090店 | AX17: 560 | AY17: 否 | AZ17: 9999999 | BA17: 560 | BC17: 否 | BD17: 560 | BE17: 空 | BH17: 560 | BI17: 已审核 | BJ17: 葛 芬 | BK17: 葛 芬 | BL17: 桑玲 | BM17: 2025/10/1 | BN17: 2025-10-01 14:21:40 | BO17: 2025-10-02 12:41:56 | BR17: 否 | BS17: 560 | BW17: 杭州中冠电器有限公司 | BZ17: 人民币 | CA17: 否 | CB17: 2025/10/9 | CC17: 是 | CD17: DRSQ.00070 | CE17: CEWH-60D1BWi储水式热水器 | CF17: A20251001004530 | CG17: 1 | CH17: 否 | CK17: 10.1刷卡2800元(2240元+补贴560元）【用户姓名：洪二香】【用户姓名:洪二香；用户手机:13738157701；其他号码: 】 | CN17: 人民币 | CO17: 固定汇率 | CT17: 杭州-主城 | CW17: 否 | DD17: 未关闭 | DK17: 洪二香 | DL17: 13738157701
A18: 现款现货收款单 | B18: SKD251002016 | C18: 杭州 | D18: 2025/10/1 | E18: 客户 | F18: 客户 | G18: 人民币 | H18: 4399 | I18: 4399 | J18: 杭州中冠电器有限公司 | L18: 杭州中冠电器有限公司 | M18: 萧山第六空间专卖店 | N18: 杭州大区 | P18: 4399 | Q18: 徐美娟 | R18: 人民币 | S18: 固定汇率 | T18: 1 | U18: 4399 | V18: 4399 | X18: 完全 | Z18: 销售业务 | AA18: 信用正常 | AB18: 转账 | AC18: 预收款 | AD18: 销售订单 | AE18: 1 | AF18: A20251001008995 | AG18: 4399 | AI18: 4399 | AJ18: 4399 | AM18: 4399 | AN18: 杭州中冠电器有限公司支付宝 | AO18: 否 | AP18: 杭州中冠电器有限公司支付宝 | AQ18: 手工新增 | AS18: 萧山第六空间专卖店 | AX18: 4399 | AY18: 否 | AZ18: hzzgcw@163.com | BA18: 4399 | BC18: 否 | BD18: 4399 | BE18: 完全 | BF18: 4399 | BH18: 4399 | BI18: 已审核 | BJ18: 徐美娟 | BK18: 桑玲 | BL18: 桑玲 | BM18: 2025/10/2 | BN18: 2025-10-02 12:43:47 | BO18: 2025-10-02 12:44:05 | BR18: 否 | BS18: 4399 | BW18: 杭州中冠电器有限公司 | BX18: 4399 | BZ18: 人民币 | CA18: 否 | CB18: 2025/10/1 | CC18: 是 | CD18: DRSQ.00026 | CE18: EWH-60HGCWi薄型电热水器 | CF18: A20251001008995 | CG18: 1 | CH18: 否 | CK18: 10.1号王旭支付宝转账4399元【用户姓名:王旭；用户手机:15157146987；其他号码: 】 | CL18: 4399 | CN18: 人民币 | CO18: 固定汇率 | CT18: 杭州-萧山 | CW18: 否 | DD18: 未关闭 | DK18: 王旭 | DL18: 15157146987 | DR18: 2025100122001464461405582215
A19: 现款现货收款单 | B19: SKD251002032 | C19: 金华 | D19: 2025/10/2 | E19: 客户 | F19: 客户 | G19: 人民币 | H19: 4059 | I19: 4050.27 | J19: 杭州中冠电器有限公司 | L19: 杭州中冠电器有限公司 | M19: 金华龙腾建材市场专卖店 | N19: 金华办事处 | P19: 4059 | Q19: 潘杏 | R19: 人民币 | S19: 固定汇率 | T19: 1 | U19: 4059 | V19: 4050.27 | X19: 完全 | Z19: 销售业务 | AA19: 信用正常 | AB19: 扫码牌 | AC19: 预收款 | AD19: 销售订单 | AE19: 1 | AF19: A20251001006320 | AG19: 4059 | AI19: 4059 | AJ19: 4059 | AK19: 8.73 | AM19: 4050.27 | AN19: 杭州中冠电器有限公司 | AO19: 否 | AP19: 中信银行杭州钱江支行 | AQ19: 手工新增 | AS19: 金华龙腾建材市场专卖店 | AX19: 4059 | AY19: 否 | AZ19: 7331710182200026317 | BA19: 4059 | BC19: 否 | BD19: 4059 | BE19: 完全 | BF19: 4059 | BG19: 8.73 | BH19: 4050.27 | BI19: 已审核 | BJ19: 周琴 | BK19: 桑玲 | BL19: 桑玲 | BM19: 2025/10/2 | BN19: 2025-10-02 12:47:37 | BO19: 2025-10-02 12:48:11 | BR19: 否 | BS19: 4059 | BW19: 杭州中冠电器有限公司 | BX19: 4059 | BZ19: 人民币 | CA19: 否 | CB19: 2025/10/2 | CC19: 是 | CD19: RQRS.00050 | CE19: JSW31-VOSWi燃气热水器（含排烟组件总成403879-079） | CF19: A20251001006320 | CG19: 1 | CH19: 否 | CK19: 10.1号扫码支付4059【用户姓名:诸葛伟；用户手机:15258992858；其他号码: 】 | CL19: 4059 | CN19: 人民币 | CO19: 固定汇率 | CT19: 金华-主城 | CW19: 否 | DD19: 未关闭 | DK19: 诸葛伟 | DL19: 15258992858
A20: 现款现货收款单 | B20: SKD251002033 | C20: 金华 | D20: 2025/10/3 | E20: 客户 | F20: 客户 | G20: 人民币 | H20: 3599 | I20: 3591.26 | J20: 杭州中冠电器有限公司 | L20: 杭州中冠电器有限公司 | M20: 金华龙腾建材市场专卖店 | N20: 金华办事处 | P20: 3599 | Q20: 潘杏 | R20: 人民币 | S20: 固定汇率 | T20: 1 | U20: 3599 | V20: 3591.26 | X20: 完全 | Z20: 销售业务 | AA20: 信用正常 | AB20: 扫码牌 | AC20: 预收款 | AD20: 销售订单 | AE20: 1 | AF20: A20251002000780 | AG20: 3599 | AI20: 3599 | AJ20: 3599 | AK20: 7.74 | AM20: 3591.26 | AN20: 杭州中冠电器有限公司 | AO20: 否 | AP20: 中信银行杭州钱江支行 | AQ20: 手工新增 | AS20: 金华龙腾建材市场专卖店 | AX20: 3599 | AY20: 否 | AZ20: 7331710182200026317 | BA20: 3599 | BC20: 否 | BD20: 3599 | BE20: 完全 | BF20: 3599 | BG20: 7.74 | BH20: 3591.26 | BI20: 已审核 | BJ20: 周琴 | BK20: 桑玲 | BL20: 桑玲 | BM20: 2025/10/2 | BN20: 2025-10-07 09:25:24 | BO20: 2025-10-03 14:57:42 | BR20: 否 | BS20: 3599 | BW20: 杭州中冠电器有限公司 | BX20: 3599 | BZ20: 人民币 | CA20: 否 | CB20: 2025/10/3 | CC20: 是 | CD20: DRSQ.00039 | CE20: CEWH-100KWi电热水器 | CF20: A20251002000780 | CG20: 1 | CH20: 否 | CK20: 10.2扫码支付3599【用户姓名:林爱花；用户手机:13857981322；其他号码: 】 | CL20: 3599 | CN20: 人民币 | CO20: 固定汇率 | CT20: 金华-主城 | CW20: 否 | DD20: 未关闭 | DK20: 林爱花 | DL20: 13857981322
A21: 销售收款单 | B21: SKD251002034 | C21: 金华 | D21: 2025/10/2 | E21: 客户 | F21: 客户 | G21: 人民币 | H21: 2360 | I21: 2360 | J21: 杭州中冠电器有限公司 | L21: 杭州中冠电器有限公司 | M21: 衢州市柯城汇鑫家用电器商行 | N21: 金华办事处 | P21: 2360 | Q21: 江雯 | R21: 人民币 | S21: 固定汇率 | T21: 1 | U21: 2360 | V21: 2360 | X21: 空 | Z21: 销售业务 | AA21: 信用正常 | AB21: 转账 | AC21: 销售收款 | AE21: 1 | AG21: 2360 | AI21: 2360 | AJ21: 2360 | AM21: 2360 | AN21: 李扬-金华 | AO21: 否 | AP21: 中国建设银行股份有限公司金华经济开发区支行 | AQ21: 手工新增 | AS21: 衢州市柯城汇鑫家用电器商行 | AX21: 2360 | AY21: 否 | AZ21: 4367421460407338728 | BA21: 2360 | BC21: 否 | BE21: 空 | BH21: 2360 | BI21: 已审核 | BJ21: 王小婷 | BK21: 王小婷 | BL21: 桑玲 | BM21: 2025/10/2 | BN21: 2025-10-02 13:04:23 | BO21: 2025-10-03 14:55:29 | BR21: 否 | BS21: 2360 | BW21: 杭州中冠电器有限公司 | BZ21: 人民币 | CA21: 否 | CB21: 2025/10/2 | CC21: 是 | CH21: 否 | CK21: 10.2金华建行2360【用户姓名:郑星；用户手机: ；其他号码: 】 | CN21: 人民币 | CO21: 固定汇率 | CT21: 衢州-主城 | CW21: 否 | DD21: 未关闭 | DK21: 郑星
A22: 现款现货收款单 | B22: SKD251002077 | C22: 杭州 | D22: 2025/10/2 | E22: 客户 | F22: 客户 | G22: 人民币 | H22: 2071 | I22: 2071 | J22: 杭州中冠电器有限公司 | L22: 杭州中冠电器有限公司 | M22: 杭州红星美凯龙一号店 | N22: 杭州大区 | P22: 2071 | Q22: 吴红玉 | R22: 人民币 | S22: 固定汇率 | T22: 1 | U22: 2071 | V22: 2071 | X22: 完全 | Z22: 销售业务 | AA22: 信用正常 | AB22: 转账 | AC22: 预收款 | AD22: 销售订单 | AE22: 1 | AF22: A20251002000984 | AG22: 2071 | AI22: 2071 | AJ22: 2071 | AM22: 2071 | AN22: 杭州中冠电器有限公司支付宝 | AO22: 否 | AP22: 杭州中冠电器有限公司支付宝 | AQ22: 手工新增 | AS22: 杭州红星美凯龙一号店 | AX22: 2071 | AY22: 否 | AZ22: hzzgcw@163.com | BA22: 2071 | BC22: 否 | BD22: 2071 | BE22: 完全 | BF22: 2071 | BH22: 2071 | BI22: 已审核 | BJ22: 陈联 | BK22: 陈联 | BL22: 桑玲 | BM22: 2025/10/2 | BN22: 2025-10-02 15:09:04 | BO22: 2025-10-03 14:49:21 | BR22: 否 | BS22: 2071 | BW22: 杭州中冠电器有限公司 | BX22: 2071 | BZ22: 人民币 | CA22: 否 | CB22: 2025/10/2 | CC22: 是 | CD22: YSJ.00056 | CE22: APM-HC1 管线机 | CF22: A20251002000984 | CG22: 1 | CH22: 否 | CK22: 10.2支付宝2071元【用户姓名:张艳佳；用户手机:18357002327；其他号码: 】 | CL22: 2071 | CN22: 人民币 | CO22: 固定汇率 | CT22: 杭州地区客户 | CW22: 否 | DD22: 未关闭 | DK22: 张艳佳 | DL22: 18357002327 | DR22: '2025100222001400021430908377
A23: 现款现货收款单 | B23: SKD251002078 | C23: 杭州 | D23: 2025/10/2 | E23: 客户 | F23: 客户 | G23: 人民币 | H23: 3439 | I23: 3439 | J23: 杭州中冠电器有限公司 | L23: 杭州中冠电器有限公司 | M23: 杭州红星美凯龙一号店 | N23: 杭州大区 | P23: 3439 | Q23: 吴红玉 | R23: 人民币 | S23: 固定汇率 | T23: 1 | U23: 3439 | V23: 3439 | X23: 完全 | Z23: 销售业务 | AA23: 信用正常 | AB23: 转账 | AC23: 预收款 | AD23: 销售订单 | AE23: 1 | AF23: A20251002002898 | AG23: 3439 | AI23: 3439 | AJ23: 3439 | AM23: 3439 | AN23: 杭州中冠电器有限公司支付宝 | AO23: 否 | AP23: 杭州中冠电器有限公司支付宝 | AQ23: 手工新增 | AS23: 杭州红星美凯龙一号店 | AX23: 3439 | AY23: 否 | AZ23: hzzgcw@163.com | BA23: 3439 | BC23: 否 | BD23: 3439 | BE23: 完全 | BF23: 3439 | BH23: 3439 | BI23: 已审核 | BJ23: 陈联 | BK23: 陈联 | BL23: 桑玲 | BM23: 2025/10/2 | BN23: 2025-10-03 10:33:47 | BO23: 2025-10-03 14:49:04 | BR23: 否 | BS23: 3439 | BW23: 杭州中冠电器有限公司 | BX23: 3439 | BZ23: 人民币 | CA23: 否 | CB23: 2025/10/2 | CC23: 是 | CD23: DR.00103 | CE23: EWH-60DA储水式电热水器 | CF23: A20251002002898 | CG23: 1 | CH23: 否 | CK23: 10.2支付宝3439元【用户姓名:吴苏萍；用户手机:13666640691；其他号码: 】 | CL23: 3439 | CN23: 人民币 | CO23: 固定汇率 | CT23: 杭州地区客户 | CW23: 否 | DD23: 未关闭 | DK23: 吴苏萍 | DL23: 13666640691 | DR23: 2025100222001431571449156527
A24: 销售收款单 | B24: SKD251003058 | C24: 杭州 | D24: 2025/10/3 | E24: 客户 | F24: 客户 | G24: 人民币 | H24: 3439 | I24: 3431.61 | J24: 杭州中冠电器有限公司 | L24: 杭州中冠电器有限公司 | M24: 杭州红星美凯龙一号店 | N24: 杭州大区 | P24: 3439 | Q24: 吴红玉 | R24: 人民币 | S24: 固定汇率 | T24: 1 | U24: 3439 | V24: 3431.61 | X24: 完全 | Z24: 销售业务 | AA24: 信用正常 | AB24: 扫码牌 | AC24: 销售收款 | AE24: 1 | AG24: 3439 | AI24: 3439 | AJ24: 3439 | AK24: 7.39 | AM24: 3431.61 | AN24: 杭州中冠电器有限公司 | AO24: 否 | AP24: 中信银行杭州钱江支行 | AQ24: 手工新增 | AS24: 杭州红星美凯龙一号店 | AX24: 3439 | AY24: 否 | AZ24: 7331710182200026317 | BA24: 3439 | BC24: 否 | BE24: 完全 | BF24: 3439 | BG24: 7.39 | BH24: 3431.61 | BI24: 已审核 | BJ24: 陈联 | BK24: 桑玲 | BL24: 桑玲 | BM24: 2025/10/3 | BN24: 2025-10-07 09:46:14 | BO24: 2025-10-07 09:46:14 | BR24: 否 | BS24: 3439 | BW24: 杭州中冠电器有限公司 | BX24: 3439 | BZ24: 人民币 | CA24: 否 | CB24: 2025/10/3 | CC24: 是 | CH24: 否 | CK24: 10.2扫码付3439元【用户姓名:吴苏萍；用户手机:13666640691；其他号码: 】 | CL24: 3439 | CN24: 人民币 | CO24: 固定汇率 | CT24: 杭州地区客户 | CW24: 否 | DD24: 未关闭 | DK24: 吴苏萍 | DL24: 13666640691
A25: 现款现货收款单 | B25: SKD251003063 | C25: 杭州 | D25: 2025/10/2 | E25: 客户 | F25: 客户 | G25: 人民币 | H25: 5220 | I25: 5220 | J25: 杭州中冠电器有限公司 | L25: 杭州中冠电器有限公司 | M25: 杭州红星美凯龙一号店 | N25: 杭州大区 | P25: 5220 | Q25: 吴红玉 | R25: 人民币 | S25: 固定汇率 | T25: 1 | U25: 5220 | V25: 5220 | X25: 完全 | Z25: 销售业务 | AA25: 信用正常 | AB25: 转账 | AC25: 预收款 | AD25: 销售订单 | AE25: 1 | AF25: A20251003000652 | AG25: 5220 | AI25: 5220 | AJ25: 5220 | AM25: 5220 | AN25: 杭州中冠电器有限公司支付宝 | AO25: 否 | AP25: 杭州中冠电器有限公司支付宝 | AQ25: 手工新增 | AS25: 杭州红星美凯龙一号店 | AX25: 5220 | AY25: 否 | AZ25: hzzgcw@163.com | BA25: 5220 | BC25: 否 | BD25: 5220 | BE25: 完全 | BF25: 5220 | BH25: 5220 | BI25: 已审核 | BJ25: 陈联 | BK25: 陈联 | BL25: 桑玲 | BM25: 2025/10/3 | BN25: 2025-10-03 10:38:21 | BO25: 2025-10-03 14:48:41 | BR25: 否 | BS25: 5220 | BW25: 杭州中冠电器有限公司 | BX25: 5220 | BZ25: 人民币 | CA25: 否 | CB25: 2025/10/2 | CC25: 是 | CD25: DRSQ.00027 | CE25: EWH-80HGCWi薄型电热水器 | CF25: A20251003000652 | CG25: 1 | CH25: 否 | CK25: 10.2支付宝5220元【用户姓名:郑笑平；用户手机:13575840935；其他号码: 】 | CL25: 5220 | CN25: 人民币 | CO25: 固定汇率 | CT25: 杭州地区客户 | CW25: 否 | DD25: 未关闭 | DK25: 郑笑平 | DL25: 13575840935 | DR25: '2025100222001431511430156610
A26: 现款现货收款单 | B26: SKD251003091 | C26: 杭州 | D26: 2025/10/9 | E26: 客户 | F26: 客户 | G26: 人民币 | H26: 2460.8 | I26: 2446.04 | J26: 杭州中冠电器有限公司 | L26: 杭州中冠电器有限公司 | M26: 杭州红星美凯龙一号店 | N26: 杭州大区 | P26: 2460.8 | Q26: 吴红玉 | R26: 人民币 | S26: 固定汇率 | T26: 1 | U26: 2460.8 | V26: 2446.04 | X26: 完全 | Z26: 销售业务 | AA26: 信用正常 | AB26: 转账 | AC26: 预收款 | AD26: 销售订单 | AE26: 1 | AF26: A20250919005149C | AG26: 2460.8 | AI26: 2460.8 | AJ26: 2460.8 | AK26: 14.76 | AM26: 2446.04 | AN26: 杭州中冠电器有限公司 | AO26: 否 | AP26: 中信银行杭州钱江支行 | AQ26: 手工新增 | AS26: 杭州红星美凯龙一号店 | AX26: 2460.8 | AY26: 否 | AZ26: 7331710182200026317 | BA26: 2460.8 | BC26: 否 | BD26: 2460.8 | BE26: 完全 | BF26: 2460.8 | BG26: 14.76 | BH26: 2446.04 | BI26: 已审核 | BJ26: 陈联 | BK26: 桑玲 | BL26: 桑玲 | BM26: 2025/10/3 | BN26: 2025-10-07 09:26:43 | BO26: 2025-10-03 14:50:55 | BR26: 否 | BS26: 2460.8 | BW26: 杭州中冠电器有限公司 | BX26: 2460.8 | BZ26: 人民币 | CA26: 否 | CB26: 2025/10/9 | CC26: 是 | CD26: DRSQ.00067 | CE26: CEWH-60D1Wi储水电热水器 | CF26: A20250919005149C | CG26: 1 | CH26: 否 | CK26: 10.1刷卡3076元（2460.8+补贴615.20元）【用户姓名:李冬梅；用户手机:13705719928；其他号码: 】 | CL26: 2460.8 | CN26: 人民币 | CO26: 固定汇率 | CT26: 杭州地区客户 | CW26: 否 | DD26: 未关闭 | DK26: 李冬梅 | DL26: 13705719928
A27: 现款现货收款单 | B27: SKD251003092 | C27: 杭州 | D27: 2025/10/9 | E27: 客户 | F27: 客户 | G27: 人民币 | H27: 615.2 | I27: 615.2 | J27: 杭州中冠电器有限公司 | L27: 杭州中冠电器有限公司 | M27: 杭州红星美凯龙一号店 | N27: 杭州大区 | P27: 615.2 | Q27: 吴红玉 | R27: 人民币 | S27: 固定汇率 | T27: 1 | U27: 615.2 | V27: 615.2 | X27: 完全 | Z27: 销售业务 | AA27: 信用正常 | AB27: 转账 | AC27: 预收款 | AD27: 销售订单 | AE27: 1 | AF27: A20250919005149C | AG27: 615.2 | AI27: 615.2 | AJ27: 615.2 | AM27: 615.2 | AN27: 政府以旧换新中转银行 | AO27: 否 | AP27: 政府以旧换新中转银行 | AQ27: 手工新增 | AS27: 杭州红星美凯龙一号店 | AX27: 615.2 | AY27: 否 | AZ27: 9999999 | BA27: 615.2 | BC27: 否 | BD27: 615.2 | BE27: 完全 | BF27: 615.2 | BH27: 615.2 | BI27: 已审核 | BJ27: 陈联 | BK27: 陈联 | BL27: 桑玲 | BM27: 2025/10/3 | BN27: 2025-10-03 11:00:29 | BO27: 2025-10-03 14:51:18 | BR27: 否 | BS27: 615.2 | BW27: 杭州中冠电器有限公司 | BX27: 615.2 | BZ27: 人民币 | CA27: 否 | CB27: 2025/10/9 | CC27: 是 | CD27: DRSQ.00067 | CE27: CEWH-60D1Wi储水电热水器 | CF27: A20250919005149C | CG27: 1 | CH27: 否 | CK27: 10.1刷卡3076元（2460.8+补贴615.20元）【用户姓名:李冬梅；用户手机:13705719928；其他号码: 】 | CL27: 615.2 | CN27: 人民币 | CO27: 固定汇率 | CT27: 杭州地区客户 | CW27: 否 | DD27: 未关闭 | DK27: 李冬梅 | DL27: 13705719928
A28: 现款现货收款单 | B28: SKD251003135 | C28: 杭州 | D28: 2025/10/3 | E28: 客户 | F28: 客户 | G28: 人民币 | H28: 3639 | I28: 3639 | J28: 杭州中冠电器有限公司 | L28: 杭州中冠电器有限公司 | M28: 滨江六空8090店 | N28: 杭州大区 | P28: 3639 | Q28: 葛芬 | R28: 人民币 | S28: 固定汇率 | T28: 1 | U28: 3639 | V28: 3639 | X28: 完全 | Z28: 销售业务 | AA28: 信用正常 | AB28: 转账 | AC28: 预收款 | AD28: 销售订单 | AE28: 1 | AF28: A20251003001834 | AG28: 3639 | AI28: 3639 | AJ28: 3639 | AM28: 3639 | AN28: 杭州中冠电器有限公司支付宝 | AO28: 否 | AP28: 杭州中冠电器有限公司支付宝 | AQ28: 手工新增 | AS28: 滨江六空8090店 | AX28: 3639 | AY28: 否 | AZ28: hzzgcw@163.com | BA28: 3639 | BC28: 否 | BD28: 3639 | BE28: 完全 | BF28: 3639 | BH28: 3639 | BI28: 已审核 | BJ28: 葛 芬 | BK28: 桑玲 | BL28: 桑玲 | BM28: 2025/10/3 | BN28: 2025-10-07 09:28:05 | BO28: 2025-10-07 09:28:06 | BR28: 否 | BS28: 3639 | BW28: 杭州中冠电器有限公司 | BX28: 3639 | BZ28: 人民币 | CA28: 否 | CB28: 2025/10/3 | CC28: 是 | CD28: DR.00103 | CE28: EWH-60DA储水式电热水器 | CF28: A20251003001834 | CG28: 1 | CH28: 否 | CK28: 10.3支付宝转账3639元（用户名 王旭东）【用户姓名:王旭东；用户手机:13750837396；其他号码: 】 | CL28: 3639 | CN28: 人民币 | CO28: 固定汇率 | CT28: 杭州-主城 | CW28: 否 | DD28: 未关闭 | DK28: 王旭东 | DL28: 13750837396 | DR28: 2025100322001459741433588445
A29: 现款现货收款单 | B29: SKD251003136 | C29: 杭州 | D29: 2025/10/3 | E29: 客户 | F29: 客户 | G29: 人民币 | H29: 2591 | I29: 2591 | J29: 杭州中冠电器有限公司 | L29: 杭州中冠电器有限公司 | M29: 杭州红星美凯龙一号店 | N29: 杭州大区 | P29: 2591 | Q29: 吴红玉 | R29: 人民币 | S29: 固定汇率 | T29: 1 | U29: 2591 | V29: 2591 | X29: 完全 | Z29: 销售业务 | AA29: 信用正常 | AB29: 转账 | AC29: 预收款 | AD29: 销售订单 | AE29: 1 | AF29: A20251003000910 | AG29: 2591 | AI29: 2591 | AJ29: 2591 | AM29: 2591 | AN29: 杭州中冠电器有限公司支付宝 | AO29: 否 | AP29: 杭州中冠电器有限公司支付宝 | AQ29: 手工新增 | AS29: 杭州红星美凯龙一号店 | AX29: 2591 | AY29: 否 | AZ29: hzzgcw@163.com | BA29: 2591 | BC29: 否 | BD29: 2591 | BE29: 完全 | BF29: 2591 | BH29: 2591 | BI29: 已审核 | BJ29: 陈联 | BK29: 陈联 | BL29: 桑玲 | BM29: 2025/10/3 | BN29: 2025-10-03 13:21:40 | BO29: 2025-10-03 14:45:23 | BR29: 否 | BS29: 2591 | BW29: 杭州中冠电器有限公司 | BX29: 2591 | BZ29: 人民币 | CA29: 否 | CB29: 2025/10/3 | CC29: 是 | CD29: DRSQ.00070 | CE29: CEWH-60D1BWi储水式热水器 | CF29: A20251003000910 | CG29: 1 | CH29: 否 | CK29: 10.3支付宝2591元【用户姓名:金丽敏；用户手机:13335710581；其他号码: 】 | CL29: 2591 | CN29: 人民币 | CO29: 固定汇率 | CT29: 杭州地区客户 | CW29: 否 | DD29: 未关闭 | DK29: 金丽敏 | DL29: 13335710581 | DR29: '2025100322001453241419896070
A30: 现款现货收款单 | B30: SKD251003149 | C30: 杭州 | D30: 2025/10/9 | E30: 客户 | F30: 客户 | G30: 人民币 | H30: 2908.8 | I30: 2891.35 | J30: 杭州中冠电器有限公司 | L30: 杭州中冠电器有限公司 | M30: 杭州红星美凯龙一号店 | N30: 杭州大区 | P30: 2908.8 | Q30: 吴红玉 | R30: 人民币 | S30: 固定汇率 | T30: 1 | U30: 2908.8 | V30: 2891.35 | X30: 完全 | Z30: 销售业务 | AA30: 信用正常 | AB30: 转账 | AC30: 预收款 | AD30: 销售订单 | AE30: 1 | AF30: A20251002000983 | AG30: 2908.8 | AI30: 2908.8 | AJ30: 2908.8 | AK30: 17.45 | AM30: 2891.35 | AN30: 杭州中冠电器有限公司 | AO30: 否 | AP30: 中信银行杭州钱江支行 | AQ30: 手工新增 | AS30: 杭州红星美凯龙一号店 | AX30: 2908.8 | AY30: 否 | AZ30: 7331710182200026317 | BA30: 2908.8 | BC30: 否 | BD30: 2908.8 | BE30: 完全 | BF30: 2908.8 | BG30: 17.45 | BH30: 2891.35 | BI30: 已审核 | BJ30: 陈联 | BK30: 桑玲 | BL30: 桑玲 | BM30: 2025/10/3 | BN30: 2025-10-07 09:35:42 | BO30: 2025-10-06 14:23:59 | BR30: 否 | BS30: 2908.8 | BW30: 杭州中冠电器有限公司 | BX30: 2908.8 | BZ30: 人民币 | CA30: 否 | CB30: 2025/10/9 | CC30: 是 | CD30: YSJ.00042 | CE30: R1700FWi饮水机 | CF30: A20251002000983 | CG30: 1 | CH30: 否 | CK30: 10.2刷卡3636元（2908.8+补贴727.20元）【用户姓名:张艳佳；用户手机:18357002327；其他号码: 】 | CL30: 2908.8 | CN30: 人民币 | CO30: 固定汇率 | CT30: 杭州地区客户 | CW30: 否 | DD30: 未关闭 | DK30: 张艳佳 | DL30: 18357002327
A31: 现款现货收款单 | B31: SKD251003150 | C31: 杭州 | D31: 2025/10/9 | E31: 客户 | F31: 客户 | G31: 人民币 | H31: 727.2 | I31: 727.2 | J31: 杭州中冠电器有限公司 | L31: 杭州中冠电器有限公司 | M31: 杭州红星美凯龙一号店 | N31: 杭州大区 | P31: 727.2 | Q31: 吴红玉 | R31: 人民币 | S31: 固定汇率 | T31: 1 | U31: 727.2 | V31: 727.2 | X31: 完全 | Z31: 销售业务 | AA31: 信用正常 | AB31: 转账 | AC31: 预收款 | AD31: 销售订单 | AE31: 1 | AF31: A20251002000983 | AG31: 727.2 | AI31: 727.2 | AJ31: 727.2 | AM31: 727.2 | AN31: 政府以旧换新中转银行 | AO31: 否 | AP31: 政府以旧换新中转银行 | AQ31: 手工新增 | AS31: 杭州红星美凯龙一号店 | AX31: 727.2 | AY31: 否 | AZ31: 9999999 | BA31: 727.2 | BC31: 否 | BD31: 727.2 | BE31: 完全 | BF31: 727.2 | BH31: 727.2 | BI31: 已审核 | BJ31: 陈联 | BK31: 陈联 | BL31: 桑玲 | BM31: 2025/10/3 | BN31: 2025-10-03 14:55:28 | BO31: 2025-10-06 14:24:13 | BR31: 否 | BS31: 727.2 | BW31: 杭州中冠电器有限公司 | BX31: 727.2 | BZ31: 人民币 | CA31: 否 | CB31: 2025/10/9 | CC31: 是 | CD31: YSJ.00042 | CE31: R1700FWi饮水机 | CF31: A20251002000983 | CG31: 1 | CH31: 否 | CK31: 10.2刷卡3636元（2908.8+补贴727.20元）【用户姓名:张艳佳；用户手机:18357002327；其他号码: 】 | CL31: 727.2 | CN31: 人民币 | CO31: 固定汇率 | CT31: 杭州地区客户 | CW31: 否 | DD31: 未关闭 | DK31: 张艳佳 | DL31: 18357002327
A32: 现款现货收款单 | B32: SKD251003152 | C32: 湖州 | D32: 2025/10/3 | E32: 客户 | F32: 客户 | G32: 人民币 | H32: 4481 | I32: 4481 | J32: 杭州中冠电器有限公司 | L32: 杭州中冠电器有限公司 | M32: 湖州金蝶零售 | N32: 湖州办事处 | P32: 4481 | Q32: 陈中元 | R32: 人民币 | S32: 固定汇率 | T32: 1 | U32: 4481 | V32: 4481 | X32: 完全 | Z32: 销售业务 | AA32: 信用正常 | AB32: 转账 | AC32: 预收款 | AD32: 销售订单 | AE32: 1 | AF32: XSDD251003011 | AG32: 4481 | AI32: 4481 | AJ32: 4481 | AM32: 4481 | AN32: 杭州中冠电器有限公司 | AO32: 否 | AP32: 中信银行杭州钱江支行 | AQ32: 手工新增 | AS32: 湖州金蝶零售 | AX32: 4481 | AY32: 否 | AZ32: 7331710182200026317 | BA32: 4481 | BC32: 否 | BD32: 4481 | BE32: 完全 | BF32: 4481 | BH32: 4481 | BI32: 已审核 | BJ32: 陈联 | BK32: 陈联 | BL32: 桑玲 | BM32: 2025/10/3 | BN32: 2025-10-03 15:35:22 | BO32: 2025-10-03 15:38:27 | BR32: 否 | BS32: 4481 | BW32: 杭州中冠电器有限公司 | BX32: 4481 | BZ32: 人民币 | CA32: 否 | CB32: 2025/10/3 | CC32: 是 | CD32: RQRS.00009 | CE32: JSQ31-CSCAi燃气快速热水器通用 | CF32: XSDD251003011 | CG32: 1 | CH32: 否 | CK32: 10.3转账4481元【用户姓名:湖州中太芯猫科技有限公司；用户手机:1315725269；其他号码: 】 | CL32: 4481 | CN32: 人民币 | CO32: 固定汇率 | CT32: 湖州-主城 | CW32: 否 | DD32: 未关闭 | DK32: 湖州中太芯猫科技有限公司 | DL32: 1315725269
A33: 现款现货收款单 | B33: SKD251003153 | C33: 杭州 | D33: 2025/10/3 | E33: 客户 | F33: 客户 | G33: 人民币 | H33: 6365 | I33: 6365 | J33: 杭州中冠电器有限公司 | L33: 杭州中冠电器有限公司 | M33: 萧山第六空间专卖店 | N33: 杭州大区 | P33: 6365 | Q33: 徐美娟 | R33: 人民币 | S33: 固定汇率 | T33: 1 | U33: 6365 | V33: 6365 | X33: 完全 | Z33: 销售业务 | AA33: 信用正常 | AB33: 转账 | AC33: 预收款 | AD33: 销售订单 | AE33: 1 | AF33: A20251003000556 | AG33: 6365 | AI33: 6365 | AJ33: 6365 | AM33: 6365 | AN33: 杭州中冠电器有限公司支付宝 | AO33: 否 | AP33: 杭州中冠电器有限公司支付宝 | AQ33: 手工新增 | AS33: 萧山第六空间专卖店 | AX33: 6365 | AY33: 否 | AZ33: hzzgcw@163.com | BA33: 6365 | BC33: 否 | BD33: 6365 | BE33: 完全 | BF33: 6365 | BH33: 6365 | BI33: 已审核 | BJ33: 陈联 | BK33: 陈联 | BL33: 桑玲 | BM33: 2025/10/3 | BN33: 2025-10-03 15:51:44 | BO33: 2025-10-03 15:52:39 | BR33: 否 | BS33: 6365 | BW33: 杭州中冠电器有限公司 | BX33: 6365 | BZ33: 人民币 | CA33: 否 | CB33: 2025/10/3 | CC33: 是 | CD33: YSJ.00013 | CE33: DR1800HF2Ai反渗透净水机 | CF33: A20251003000556 | CG33: 1 | CH33: 否 | CK33: 10.3支付宝6365元【用户姓名:陈海军；用户手机:13616539181；其他号码: 】 | CL33: 6365 | CN33: 人民币 | CO33: 固定汇率 | CT33: 杭州-萧山 | CW33: 否 | DD33: 未关闭 | DK33: 陈海军 | DL33: 13616539181 | DR33: 2025100322001438391430215115
A34: 现款现货收款单 | B34: SKD251004017 | C34: 杭州 | D34: 2025/10/9 | E34: 客户 | F34: 客户 | G34: 人民币 | H34: 3717.6 | I34: 3695.29 | J34: 杭州中冠电器有限公司 | L34: 杭州中冠电器有限公司 | M34: 滨江六空8090店 | N34: 杭州大区 | P34: 3717.6 | Q34: 葛芬 | R34: 人民币 | S34: 固定汇率 | T34: 1 | U34: 3717.6 | V34: 3695.29 | X34: 完全 | Z34: 销售业务 | AA34: 信用正常 | AB34: 转账 | AC34: 预收款 | AD34: 销售订单 | AE34: 1 | AF34: A20251004001163 | AG34: 3717.6 | AI34: 3717.6 | AJ34: 3717.6 | AK34: 22.31 | AM34: 3695.29 | AN34: 杭州中冠电器有限公司 | AO34: 否 | AP34: 中信银行杭州钱江支行 | AQ34: 手工新增 | AS34: 滨江六空8090店 | AX34: 3717.6 | AY34: 否 | AZ34: 7331710182200026317 | BA34: 3717.6 | BC34: 否 | BD34: 3717.6 | BE34: 完全 | BF34: 3717.6 | BG34: 22.31 | BH34: 3695.29 | BI34: 已审核 | BJ34: 葛 芬 | BK34: 桑玲 | BL34: 桑玲 | BM34: 2025/10/4 | BN34: 2025-10-07 09:36:15 | BO34: 2025-10-06 12:53:16 | BR34: 否 | BS34: 3717.6 | BW34: 杭州中冠电器有限公司 | BX34: 3717.6 | BZ34: 人民币 | CA34: 否 | CB34: 2025/10/9 | CC34: 是 | CD34: YSJ.00040 | CE34: R2000FWi饮水机 | CF34: A20251004001163 | CG34: 1 | CH34: 否 | CK34: 10.3刷卡4647元(3717.6元+补贴929.4元）（用户名 刘利）【用户姓名:刘利；用户手机:15268117016；其他号码: 】 | CL34: 3717.6 | CN34: 人民币 | CO34: 固定汇率 | CT34: 杭州-主城 | CW34: 否 | DD34: 未关闭 | DK34: 刘利 | DL34: 15268117016
A35: 现款现货收款单 | B35: SKD251004018 | C35: 杭州 | D35: 2025/10/9 | E35: 客户 | F35: 客户 | G35: 人民币 | H35: 929.4 | I35: 929.4 | J35: 杭州中冠电器有限公司 | L35: 杭州中冠电器有限公司 | M35: 滨江六空8090店 | N35: 杭州大区 | P35: 929.4 | Q35: 葛芬 | R35: 人民币 | S35: 固定汇率 | T35: 1 | U35: 929.4 | V35: 929.4 | X35: 完全 | Z35: 销售业务 | AA35: 信用正常 | AB35: 转账 | AC35: 预收款 | AD35: 销售订单 | AE35: 1 | AF35: A20251004001163 | AG35: 929.4 | AI35: 929.4 | AJ35: 929.4 | AM35: 929.4 | AN35: 政府以旧换新中转银行 | AO35: 否 | AP35: 政府以旧换新中转银行 | AQ35: 手工新增 | AS35: 滨江六空8090店 | AX35: 929.4 | AY35: 否 | AZ35: 9999999 | BA35: 929.4 | BC35: 否 | BD35: 929.4 | BE35: 完全 | BF35: 929.4 | BH35: 929.4 | BI35: 已审核 | BJ35: 葛 芬 | BK35: 葛 芬 | BL35: 桑玲 | BM35: 2025/10/4 | BN35: 2025-10-04 11:52:01 | BO35: 2025-10-06 12:53:31 | BR35: 否 | BS35: 929.4 | BW35: 杭州中冠电器有限公司 | BX35: 929.4 | BZ35: 人民币 | CA35: 否 | CB35: 2025/10/9 | CC35: 是 | CD35: YSJ.00040 | CE35: R2000FWi饮水机 | CF35: A20251004001163 | CG35: 1 | CH35: 否 | CK35: 10.3刷卡4647元(3717.6元+补贴929.4元）（用户名 刘利）【用户姓名:刘利；用户手机:15268117016；其他号码: 】 | CL35: 929.4 | CN35: 人民币 | CO35: 固定汇率 | CT35: 杭州-主城 | CW35: 否 | DD35: 未关闭 | DK35: 刘利 | DL35: 15268117016
A36: 现款现货收款单 | B36: SKD251004050 | C36: 杭州 | D36: 2025/10/4 | E36: 客户 | F36: 客户 | G36: 人民币 | H36: 5000 | I36: 5000 | J36: 杭州中冠电器有限公司 | L36: 杭州中冠电器有限公司 | M36: 杭州临平江南家居专卖店 | N36: 杭州大区 | P36: 5000 | Q36: 余亚炜 | R36: 人民币 | S36: 固定汇率 | T36: 1 | U36: 5000 | V36: 5000 | X36: 完全 | Z36: 销售业务 | AA36: 信用正常 | AB36: 转账 | AC36: 预收款 | AD36: 销售订单 | AE36: 1 | AF36: A20251004000621 | AG36: 5000 | AI36: 5000 | AJ36: 5000 | AM36: 5000 | AN36: 杭州中冠电器有限公司支付宝 | AO36: 否 | AP36: 杭州中冠电器有限公司支付宝 | AQ36: 手工新增 | AS36: 杭州临平江南家居专卖店 | AX36: 5000 | AY36: 否 | AZ36: hzzgcw@163.com | BA36: 5000 | BC36: 否 | BD36: 5000 | BE36: 完全 | BF36: 5000 | BH36: 5000 | BI36: 已审核 | BJ36: 余亚炜 | BK36: 余亚炜 | BL36: 桑玲 | BM36: 2025/10/4 | BN36: 2025-10-04 14:54:45 | BO36: 2025-10-06 12:54:03 | BR36: 否 | BS36: 5000 | BW36: 杭州中冠电器有限公司 | BX36: 5000 | BZ36: 人民币 | CA36: 否 | CB36: 2025/10/4 | CC36: 是 | CD36: YYJ.00008 | CE36: CXW-200-Q3AWi易清洁顶侧双吸油烟机 | CF36: A20251004000621 | CG36: 1 | CH36: 否 | CK36: 10.4扫码转支付宝5000元【用户姓名:徐广东；用户手机:13683762291；其他号码: 】 | CL36: 5000 | CN36: 人民币 | CO36: 固定汇率 | CT36: 杭州-余杭 | CW36: 否 | DD36: 未关闭 | DK36: 徐广东 | DL36: 13683762291 | DR36: 2025100422001497631442263144
A37: 销售收款单 | B37: SKD251004086 | C37: 杭州 | D37: 2025/10/2 | E37: 客户 | F37: 客户 | G37: 人民币 | H37: 17300 | I37: 17187.53 | J37: 杭州中冠电器有限公司 | L37: 杭州中冠电器有限公司 | M37: 自营以旧换新特别账户 | N37: 销管部 | P37: 17300 | Q37: 罗清 | R37: 人民币 | S37: 固定汇率 | T37: 1 | U37: 17300 | V37: 17187.53 | X37: 空 | Z37: 销售业务 | AA37: 信用正常 | AB37: 转账 | AC37: 销售收款 | AE37: 1 | AG37: 3290 | AI37: 17300 | AJ37: 3290 | AK37: 21.39 | AM37: 3268.61 | AN37: 杭州中冠电器有限公司 | AO37: 否 | AP37: 中信银行杭州钱江支行 | AQ37: 手工新增 | AS37: 自营以旧换新特别账户 | AX37: 3290 | AY37: 否 | AZ37: 7331710182200026317 | BA37: 3290 | BB37: 2025年10月用户结算(换新5） | BC37: 否 | BE37: 空 | BG37: 21.39 | BH37: 3268.61 | BI37: 已审核 | BJ37: 毛银萍 | BK37: 桑玲 | BL37: 桑玲 | BM37: 2025/10/4 | BN37: 2025-10-07 09:47:48 | BO37: 2025-10-07 09:47:49 | BR37: 否 | BS37: 3290 | BW37: 杭州中冠电器有限公司 | BZ37: 人民币 | CA37: 否 | CB37: 2025/10/2 | CC37: 是 | CH37: 否 | CK37: 2025年10月2日中信银行收款【用户姓名:2025年10月结算(换新5-10）；用户手机: ；其他号码: 】 | CN37: 人民币 | CO37: 固定汇率 | CT37: 杭州-主城 | CW37: 否 | DD37: 未关闭 | DK37: 2025年10月结算(换新5-10） | DR37: 2025年10月结算(换新5-10）
AB38: 转账 | AC38: 销售收款 | AG38: 2976 | AJ38: 2976 | AK38: 19.35 | AM38: 2956.65 | AN38: 杭州中冠电器有限公司 | AP38: 中信银行杭州钱江支行 | AX38: 2976 | AZ38: 7331710182200026317 | BA38: 2976 | BB38: 2025年10月客户结算(换新6） | BC38: 否 | BE38: 空 | BG38: 19.35 | BH38: 2956.65 | BS38: 2976 | CB38: 2025/10/2 | CC38: 是 | DD38: 未关闭
AB39: 转账 | AC39: 销售收款 | AG39: 2976 | AJ39: 2976 | AK39: 19.35 | AM39: 2956.65 | AN39: 杭州中冠电器有限公司 | AP39: 中信银行杭州钱江支行 | AX39: 2976 | AZ39: 7331710182200026317 | BA39: 2976 | BB39: 2025年10月唐宇魁结算(换新7） | BC39: 否 | BE39: 空 | BG39: 19.35 | BH39: 2956.65 | BS39: 2976 | CB39: 2025/10/2 | CC39: 是 | DD39: 未关闭
AB40: 转账 | AC40: 销售收款 | AG40: 2686 | AJ40: 2686 | AK40: 17.46 | AM40: 2668.54 | AN40: 杭州中冠电器有限公司 | AP40: 中信银行杭州钱江支行 | AX40: 2686 | AZ40: 7331710182200026317 | BA40: 2686 | BB40: 2025年10月侯新波结算(换新8） | BC40: 否 | BE40: 空 | BG40: 17.46 | BH40: 2668.54 | BS40: 2686 | CB40: 2025/10/2 | CC40: 是 | DD40: 未关闭
...
