Workbook

Sheet 汇总1
A1: 公司 | B1: 地区 | C1: 25年任务 | D1: 1月 | F1: 同比 | G1: 2月 | I1: 同比 | J1: 3月 | L1: 同比 | M1: 1-3月 | O1: 同比 | P1: 4月 | R1: 同比 | S1: 1-4月 | U1: 同比 | V1: 5月 | X1: 同比 | Y1: 1-5月 | AA1: 同比 | AB1: 6月 | AD1: 同比 | AE1: 1-6月 | AG1: 同比 | AH1: 7月 | AJ1: 同比 | AK1: 8月 | AM1: 同比 | AN1: 9月 | AP1: 同比 | AQ1: Q3 | AS1: 同比 | AT1: 1-9月 | AV1: 同比 | AW1: 10月 | AY1: 同比 | AZ1: 1-10月 | BB1: 同比 | BC1: 完成率
D2: 2024年 | E2: 2025年 | G2: 2024年 | H2: 2025年 | J2: 2024年 | K2: 2025年 | M2: 2024年 | N2: 2025年 | P2: 2024年 | Q2: 2025年 | S2: 2024年 | T2: 2025年 | V2: 2024年 | W2: 2025年 | Y2: 2024年 | Z2: 2025年 | AB2: 2024年 | AC2: 2025年 | AE2: 2024年 | AF2: 2025年 | AH2: 2024年 | AI2: 2025年 | AK2: 2024年 | AL2: 2025年 | AN2: 2024年 | AO2: 2025年 | AQ2: 2024年 | AR2: 2025年 | AT2: 2024年 | AU2: 2025年 | AW2: 2024年 | AX2: 2025年 | AZ2: 2024年 | BA2: 2025年
A3: 中冠 | B3: 杭州 | C3: 43500000 | D3: 1820726.5 | E3: 2134133.9 | F3: =E3/D3-1 -> 0.17213319 | G3: 665632 | H3: 2030936 | I3: =H3/G3-1 -> 2.0511394 | J3: 2335229.5 | K3: 3216768.4 | L3: =K3/J3-1 -> 0.37749557 | M3: 4821588 | N3: 7381838.3 | O3: =N3/M3-1 -> 0.53099732 | P3: 2932936.8 | Q3: 3545274.2 | R3: =Q3/P3-1 -> 0.20877959 | S3: 7754524.9 | T3: 10927113 | U3: =T3/S3-1 -> 0.40912728 | V3: 2754128.3 | W3: 2967729.7 | X3: =W3/V3-1 -> 0.077556827 | Y3: 10508653 | Z3: 13954842 | AA3: =Z3/Y3-1 -> 0.32793823 | AB3: 3834503.5 | AC3: 3744101 | AD3: =AC3/AB3-1 -> -0.023576064 | AE3: 14343157 | AF3: 17698368 | AG3: =AF3/AE3-1 -> 0.23392421 | AH3: 2104345.2 | AI3: 2351069.8 | AJ3: =AI3/AH3-1 -> 0.11724528 | AK3: 1930214.4 | AL3: 1841887.6 | AM3: =AL3/AK3-1 -> -0.045760052 | AN3: 2928380.3 | AO3: 1665365.5 | AP3: =AO3/AN3-1 -> -0.43130149 | AQ3: =AH3+AK3+AN3 -> 6962939.9 | AR3: =AI3+AL3+AO3 -> 5858323 | AS3: =AR3/AQ3-1 -> -0.15864232 | AT3: 21306097 | AU3: 23556691 | AV3: =AU3/AT3-1 -> 0.10563149 | AW3: 4365273.7 | AX3: 2242104.6 | AY3: =AX3/AW3-1 -> -0.48637709 | AZ3: 25671370 | BA3: 25798796 | BB3: =BA3/AZ3-1 -> 0.0049637194 | BC3: =BA3/C3 -> 0.59307576
B4: 自营以旧换新 | E4: 646534 | F4: =E4/D4-1 -> #DIV/0! | H4: 486138 | I4: =H4/G4-1 -> #DIV/0! | K4: 376210 | L4: =K4/J4-1 -> #DIV/0! | N4: 1508882 | O4: =N4/M4-1 -> #DIV/0! | P4: 127164 | Q4: 332230 | R4: =Q4/P4-1 -> 1.6126105 | S4: 127164 | T4: 1841112 | U4: =T4/S4-1 -> 13.478249 | V4: 237373 | W4: 272632 | X4: =W4/V4-1 -> 0.14853838 | Y4: 364537 | Z4: 2113744 | AA4: =Z4/Y4-1 -> 4.7984347 | AB4: 205722 | AC4: 351814 | AD4: =AC4/AB4-1 -> 0.71014281 | AE4: 570259 | AF4: 2466133 | AG4: =AF4/AE4-1 -> 3.3245841 | AH4: 377153 | AI4: 310892 | AJ4: =AI4/AH4-1 -> -0.17568732 | AK4: 425201 | AL4: 351404 | AM4: =AL4/AK4-1 -> -0.17355792 | AN4: 574651.12 | AO4: 534045 | AP4: =AO4/AN4-1 -> -0.070662213 | AQ4: =AH4+AK4+AN4 -> 1377005.1 | AR4: =AI4+AL4+AO4 -> 1196341 | AS4: =AR4/AQ4-1 -> -0.13120076 | AT4: 1947264.1 | AU4: 3662474 | AV4: =AU4/AT4-1 -> 0.88083063 | AW4: 522761 | AX4: 532345 | AY4: =AX4/AW4-1 -> 0.018333426 | AZ4: 2470025.1 | BA4: 4194819 | BB4: =BA4/AZ4-1 -> 0.69829002 | BC4: =BA4/C4 -> #DIV/0!
B5: 金衢 | C5: 12000000 | D5: 1110866.7 | E5: 802311.19 | F5: =E5/D5-1 -> -0.27776106 | G5: 225264 | H5: 353390.48 | I5: =H5/G5-1 -> 0.56878365 | J5: 365888 | K5: 969353.65 | L5: =K5/J5-1 -> 1.649318 | M5: 1702018.7 | N5: 2125055.3 | O5: =N5/M5-1 -> 0.24854992 | P5: 648379.45 | Q5: 857787.1 | R5: =Q5/P5-1 -> 0.32297083 | S5: 2350398.2 | T5: 2982842.4 | U5: =T5/S5-1 -> 0.26907963 | V5: 639095.81 | W5: 661714.03 | X5: =W5/V5-1 -> 0.035390969 | Y5: 2989494 | Z5: 3644556.5 | AA5: =Z5/Y5-1 -> 0.21912153 | AB5: 677171.21 | AC5: 970845.98 | AD5: =AC5/AB5-1 -> 0.43367876 | AE5: 3666665.2 | AF5: 4615402.4 | AG5: =AF5/AE5-1 -> 0.25874663 | AH5: 658308.08 | AI5: 383538.42 | AJ5: =AI5/AH5-1 -> -0.41738765 | AK5: 452837.18 | AL5: 243092 | AM5: =AL5/AK5-1 -> -0.46318012 | AN5: 672163.76 | AO5: 347351.48 | AP5: =AO5/AN5-1 -> -0.48323385 | AQ5: =AH5+AK5+AN5 -> 1783309 | AR5: =AI5+AL5+AO5 -> 973981.9 | AS5: =AR5/AQ5-1 -> -0.45383448 | AT5: 5449974.2 | AU5: 5589384.3 | AV5: =AU5/AT5-1 -> 0.025579961 | AW5: 1095151 | AX5: 262859.9 | AY5: =AX5/AW5-1 -> -0.75997839 | AZ5: 6545125.2 | BA5: 5852244.2 | BB5: =BA5/AZ5-1 -> -0.10586214 | BC5: =BA5/C5 -> 0.48768702
B6: 湖州 | C6: 10000000 | D6: 578458.28 | E6: 474052 | F6: =E6/D6-1 -> -0.1804906 | G6: 382921 | H6: 390891.04 | I6: =H6/G6-1 -> 0.020813797 | J6: 427042.28 | K6: 414836.06 | L6: =K6/J6-1 -> -0.028583165 | M6: 1388421.6 | N6: 1279779.1 | O6: =N6/M6-1 -> -0.0782489 | P6: 399949 | Q6: 411808.08 | R6: =Q6/P6-1 -> 0.029651481 | S6: 1788370.6 | T6: 1691587.2 | U6: =T6/S6-1 -> -0.054118191 | V6: 597544 | W6: 404990 | X6: =W6/V6-1 -> -0.32224238 | Y6: 2385914.6 | Z6: 2096577.2 | AA6: =Z6/Y6-1 -> -0.12126896 | AB6: 442447 | AC6: 273945 | AD6: =AC6/AB6-1 -> -0.3808411 | AE6: 2828361.6 | AF6: 2370522.2 | AG6: =AF6/AE6-1 -> -0.16187442 | AH6: 267076.26 | AI6: 314396 | AJ6: =AI6/AH6-1 -> 0.17717689 | AK6: 297074.56 | AL6: 301382.6 | AM6: =AL6/AK6-1 -> 0.014501545 | AN6: 493686.14 | AO6: 220016 | AP6: =AO6/AN6-1 -> -0.55434033 | AQ6: =AH6+AK6+AN6 -> 1057837 | AR6: =AI6+AL6+AO6 -> 835794.6 | AS6: =AR6/AQ6-1 -> -0.20990225 | AT6: 3886198.5 | AU6: 3206316.8 | AV6: =AU6/AT6-1 -> -0.17494776 | AW6: 594994.64 | AX6: 196308 | AY6: =AX6/AW6-1 -> -0.67006762 | AZ6: 4481193.2 | BA6: 3402624.8 | BB6: =BA6/AZ6-1 -> -0.24068777 | BC6: =BA6/C6 -> 0.34026248
B7: 小计2 | C7: =SUM(C3:C6) -> 65500000 | D7: =SUM(D3:D6) -> 3510051.5 | E7: =SUM(E3:E6) -> 4057031.1 | F7: =E7/D7-1 -> 0.15583237 | G7: =SUM(G3:G6) -> 1273817 | H7: =SUM(H3:H6) -> 3261355.5 | I7: =H7/G7-1 -> 1.5603015 | J7: =SUM(J3:J6) -> 3128159.8 | K7: =SUM(K3:K6) -> 4977168.1 | L7: =K7/J7-1 -> 0.59108497 | M7: =SUM(M3:M6) -> 7912028.3 | N7: =SUM(N3:N6) -> 12295555 | O7: =N7/M7-1 -> 0.55403321 | P7: =SUM(P3:P6) -> 4108429.3 | Q7: =SUM(Q3:Q6) -> 5147099.4 | R7: =Q7/P7-1 -> 0.2528144 | S7: =SUM(S3:S6) -> 12020458 | T7: =SUM(T3:T6) -> 17442654 | U7: =T7/S7-1 -> 0.45108071 | V7: =SUM(V3:V6) -> 4228141.1 | W7: =SUM(W3:W6) -> 4307065.8 | X7: =W7/V7-1 -> 0.018666518 | Y7: =SUM(Y3:Y6) -> 16248599 | Z7: =SUM(Z3:Z6) -> 21809720 | AA7: =Z7/Y7-1 -> 0.34225236 | AB7: =SUM(AB3:AB6) -> 5159843.7 | AC7: =SUM(AC3:AC6) -> 5340706 | AD7: =AC7/AB7-1 -> 0.035051889 | AE7: =SUM(AE3:AE6) -> 21408442 | AF7: =SUM(AF3:AF6) -> 27150426 | AG7: =AF7/AE7-1 -> 0.26821117 | AH7: =SUM(AH3:AH6) -> 3406882.6 | AI7: =SUM(AI3:AI6) -> 3359896.2 | AJ7: =AI7/AH7-1 -> -0.013791605 | AK7: =SUM(AK3:AK6) -> 3105327.1 | AL7: =SUM(AL3:AL6) -> 2737766.2 | AM7: =AL7/AK7-1 -> -0.11836462 | AN7: =SUM(AN3:AN6) -> 4668881.4 | AO7: =SUM(AO3:AO6) -> 2766778 | AP7: =AO7/AN7-1 -> -0.40740023 | AQ7: =SUM(AQ3:AQ6) -> 11181091 | AR7: =SUM(AR3:AR6) -> 8864440.5 | AS7: =AR7/AQ7-1 -> -0.20719361 | AT7: =SUM(AT3:AT6) -> 32589533 | AU7: =SUM(AU3:AU6) -> 36014866 | AV7: =AU7/AT7-1 -> 0.10510531 | AW7: =SUM(AW3:AW6) -> 6578180.3 | AX7: =SUM(AX3:AX6) -> 3233617.5 | AY7: =AX7/AW7-1 -> -0.50843283 | AZ7: =SUM(AZ3:AZ6) -> 39167714 | BA7: =SUM(BA3:BA6) -> 39248484 | BB7: =BA7/AZ7-1 -> 0.0020621587 | BC7: =BA7/C7 -> 0.59921349
B8: 嘉兴 | C8: 18000000 | D8: 757967.7 | E8: 1042811.5 | F8: =E8/D8-1 -> 0.37579939 | G8: 650701 | H8: 654682.86 | I8: =H8/G8-1 -> 0.006119339 | J8: 834107.08 | K8: 1262815.5 | L8: =K8/J8-1 -> 0.51397288 | M8: 2242775.8 | N8: 2979548.1 | O8: =N8/M8-1 -> 0.32850913 | P8: 1174295.4 | Q8: 591900.56 | R8: =Q8/P8-1 -> -0.49595259 | S8: 3417071.2 | T8: 3571448.7 | U8: =T8/S8-1 -> 0.045178304 | V8: 841508.5 | W8: 1004931.7 | X8: =W8/V8-1 -> 0.19420261 | Y8: 4258579.7 | Z8: 4576380.3 | AA8: =Z8/Y8-1 -> 0.074625968 | AB8: 1079235.6 | AC8: 1526485.7 | AD8: =AC8/AB8-1 -> 0.4144138 | AE8: 5337815.3 | AF8: 6102866 | AG8: =AF8/AE8-1 -> 0.14332657 | AH8: 767814 | AI8: 1057783 | AJ8: =AI8/AH8-1 -> 0.37765525 | AK8: 611076.9 | AL8: 976642.51 | AM8: =AL8/AK8-1 -> 0.59823176 | AN8: 1467492.1 | AO8: 781228.93 | AP8: =AO8/AN8-1 -> -0.46764352 | AQ8: =AH8+AK8+AN8 -> 2846383 | AR8: =AI8+AL8+AO8 -> 2815654.4 | AS8: =AR8/AQ8-1 -> -0.010795652 | AT8: 8184198.3 | AU8: 8919205.4 | AV8: =AU8/AT8-1 -> 0.089808076 | AW8: 2289433.9 | AX8: 911115.36 | AY8: =AX8/AW8-1 -> -0.60203465 | AZ8: 10473632 | BA8: 9830320.7 | BB8: =BA8/AZ8-1 -> -0.061422 | BC8: =BA8/C8 -> 0.54612893
B9: 台州 | C9: 13000000 | D9: 987273 | E9: 979673.76 | F9: =E9/D9-1 -> -0.0076972023 | G9: 496989.73 | H9: 426348.02 | I9: =H9/G9-1 -> -0.14213917 | J9: 704817.31 | K9: 895972.45 | L9: =K9/J9-1 -> 0.27121232 | M9: 2189080 | N9: 2301994.2 | O9: =N9/M9-1 -> 0.051580659 | P9: 634914 | Q9: 940883.01 | R9: =Q9/P9-1 -> 0.48190623 | S9: 2823994 | T9: 3242877.2 | U9: =T9/S9-1 -> 0.14833006 | V9: 730473.41 | W9: 967383.15 | X9: =W9/V9-1 -> 0.32432356 | Y9: 3554467.5 | Z9: 4210260.4 | AA9: =Z9/Y9-1 -> 0.18449823 | AB9: 396701.38 | AC9: 995385.52 | AD9: =AC9/AB9-1 -> 1.5091557 | AE9: 3951168.8 | AF9: 5205645.9 | AG9: =AF9/AE9-1 -> 0.31749519 | AH9: 528805.98 | AI9: 665570.61 | AJ9: =AI9/AH9-1 -> 0.25862913 | AK9: 747759.2 | AL9: 600199.76 | AM9: =AL9/AK9-1 -> -0.19733551 | AN9: 1304515.8 | AO9: 463720.7 | AP9: =AO9/AN9-1 -> -0.64452656 | AQ9: =AH9+AK9+AN9 -> 2581080.9 | AR9: =AI9+AL9+AO9 -> 1729491.1 | AS9: =AR9/AQ9-1 -> -0.32993536 | AT9: 6532249.8 | AU9: 6935137 | AV9: =AU9/AT9-1 -> 0.061676639 | AW9: 768318.57 | AX9: 666246.78 | AY9: =AX9/AW9-1 -> -0.13285087 | AZ9: 7300568.3 | BA9: 7601383.8 | BB9: =BA9/AZ9-1 -> 0.041204384 | BC9: =BA9/C9 -> 0.58472183
B10: 合计 | C10: =SUM(C7:C9) -> 96500000 | D10: =SUM(D7:D9) -> 5255292.2 | E10: =SUM(E7:E9) -> 6079516.4 | F10: =E10/D10-1 -> 0.15683699 | G10: =SUM(G7:G9) -> 2421507.7 | H10: =SUM(H7:H9) -> 4342386.4 | I10: =H10/G10-1 -> 0.79325731 | J10: =SUM(J7:J9) -> 4667084.2 | K10: =SUM(K7:K9) -> 7135956 | L10: =K10/J10-1 -> 0.52899663 | M10: =SUM(M7:M9) -> 12343884 | N10: =SUM(N7:N9) -> 17577097 | O10: =N10/M10-1 -> 0.42395189 | P10: =SUM(P7:P9) -> 5917638.7 | Q10: =SUM(Q7:Q9) -> 6679882.9 | R10: =Q10/P10-1 -> 0.12880885 | S10: =SUM(S7:S9) -> 18261523 | T10: =SUM(T7:T9) -> 24256980 | U10: =T10/S10-1 -> 0.32831091 | V10: =SUM(V7:V9) -> 5800123 | W10: =SUM(W7:W9) -> 6279380.5 | X10: =W10/V10-1 -> 0.082628862 | Y10: =SUM(Y7:Y9) -> 24061646 | Z10: =SUM(Z7:Z9) -> 30596361 | AA10: =Z10/Y10-1 -> 0.2715822 | AB10: =SUM(AB7:AB9) -> 6635780.7 | AC10: =SUM(AC7:AC9) -> 7862577.2 | AD10: =AC10/AB10-1 -> 0.18487599 | AE10: =SUM(AE7:AE9) -> 30697426 | AF10: =SUM(AF7:AF9) -> 38458938 | AG10: =AF10/AE10-1 -> 0.25283915 | AH10: =SUM(AH7:AH9) -> 4703502.6 | AI10: =SUM(AI7:AI9) -> 5083249.8 | AJ10: =AI10/AH10-1 -> 0.080737118 | AK10: =SUM(AK7:AK9) -> 4464163.2 | AL10: =SUM(AL7:AL9) -> 4314608.5 | AM10: =AL10/AK10-1 -> -0.033501168 | AN10: =SUM(AN7:AN9) -> 7440889.2 | AO10: =SUM(AO7:AO9) -> 4011727.6 | AP10: =AO10/AN10-1 -> -0.46085373 | AQ10: =SUM(AQ7:AQ9) -> 16608555 | AR10: =SUM(AR7:AR9) -> 13409586 | AS10: =AR10/AQ10-1 -> -0.19260971 | AT10: =SUM(AT7:AT9) -> 47305981 | AU10: =SUM(AU7:AU9) -> 51869209 | AV10: =AU10/AT10-1 -> 0.09646195 | AW10: =SUM(AW7:AW9) -> 9635932.8 | AX10: =SUM(AX7:AX9) -> 4810979.6 | AY10: =AX10/AW10-1 -> -0.50072507 | AZ10: =SUM(AZ7:AZ9) -> 56941914 | BA10: =SUM(BA7:BA9) -> 56680188 | BB10: =BA10/AZ10-1 -> -0.0045963676 | BC10: =BA10/C10 -> 0.58735946
A11: 晨涛 | B11: 绍兴 | C11: 26000000 | D11: 1971859.5 | E11: 1683228.3 | F11: =E11/D11-1 -> -0.14637513 | G11: 862585.12 | H11: 832659.54 | I11: =H11/G11-1 -> -0.034692901 | J11: 1454016 | K11: 2188918.4 | L11: =K11/J11-1 -> 0.50542937 | M11: 4288460.6 | N11: 4704806.2 | O11: =N11/M11-1 -> 0.097085103 | P11: 1189993.8 | Q11: 1508708.2 | R11: =Q11/P11-1 -> 0.2678287 | S11: 5478454.4 | T11: 6213514.5 | U11: =T11/S11-1 -> 0.1341729 | V11: 1649605.2 | W11: 1736224.2 | X11: =W11/V11-1 -> 0.052508915 | Y11: 7128059.6 | Z11: 7949738.7 | AA11: =Z11/Y11-1 -> 0.11527388 | AB11: 1202502.8 | AC11: 2136560.1 | AD11: =AC11/AB11-1 -> 0.77676095 | AE11: 8330562.4 | AF11: 10086299 | AG11: =AF11/AE11-1 -> 0.21075844 | AH11: 1775233.9 | AI11: 1520600.2 | AJ11: =AI11/AH11-1 -> -0.14343667 | AK11: 1110802.6 | AL11: 748570.86 | AM11: =AL11/AK11-1 -> -0.32609911 | AN11: 2053571 | AO11: 1180401.6 | AP11: =AO11/AN11-1 -> -0.4251956 | AQ11: =AH11+AK11+AN11 -> 4939607.5 | AR11: =AI11+AL11+AO11 -> 3449572.8 | AS11: =AR11/AQ11-1 -> -0.30165043 | AT11: 13270170 | AU11: 13535872 | AV11: =AU11/AT11-1 -> 0.020022473 | AW11: 2117929.2 | AX11: 1637345.4 | AY11: =AX11/AW11-1 -> -0.22691214 | AZ11: 15388099 | BA11: 15173217 | BB11: =BA11/AZ11-1 -> -0.013964184 | BC11: =BA11/C11 -> 0.58358526
A12: 吉远 | B12: 温丽 | C12: 15700000 | D12: 1223845.6 | E12: 595578.3 | F12: =E12/D12-1 -> -0.51335503 | G12: 355310.4 | H12: 470333.56 | I12: =H12/G12-1 -> 0.32372585 | J12: 756633.2 | K12: 1014927.8 | L12: =K12/J12-1 -> 0.34137357 | M12: 2335789.2 | N12: 2080839.6 | O12: =N12/M12-1 -> -0.10914922 | P12: 683687.2 | Q12: 937105.26 | R12: =Q12/P12-1 -> 0.37066375 | S12: 3019476.4 | T12: 3017944.9 | U12: =T12/S12-1 -> -0.00050720714 | V12: 541949.88 | W12: 706896 | X12: =W12/V12-1 -> 0.30435678 | Y12: 3561426.3 | Z12: 3724840.9 | AA12: =Z12/Y12-1 -> 0.0458846 | AB12: 565078.8 | AC12: 1078704.9 | AD12: =AC12/AB12-1 -> 0.90894594 | AE12: 4126505.1 | AF12: 4801339.8 | AG12: =AF12/AE12-1 -> 0.16353662 | AH12: 611348.06 | AI12: 1116779.7 | AJ12: =AI12/AH12-1 -> 0.82674933 | AK12: 565935 | AL12: 529250 | AM12: =AL12/AK12-1 -> -0.064821932 | AN12: 1201478.6 | AO12: 574943.16 | AP12: =AO12/AN12-1 -> -0.52147034 | AQ12: =AH12+AK12+AN12 -> 2378761.7 | AR12: =AI12+AL12+AO12 -> 2220972.8 | AS12: =AR12/AQ12-1 -> -0.066332361 | AT12: 6505266.8 | AU12: 7023603.6 | AV12: =AU12/AT12-1 -> 0.079679564 | AW12: 2091707.1 | AX12: 407028.36 | AY12: =AX12/AW12-1 -> -0.80540853 | AZ12: 8596973.8 | BA12: 7430632 | BB12: =BA12/AZ12-1 -> -0.13566889 | BC12: =BA12/C12 -> 0.47328866
A13: 汇总 | C13: =SUM(C10:C12) -> 138200000 | D13: =SUM(D10:D12) -> 8450997.2 | E13: =SUM(E10:E12) -> 8358323 | F13: =E13/D13-1 -> -0.010966075 | G13: =SUM(G10:G12) -> 3639403.2 | H13: =SUM(H10:H12) -> 5645379.5 | I13: =H13/G13-1 -> 0.55118275 | J13: =SUM(J10:J12) -> 6877733.4 | K13: =SUM(K10:K12) -> 10339802 | L13: =K13/J13-1 -> 0.50337351 | M13: =SUM(M10:M12) -> 18968134 | N13: =SUM(N10:N12) -> 24362743 | O13: =N13/M13-1 -> 0.28440378 | P13: =SUM(P10:P12) -> 7791319.7 | Q13: =SUM(Q10:Q12) -> 9125696.4 | R13: =Q13/P13-1 -> 0.17126454 | S13: =SUM(S10:S12) -> 26759454 | T13: =SUM(T10:T12) -> 33488439 | U13: =T13/S13-1 -> 0.251462 | V13: =SUM(V10:V12) -> 7991678.1 | W13: =SUM(W10:W12) -> 8722500.7 | X13: =W13/V13-1 -> 0.09144796 | Y13: =SUM(Y10:Y12) -> 34751132 | Z13: =SUM(Z10:Z12) -> 42270940 | AA13: =Z13/Y13-1 -> 0.21639032 | AB13: =SUM(AB10:AB12) -> 8403362.3 | AC13: =SUM(AC10:AC12) -> 11077842 | AD13: =AC13/AB13-1 -> 0.31826307 | AE13: =SUM(AE10:AE12) -> 43154494 | AF13: =SUM(AF10:AF12) -> 53346576 | AG13: =AF13/AE13-1 -> 0.23617662 | AH13: =SUM(AH10:AH12) -> 7090084.5 | AI13: =SUM(AI10:AI12) -> 7720629.7 | AJ13: =AI13/AH13-1 -> 0.088933384 | AK13: =SUM(AK10:AK12) -> 6140900.8 | AL13: =SUM(AL10:AL12) -> 5592429.4 | AM13: =AL13/AK13-1 -> -0.089314489 | AN13: =SUM(AN10:AN12) -> 10695939 | AO13: =SUM(AO10:AO12) -> 5767072.5 | AP13: =AO13/AN13-1 -> -0.46081662 | AQ13: =SUM(AQ10:AQ12) -> 23926924 | AR13: =SUM(AR10:AR12) -> 19080132 | AS13: =AR13/AQ13-1 -> -0.20256647 | AT13: =SUM(AT10:AT12) -> 67081418 | AU13: =SUM(AU10:AU12) -> 72428684 | AV13: =AU13/AT13-1 -> 0.079713068 | AW13: =SUM(AW10:AW12) -> 13845569 | AX13: =SUM(AX10:AX12) -> 6855353.4 | AY13: =AX13/AW13-1 -> -0.50487024 | AZ13: =SUM(AZ10:AZ12) -> 80926987 | BA13: =SUM(BA10:BA12) -> 79284037 | BB13: =BA13/AZ13-1 -> -0.020301634 | BC13: =BA13/C13 -> 0.57369057
B16: 电商 | D16: 159223.48 | E16: 10985.2 | F16: =E16/D16-1 -> -0.93100766 | G16: 17619.22 | H16: 3564.8 | I16: =H16/G16-1 -> -0.79767549 | J16: 15307.5 | K16: 165.6 | L16: =K16/J16-1 -> -0.98918177 | M16: 192150.2 | N16: 14715.6 | O16: =N16/M16-1 -> -0.92341616 | P16: 15307.5 | Q16: 165.6 | R16: =Q16/P16-1 -> -0.98918177 | S16: 192150.2 | T16: 14715.6 | U16: =T16/S16-1 -> -0.92341616 | V16: 7356.6 | X16: =W16/V16-1 -> -1 | Y16: 226296.48 | Z16: 14715.6 | AA16: =Z16/Y16-1 -> -0.93497203 | AB16: 10109.2 | AC16: 6590.6 | AD16: =AC16/AB16-1 -> -0.34805919 | AE16: 236405.68 | AF16: 21306.2 | AG16: =AF16/AE16-1 -> -0.90987442 | AH16: 30218.12 | AI16: 10907.2 | AJ16: =AI16/AH16-1 -> -0.63905101 | AK16: 18456 | AL16: 4860.8 | AM16: =AL16/AK16-1 -> -0.73662765 | AN16: 32843.62 | AO16: 6872.6 | AP16: =AO16/AN16-1 -> -0.79074779 | AT16: 317923.42 | AU16: 43946.8 | AV16: =AU16/AT16-1 -> -0.86176923 | AW16: 6011.6 | AX16: 9287 | AY16: =AX16/AW16-1 -> 0.54484663 | AZ16: 323935.02 | BA16: 53233.8 | BB16: =BA16/AZ16-1 -> -0.83566519

Sheet 杭州
I1: 合同任务 | J1: 1月 | L1: 同比 | M1: 2月 | O1: 同比 | P1: 1-2月 | R1: 同比 | S1: 3月 | U1: 同比 | V1: 1-3月 | X1: 同比 | Y1: 4月 | AA1: 同比 | AB1: 1-4月 | AD1: 同比 | AE1: 5月 | AG1: 同比 | AH1: 1-5月 | AJ1: 同比 | AK1: 6月 | AM1: 同比 | AN1: 1-6月 | AP1: 同比 | AQ1: 7月 | AS1: 同比 | AT1: 1-7月 | AV1: 同比 | AW1: 8月 | AY1: 同比 | AZ1: 1-8月 | BB1: 同比 | BC1: 9月 | BE1: 同比 | BF1: 1-9月 | BH1: 同比 | BI1: 10月 | BK1: 同比 | BL1: 1-10月 | BN1: 同比 | BO1: 11月 | BP1: 12月 | BQ1: 全年 | BR1: 完成率
A2: 大地区 | B2: 序号 | C2: 门店 | D2: 渠道 | E2: 渠道细分 | F2: 大区 | G2: 市/区/县 | H2: 业务员 | J2: 2024年 | K2: 2025年 | M2: 2024年 | N2: 2025年 | P2: 2024年 | Q2: 2025年 | S2: 2024年 | T2: 2025年 | V2: 2024年 | W2: 2025年 | Y2: 2024年 | Z2: 2025年 | AB2: 2024年 | AC2: 2025年 | AE2: 2024年 | AF2: 2025年 | AH2: 2024年 | AI2: 2025年 | AK2: 2024年 | AL2: 2025年 | AN2: 2024年 | AO2: 2025年 | AQ2: 2024年 | AR2: 2025年 | AT2: 2024年 | AU2: 2025年 | AW2: 2024年 | AX2: 2025年 | AZ2: 2024年 | BA2: 2025年 | BC2: 2024年 | BD2: 2025年 | BF2: 2024年 | BG2: 2025年 | BI2: 2024年 | BJ2: 2025年 | BL2: 2024年 | BM2: 2025年 | BO2: 2024年 | BP2: 2024年 | BQ2: 2024年 | BS2: 24年场地费 | BT2: 25年场地费 | BU2: 25年特殊
A3: 杭州 | B3: 杭州 | C3: 汇德隆 | D3: TOP渠道 | E3: TOP渠道 | F3: 萧山区 | G3: 萧山区 | H3: 董培培 | I3: 800 | J3: 100000 | K3: 180000 | L3: =K3/J3-1 -> 0.8 | N3: 90000 | O3: =N3/M3-1 -> #DIV/0! | P3: =J3+M3 -> 100000 | Q3: =K3+N3 -> 270000 | R3: =Q3/P3-1 -> 1.7 | S3: 540000 | T3: 200000 | U3: =T3/S3-1 -> -0.62962963 | V3: =S3+P3 -> 640000 | W3: =T3+Q3 -> 470000 | X3: =W3/V3-1 -> -0.265625 | Y3: 550000 | Z3: =620000+30000+42800 -> 692800 | AA3: =Z3/Y3-1 -> 0.25963636 | AB3: =Y3+V3 -> 1190000 | AC3: =Z3+W3 -> 1162800 | AD3: =AC3/AB3-1 -> -0.022857143 | AE3: 513000 | AF3: 480000 | AG3: =AF3/AE3-1 -> -0.064327485 | AH3: =AE3+AB3 -> 1703000 | AI3: =AF3+AC3 -> 1642800 | AJ3: =AI3/AH3-1 -> -0.035349383 | AK3: 350000 | AL3: 180000 | AM3: =AL3/AK3-1 -> -0.48571429 | AN3: =AK3+AH3 -> 2053000 | AO3: =AL3+AI3 -> 1822800 | AP3: =AO3/AN3-1 -> -0.11212859 | AQ3: 200000 | AR3: 420000 | AS3: =AR3/AQ3-1 -> 1.1 | AT3: =AQ3+AN3 -> 2253000 | AU3: =AR3+AO3 -> 2242800 | AV3: =AU3/AT3-1 -> -0.0045272969 | AW3: 190000 | AX3: 310000 | AY3: =AX3/AW3-1 -> 0.63157895 | AZ3: =AW3+AT3 -> 2443000 | BA3: =AX3+AU3 -> 2552800 | BB3: =BA3/AZ3-1 -> 0.04494474 | BC3: 730000 | BD3: 250000 | BE3: =BD3/BC3-1 -> -0.65753425 | BF3: =BC3+AZ3 -> 3173000 | BG3: =BD3+BA3 -> 2802800 | BH3: =BG3/BF3-1 -> -0.11667192 | BI3: 840000 | BJ3: 300000 | BK3: =BJ3/BI3-1 -> -0.64285714 | BL3: =BI3+BF3 -> 4013000 | BM3: =BJ3+BG3 -> 3102800 | BN3: =BM3/BL3-1 -> -0.22681286 | BO3: 180000 | BP3: 260000 | BQ3: 4453000 | BR3: =(BM3+BM4)/10000/I3 -> 0.55794035 | BS3: 83000 | BT3: =30000+42800 -> 72800
A4: 杭州 | B4: 杭州 | C4: 萧山汇德隆净水 | D4: TOP渠道 | E4: TOP渠道 | F4: 萧山区 | G4: 萧山区 | H4: 董培培 | J4: 109082.35 | K4: 85017.95 | L4: =K4/J4-1 -> -0.22060764 | N4: 124698.5 | O4: =N4/M4-1 -> #DIV/0! | P4: =J4+M4 -> 109082.35 | Q4: =K4+N4 -> 209716.45 | R4: =Q4/P4-1 -> 0.92255163 | S4: 98942.87 | U4: =T4/S4-1 -> -1 | V4: =S4+P4 -> 208025.22 | W4: =T4+Q4 -> 209716.45 | X4: =W4/V4-1 -> 0.0081299277 | Y4: 96183.1 | Z4: 277266.5 | AA4: =Z4/Y4-1 -> 1.8826946 | AB4: =Y4+V4 -> 304208.32 | AC4: =Z4+W4 -> 486982.95 | AD4: =AC4/AB4-1 -> 0.60082062 | AE4: 108234.5 | AF4: 108269.25 | AG4: =AF4/AE4-1 -> 0.00032106214 | AH4: =AE4+AB4 -> 412442.82 | AI4: =AF4+AC4 -> 595252.2 | AJ4: =AI4/AH4-1 -> 0.4432357 | AK4: 329415.3 | AL4: 173565 | AM4: =AL4/AK4-1 -> -0.4731119 | AN4: =AK4+AH4 -> 741858.12 | AO4: =AL4+AI4 -> 768817.2 | AP4: =AO4/AN4-1 -> 0.036339941 | AQ4: 83070 | AR4: 256417.7 | AS4: =AR4/AQ4-1 -> 2.0867666 | AT4: =AQ4+AN4 -> 824928.12 | AU4: =AR4+AO4 -> 1025234.9 | AV4: =AU4/AT4-1 -> 0.24281725 | AW4: 170557.8 | AX4: 110759 | AY4: =AX4/AW4-1 -> -0.35060724 | AZ4: =AW4+AT4 -> 995485.92 | BA4: =AX4+AU4 -> 1135993.9 | BB4: =BA4/AZ4-1 -> 0.14114512 | BC4: 58082.8 | BE4: =BD4/BC4-1 -> -1 | BF4: =BC4+AZ4 -> 1053568.7 | BG4: =BD4+BA4 -> 1135993.9 | BH4: =BG4/BF4-1 -> 0.07823427 | BJ4: 224728.9 | BK4: =BJ4/BI4-1 -> #DIV/0! | BL4: =BI4+BF4 -> 1053568.7 | BM4: =BJ4+BG4 -> 1360722.8 | BN4: =BM4/BL4-1 -> 0.29153683 | BO4: 407846.4 | BP4: 134778.1 | BQ4: 1596193.2
A5: 杭州 | B5: 杭州 | C5: 杭州兴达京昀电器有限公司 | D5: 经销 | E5: TOP渠道 | F5: 临平区 | G5: 临平区 | H5: 吴海林 | I5: 130 | K5: 100000 | L5: =K5/J5-1 -> #DIV/0! | O5: =N5/M5-1 -> #DIV/0! | P5: =J5+M5 -> 0 | Q5: =K5+N5 -> 100000 | R5: =Q5/P5-1 -> #DIV/0! | T5: 60000 | U5: =T5/S5-1 -> #DIV/0! | V5: =S5+P5 -> 0 | W5: =T5+Q5 -> 160000 | X5: =W5/V5-1 -> #DIV/0! | Y5: 100000 | Z5: 50000 | AA5: =Z5/Y5-1 -> -0.5 | AB5: =Y5+V5 -> 100000 | AC5: =Z5+W5 -> 210000 | AD5: =AC5/AB5-1 -> 1.1 | AE5: 100000 | AF5: 60000 | AG5: =AF5/AE5-1 -> -0.4 | AH5: =AE5+AB5 -> 200000 | AI5: =AF5+AC5 -> 270000 | AJ5: =AI5/AH5-1 -> 0.35 | AK5: 100000 | AL5: 120000 | AM5: =AL5/AK5-1 -> 0.2 | AN5: =AK5+AH5 -> 300000 | AO5: =AL5+AI5 -> 390000 | AP5: =AO5/AN5-1 -> 0.3 | AQ5: 100000 | AR5: 100000 | AS5: =AR5/AQ5-1 -> 0 | AT5: =AQ5+AN5 -> 400000 | AU5: =AR5+AO5 -> 490000 | AV5: =AU5/AT5-1 -> 0.225 | AW5: 100000 | AX5: 50000 | AY5: =AX5/AW5-1 -> -0.5 | AZ5: =AW5+AT5 -> 500000 | BA5: =AX5+AU5 -> 540000 | BB5: =BA5/AZ5-1 -> 0.08 | BC5: 100000 | BD5: 100000 | BE5: =BD5/BC5-1 -> 0 | BF5: =BC5+AZ5 -> 600000 | BG5: =BD5+BA5 -> 640000 | BH5: =BG5/BF5-1 -> 0.066666667 | BI5: 100000 | BJ5: 100000 | BK5: =BJ5/BI5-1 -> 0 | BL5: =BI5+BF5 -> 700000 | BM5: =BJ5+BG5 -> 740000 | BN5: =BM5/BL5-1 -> 0.057142857 | BO5: 200000 | BP5: 100000 | BQ5: 1000000 | BR5: =BM5/10000/I5 -> 0.56923077
A6: 杭州 | B6: 杭州 | C6: 杭州临安一栋电器有限公司 | D6: 加盟 | E6: 加盟 | F6: 临安区 | G6: 临安区 | H6: 吴海林 | I6: 190 | J6: 140000 | K6: 41700 | L6: =K6/J6-1 -> -0.70214286 | M6: 60000 | N6: =20000+7875 -> 27875 | O6: =N6/M6-1 -> -0.53541667 | P6: =J6+M6 -> 200000 | Q6: =K6+N6 -> 69575 | R6: =Q6/P6-1 -> -0.652125 | S6: 60000 | T6: =55000+39786 -> 94786 | U6: =T6/S6-1 -> 0.57976667 | V6: =S6+P6 -> 260000 | W6: =T6+Q6 -> 164361 | X6: =W6/V6-1 -> -0.36784231 | Y6: 270219 | Z6: 67000 | AA6: =Z6/Y6-1 -> -0.75205296 | AB6: =Y6+V6 -> 530219 | AC6: =Z6+W6 -> 231361 | AD6: =AC6/AB6-1 -> -0.56365011 | AE6: 61019 | AG6: =AF6/AE6-1 -> -1 | AH6: =AE6+AB6 -> 591238 | AI6: =AF6+AC6 -> 231361 | AJ6: =AI6/AH6-1 -> -0.60868381 | AK6: 501898 | AL6: 30253.74 | AM6: =AL6/AK6-1 -> -0.93972134 | AN6: =AK6+AH6 -> 1093136 | AO6: =AL6+AI6 -> 261614.74 | AP6: =AO6/AN6-1 -> -0.76067503 | AR6: 40000 | AS6: =AR6/AQ6-1 -> #DIV/0! | AT6: =AQ6+AN6 -> 1093136 | AU6: =AR6+AO6 -> 301614.74 | AV6: =AU6/AT6-1 -> -0.72408306 | AX6: 70000 | AY6: =AX6/AW6-1 -> #DIV/0! | AZ6: =AW6+AT6 -> 1093136 | BA6: =AX6+AU6 -> 371614.74 | BB6: =BA6/AZ6-1 -> -0.66004711 | BC6: 43506 | BD6: 30000 | BE6: =BD6/BC6-1 -> -0.31043994 | BF6: =BC6+AZ6 -> 1136642 | BG6: =BD6+BA6 -> 401614.74 | BH6: =BG6/BF6-1 -> -0.64666558 | BI6: 89609 | BJ6: 40000 | BK6: =BJ6/BI6-1 -> -0.55361627 | BL6: =BI6+BF6 -> 1226251 | BM6: =BJ6+BG6 -> 441614.74 | BN6: =BM6/BL6-1 -> -0.63986595 | BO6: 10000 | BP6: 175000 | BQ6: 1411251 | BR6: =BM6/10000/I6 -> 0.23242881 | BS6: 61019
A7: 杭州 | B7: 杭州 | C7: 杭州宏信机电有限公司 | D7: 加盟 | E7: 加盟 | F7: 富阳区 | G7: 富阳区 | H7: 吴海林 | I7: 270 | J7: 215180.88 | K7: 10000 | L7: =K7/J7-1 -> -0.95352747 | M7: 146500 | N7: 83000 | O7: =N7/M7-1 -> -0.4334471 | P7: =J7+M7 -> 361680.88 | Q7: =K7+N7 -> 93000 | R7: =Q7/P7-1 -> -0.74286725 | S7: 280836 | T7: 71000 | U7: =T7/S7-1 -> -0.74718341 | V7: =S7+P7 -> 642516.88 | W7: =T7+Q7 -> 164000 | X7: =W7/V7-1 -> -0.74475379 | Y7: 201000 | Z7: 140000 | AA7: =Z7/Y7-1 -> -0.30348259 | AB7: =Y7+V7 -> 843516.88 | AC7: =Z7+W7 -> 304000 | AD7: =AC7/AB7-1 -> -0.63960413 | AE7: 182933 | AF7: 70000 | AG7: =AF7/AE7-1 -> -0.61734624 | AH7: =AE7+AB7 -> 1026449.9 | AI7: =AF7+AC7 -> 374000 | AJ7: =AI7/AH7-1 -> -0.63563735 | AK7: 205000 | AL7: 65840 | AM7: =AL7/AK7-1 -> -0.67882927 | AN7: =AK7+AH7 -> 1231449.9 | AO7: =AL7+AI7 -> 439840 | AP7: =AO7/AN7-1 -> -0.64282753 | AQ7: 157000 | AR7: 39000 | AS7: =AR7/AQ7-1 -> -0.75159236 | AT7: =AQ7+AN7 -> 1388449.9 | AU7: =AR7+AO7 -> 478840 | AV7: =AU7/AT7-1 -> -0.65512619 | AW7: 106000 | AX7: 95500 | AY7: =AX7/AW7-1 -> -0.099056604 | AZ7: =AW7+AT7 -> 1494449.9 | BA7: =AX7+AU7 -> 574340 | BB7: =BA7/AZ7-1 -> -0.61568467 | BC7: 142000 | BD7: 19000 | BE7: =BD7/BC7-1 -> -0.86619718 | BF7: =BC7+AZ7 -> 1636449.9 | BG7: =BD7+BA7 -> 593340 | BH7: =BG7/BF7-1 -> -0.63742244 | BI7: 219169 | BJ7: 34000 | BK7: =BJ7/BI7-1 -> -0.84486857 | BL7: =BI7+BF7 -> 1855618.9 | BM7: =BJ7+BG7 -> 627340 | BN7: =BM7/BL7-1 -> -0.66192411 | BO7: 239000 | BP7: 343500 | BQ7: 2438118.9 | BR7: =BM7/10000/I7 -> 0.23234815 | BS7: 106933
A8: 杭州 | B8: 杭州 | C8: 桐庐佳尼特水处理设备有限公司 | D8: 加盟 | E8: 加盟 | F8: 桐庐县 | G8: 桐庐县 | H8: 吴海林 | I8: 190 | J8: 100000 | K8: 149040 | L8: =K8/J8-1 -> 0.4904 | M8: 30000 | N8: 72140 | O8: =N8/M8-1 -> 1.4046667 | P8: =J8+M8 -> 130000 | Q8: =K8+N8 -> 221180 | R8: =Q8/P8-1 -> 0.70138462 | S8: 70000 | T8: 160000 | U8: =T8/S8-1 -> 1.2857143 | V8: =S8+P8 -> 200000 | W8: =T8+Q8 -> 381180 | X8: =W8/V8-1 -> 0.9059 | Y8: 90000 | Z8: 100000 | AA8: =Z8/Y8-1 -> 0.11111111 | AB8: =Y8+V8 -> 290000 | AC8: =Z8+W8 -> 481180 | AD8: =AC8/AB8-1 -> 0.65924138 | AE8: 65253 | AF8: 90000 | AG8: =AF8/AE8-1 -> 0.37924693 | AH8: =AE8+AB8 -> 355253 | AI8: =AF8+AC8 -> 571180 | AJ8: =AI8/AH8-1 -> 0.6078119 | AK8: 555000 | AL8: 275000 | AM8: =AL8/AK8-1 -> -0.5045045 | AN8: =AK8+AH8 -> 910253 | AO8: =AL8+AI8 -> 846180 | AP8: =AO8/AN8-1 -> -0.07039032 | AS8: =AR8/AQ8-1 -> #DIV/0! | AT8: =AQ8+AN8 -> 910253 | AU8: =AR8+AO8 -> 846180 | AV8: =AU8/AT8-1 -> -0.07039032 | AX8: 30000 | AY8: =AX8/AW8-1 -> #DIV/0! | AZ8: =AW8+AT8 -> 910253 | BA8: =AX8+AU8 -> 876180 | BB8: =BA8/AZ8-1 -> -0.03743245 | BC8: 6799 | BD8: 10000 | BE8: =BD8/BC8-1 -> 0.47080453 | BF8: =BC8+AZ8 -> 917052 | BG8: =BD8+BA8 -> 886180 | BH8: =BG8/BF8-1 -> -0.033664394 | BI8: 137020 | BJ8: 100000 | BK8: =BJ8/BI8-1 -> -0.27017954 | BL8: =BI8+BF8 -> 1054072 | BM8: =BJ8+BG8 -> 986180 | BN8: =BM8/BL8-1 -> -0.064409262 | BO8: 182000 | BP8: 220000 | BQ8: 1456072 | BR8: =BM8/10000/I8 -> 0.51904211 | BS8: 50253
A9: 杭州 | B9: 杭州 | C9: 杭州佳威信息科技有限公司 | D9: 经销 | E9: 经销 | F9: 建德市 | G9: 建德市 | H9: 吴海林 | J9: 10000 | L9: =K9/J9-1 -> -1 | O9: =N9/M9-1 -> #DIV/0! | P9: =J9+M9 -> 10000 | Q9: =K9+N9 -> 0 | R9: =Q9/P9-1 -> -1 | S9: 10000 | U9: =T9/S9-1 -> -1 | V9: =S9+P9 -> 20000 | W9: =T9+Q9 -> 0 | X9: =W9/V9-1 -> -1 | Y9: 10000 | AA9: =Z9/Y9-1 -> -1 | AB9: =Y9+V9 -> 30000 | AC9: =Z9+W9 -> 0 | AD9: =AC9/AB9-1 -> -1 | AG9: =AF9/AE9-1 -> #DIV/0! | AH9: =AE9+AB9 -> 30000 | AI9: =AF9+AC9 -> 0 | AJ9: =AI9/AH9-1 -> -1 | AM9: =AL9/AK9-1 -> #DIV/0! | AN9: =AK9+AH9 -> 30000 | AO9: =AL9+AI9 -> 0 | AP9: =AO9/AN9-1 -> -1 | AS9: =AR9/AQ9-1 -> #DIV/0! | AT9: =AQ9+AN9 -> 30000 | AU9: =AR9+AO9 -> 0 | AV9: =AU9/AT9-1 -> -1 | AY9: =AX9/AW9-1 -> #DIV/0! | AZ9: =AW9+AT9 -> 30000 | BA9: =AX9+AU9 -> 0 | BB9: =BA9/AZ9-1 -> -1 | BE9: =BD9/BC9-1 -> #DIV/0! | BF9: =BC9+AZ9 -> 30000 | BG9: =BD9+BA9 -> 0 | BH9: =BG9/BF9-1 -> -1 | BK9: =BJ9/BI9-1 -> #DIV/0! | BL9: =BI9+BF9 -> 30000 | BM9: =BJ9+BG9 -> 0 | BN9: =BM9/BL9-1 -> -1 | BQ9: 30000 | BR9: =BM9/10000/I9 -> #DIV/0!
A10: 杭州 | B10: 杭州 | C10: 杭州京品满屋家电有限公司 | D10: 经销 | E10: 经销 | F10: 淳安县 | G10: 淳安县 | H10: 吴海林 | I10: 60 | J10: 10980 | K10: 1887 | L10: =K10/J10-1 -> -0.82814208 | M10: 10390 | O10: =N10/M10-1 -> -1 | P10: =J10+M10 -> 21370 | Q10: =K10+N10 -> 1887 | R10: =Q10/P10-1 -> -0.91169864 | S10: 20613 | T10: 21472 | U10: =T10/S10-1 -> 0.041672731 | V10: =S10+P10 -> 41983 | W10: =T10+Q10 -> 23359 | X10: =W10/V10-1 -> -0.44360813 | Y10: 14343 | Z10: 24592 | AA10: =Z10/Y10-1 -> 0.7145646 | AB10: =Y10+V10 -> 56326 | AC10: =Z10+W10 -> 47951 | AD10: =AC10/AB10-1 -> -0.14868799 | AE10: 10168 | AF10: 35823 | AG10: =AF10/AE10-1 -> 2.5231117 | AH10: =AE10+AB10 -> 66494 | AI10: =AF10+AC10 -> 83774 | AJ10: =AI10/AH10-1 -> 0.25987307 | AK10: 6124 | AL10: 40090 | AM10: =AL10/AK10-1 -> 5.5463749 | AN10: =AK10+AH10 -> 72618 | AO10: =AL10+AI10 -> 123864 | AP10: =AO10/AN10-1 -> 0.7056928 | AR10: 5841 | AS10: =AR10/AQ10-1 -> #DIV/0! | AT10: =AQ10+AN10 -> 72618 | AU10: =AR10+AO10 -> 129705 | AV10: =AU10/AT10-1 -> 0.78612741 | AW10: 9927 | AX10: 19585 | AY10: =AX10/AW10-1 -> 0.97290219 | AZ10: =AW10+AT10 -> 82545 | BA10: =AX10+AU10 -> 149290 | BB10: =BA10/AZ10-1 -> 0.80858925 | BC10: 97064 | BD10: 24536 | BE10: =BD10/BC10-1 -> -0.74721833 | BF10: =BC10+AZ10 -> 179609 | BG10: =BD10+BA10 -> 173826 | BH10: =BG10/BF10-1 -> -0.032197718 | BI10: 75532 | BK10: =BJ10/BI10-1 -> -1 | BL10: =BI10+BF10 -> 255141 | BM10: =BJ10+BG10 -> 173826 | BN10: =BM10/BL10-1 -> -0.31870613 | BP10: 119846 | BQ10: 374987 | BR10: =BM10/10000/I10 -> 0.28971
A11: 杭州 | B11: 杭州 | C11: 杭州司亿博环境设备有限公司 | D11: 经销 | E11: 经销 | F11: 杭州市区 | G11: 钱塘区 | H11: 董培培 | I11: 10 | J11: 11748 | L11: =K11/J11-1 -> -1 | M11: 16445 | N11: 2274 | O11: =N11/M11-1 -> -0.86172089 | P11: =J11+M11 -> 28193 | Q11: =K11+N11 -> 2274 | R11: =Q11/P11-1 -> -0.91934168 | S11: 800 | U11: =T11/S11-1 -> -1 | V11: =S11+P11 -> 28993 | W11: =T11+Q11 -> 2274 | X11: =W11/V11-1 -> -0.92156727 | Z11: 2217 | AA11: =Z11/Y11-1 -> #DIV/0! | AB11: =Y11+V11 -> 28993 | AC11: =Z11+W11 -> 4491 | AD11: =AC11/AB11-1 -> -0.84510054 | AE11: 19214 | AF11: 13140 | AG11: =AF11/AE11-1 -> -0.31612366 | AH11: =AE11+AB11 -> 48207 | AI11: =AF11+AC11 -> 17631 | AJ11: =AI11/AH11-1 -> -0.63426473 | AM11: =AL11/AK11-1 -> #DIV/0! | AN11: =AK11+AH11 -> 48207 | AO11: =AL11+AI11 -> 17631 | AP11: =AO11/AN11-1 -> -0.63426473 | AQ11: 4009 | AR11: 3043 | AS11: =AR11/AQ11-1 -> -0.24095784 | AT11: =AQ11+AN11 -> 52216 | AU11: =AR11+AO11 -> 20674 | AV11: =AU11/AT11-1 -> -0.60406772 | AW11: 10575 | AY11: =AX11/AW11-1 -> -1 | AZ11: =AW11+AT11 -> 62791 | BA11: =AX11+AU11 -> 20674 | BB11: =BA11/AZ11-1 -> -0.67074899 | BC11: 800 | BE11: =BD11/BC11-1 -> -1 | BF11: =BC11+AZ11 -> 63591 | BG11: =BD11+BA11 -> 20674 | BH11: =BG11/BF11-1 -> -0.6748911 | BI11: 3078 | BK11: =BJ11/BI11-1 -> -1 | BL11: =BI11+BF11 -> 66669 | BM11: =BJ11+BG11 -> 20674 | BN11: =BM11/BL11-1 -> -0.68990085 | BP11: 3200 | BQ11: 69869 | BR11: =BM11/10000/I11 -> 0.20674
A12: 杭州 | B12: 杭州 | C12: 杭州五星 | D12: 五星 | E12: 五星 | F12: 杭州市区 | G12: 市区 | H12: 李燕霞 | I12: 560 | J12: -55370.32 | K12: 513987.69 | L12: =K12/J12-1 -> -10.282729 | N12: 456944.83 | O12: =N12/M12-1 -> #DIV/0! | P12: =J12+M12 -> -55370.32 | Q12: =K12+N12 -> 970932.52 | R12: =Q12/P12-1 -> -18.535252 | T12: =591327.2+48000 -> 639327.2 | U12: =T12/S12-1 -> #DIV/0! | V12: =S12+P12 -> -55370.32 | W12: =T12+Q12 -> 1610259.7 | X12: =W12/V12-1 -> -30.08164 | Y12: 442229.3 | Z12: =279375.22+41000+60000 -> 380375.22 | AA12: =Z12/Y12-1 -> -0.1398688 | AB12: =Y12+V12 -> 386858.98 | AC12: =Z12+W12 -> 1990634.9 | AD12: =AC12/AB12-1 -> 4.1456346 | AE12: 309190.52 | AF12: 403454.03 | AG12: =AF12/AE12-1 -> 0.30487193 | AH12: =AE12+AB12 -> 696049.5 | AI12: =AF12+AC12 -> 2394089 | AJ12: =AI12/AH12-1 -> 2.4395384 | AK12: 319675.55 | AL12: 521128.98 | AM12: =AL12/AK12-1 -> 0.63018091 | AN12: =AK12+AH12 -> 1015725.1 | AO12: =AL12+AI12 -> 2915218 | AP12: =AO12/AN12-1 -> 1.8700857 | AQ12: 528891.84 | AR12: 152639.86 | AS12: =AR12/AQ12-1 -> -0.71139683 | AT12: =AQ12+AN12 -> 1544616.9 | AU12: =AR12+AO12 -> 3067857.8 | AV12: =AU12/AT12-1 -> 0.98616099 | AW12: 226314.07 | AY12: =AX12/AW12-1 -> -1 | AZ12: =AW12+AT12 -> 1770931 | BA12: =AX12+AU12 -> 3067857.8 | BB12: =BA12/AZ12-1 -> 0.73234185 | BC12: 174190.5 | BE12: =BD12/BC12-1 -> -1 | BF12: =BC12+AZ12 -> 1945121.5 | BG12: =BD12+BA12 -> 3067857.8 | BH12: =BG12/BF12-1 -> 0.57720629 | BI12: 471478.84 | BK12: =BJ12/BI12-1 -> -1 | BL12: =BI12+BF12 -> 2416600.3 | BM12: =BJ12+BG12 -> 3067857.8 | BN12: =BM12/BL12-1 -> 0.26949327 | BO12: 897862.49 | BP12: 233096.17 | BQ12: 3547559 | BR12: =BM12/10000/I12 -> 0.54783175 | BS12: 94000 | BT12: =48000+41000 -> 89000 | BU12: 6+1.7
A13: 杭州 | B13: 杭州 | C13: 杭州临平江南家居专卖店 | D13: 直营 | E13: 直营 | F13: 临平区 | G13: 临平区 | H13: 专卖店 | I13: 180 | J13: 103977 | K13: 22066 | L13: =K13/J13-1 -> -0.78777999 | M13: 19500 | N13: 49149 | O13: =N13/M13-1 -> 1.5204615 | P13: =J13+M13 -> 123477 | Q13: =K13+N13 -> 71215 | R13: =Q13/P13-1 -> -0.42325291 | S13: 113494 | T13: 91366 | U13: =T13/S13-1 -> -0.19497066 | V13: =S13+P13 -> 236971 | W13: =T13+Q13 -> 162581 | X13: =W13/V13-1 -> -0.31392027 | Y13: 109059 | Z13: 67817 | AA13: =Z13/Y13-1 -> -0.37816228 | AB13: =Y13+V13 -> 346030 | AC13: =Z13+W13 -> 230398 | AD13: =AC13/AB13-1 -> -0.33416756 | AE13: 111723 | AF13: 71689 | AG13: =AF13/AE13-1 -> -0.35833266 | AH13: =AE13+AB13 -> 457753 | AI13: =AF13+AC13 -> 302087 | AJ13: =AI13/AH13-1 -> -0.34006549 | AK13: 173284 | AL13: 123804 | AM13: =AL13/AK13-1 -> -0.28554281 | AN13: =AK13+AH13 -> 631037 | AO13: =AL13+AI13 -> 425891 | AP13: =AO13/AN13-1 -> -0.32509346 | AQ13: 72134 | AR13: 47933 | AS13: =AR13/AQ13-1 -> -0.3355006 | AT13: =AQ13+AN13 -> 703171 | AU13: =AR13+AO13 -> 473824 | AV13: =AU13/AT13-1 -> -0.32616106 | AW13: 94856 | AX13: 51793 | AY13: =AX13/AW13-1 -> -0.45398288 | AZ13: =AW13+AT13 -> 798027 | BA13: =AX13+AU13 -> 525617 | BB13: =BA13/AZ13-1 -> -0.34135437 | BC13: 159320 | BD13: 24824 | BE13: =BD13/BC13-1 -> -0.8441878 | BF13: =BC13+AZ13 -> 957347 | BG13: =BD13+BA13 -> 550441 | BH13: =BG13/BF13-1 -> -0.42503502 | BI13: 185198.4 | BJ13: 49284 | BK13: =BJ13/BI13-1 -> -0.73388539 | BL13: =BI13+BF13 -> 1142545.4 | BM13: =BJ13+BG13 -> 599725 | BN13: =BM13/BL13-1 -> -0.47509744 | BO13: 81513 | BP13: 177473 | BQ13: 1401531.4 | BR13: =BM13/10000/I13 -> 0.33318056
A14: 杭州 | B14: 杭州 | C14: 杭州华泓电器有限公司 | D14: 经销 | E14: 经销 | F14: 萧山区 | G14: 萧山区 | H14: 董培培 | J14: 800 | L14: =K14/J14-1 -> -1 | O14: =N14/M14-1 -> #DIV/0! | P14: =J14+M14 -> 800 | Q14: =K14+N14 -> 0 | R14: =Q14/P14-1 -> -1 | U14: =T14/S14-1 -> #DIV/0! | V14: =S14+P14 -> 800 | W14: =T14+Q14 -> 0 | X14: =W14/V14-1 -> -1 | AA14: =Z14/Y14-1 -> #DIV/0! | AB14: =Y14+V14 -> 800 | AC14: =Z14+W14 -> 0 | AD14: =AC14/AB14-1 -> -1 | AG14: =AF14/AE14-1 -> #DIV/0! | AH14: =AE14+AB14 -> 800 | AI14: =AF14+AC14 -> 0 | AJ14: =AI14/AH14-1 -> -1 | AK14: 6071 | AM14: =AL14/AK14-1 -> -1 | AN14: =AK14+AH14 -> 6871 | AO14: =AL14+AI14 -> 0 | AP14: =AO14/AN14-1 -> -1 | AR14: 4498 | AS14: =AR14/AQ14-1 -> #DIV/0! | AT14: =AQ14+AN14 -> 6871 | AU14: =AR14+AO14 -> 4498 | AV14: =AU14/AT14-1 -> -0.34536458 | AW14: 6599 | AX14: 13050 | AY14: =AX14/AW14-1 -> 0.97757236 | AZ14: =AW14+AT14 -> 13470 | BA14: =AX14+AU14 -> 17548 | BB14: =BA14/AZ14-1 -> 0.30274684 | BC14: 16646 | BE14: =BD14/BC14-1 -> -1 | BF14: =BC14+AZ14 -> 30116 | BG14: =BD14+BA14 -> 17548 | BH14: =BG14/BF14-1 -> -0.4173197 | BI14: 8396 | BK14: =BJ14/BI14-1 -> -1 | BL14: =BI14+BF14 -> 38512 | BM14: =BJ14+BG14 -> 17548 | BN14: =BM14/BL14-1 -> -0.54434981 | BQ14: 38512 | BR14: =BM14/10000/I14 -> #DIV/0!
A15: 杭州 | B15: 杭州 | C15: 杭州金蝶零售 | D15: 零售 | E15: 零售 | F15: 杭州市区 | G15: 市区 | H15: 杭州零售 | J15: 111956.28 | K15: 76873.34 | L15: =K15/J15-1 -> -0.31336286 | M15: 43919 | N15: 43284.9 | O15: =N15/M15-1 -> -0.014437943 | P15: =J15+M15 -> 155875.28 | Q15: =K15+N15 -> 120158.24 | R15: =Q15/P15-1 -> -0.22913858 | S15: 80405.08 | T15: 119148.66 | U15: =T15/S15-1 -> 0.48185488 | V15: =S15+P15 -> 236280.36 | W15: =T15+Q15 -> 239306.9 | X15: =W15/V15-1 -> 0.012809105 | Y15: 82108.64 | Z15: 310195.38 | AA15: =Z15/Y15-1 -> 2.7778653 | AB15: =Y15+V15 -> 318389 | AC15: =Z15+W15 -> 549502.28 | AD15: =AC15/AB15-1 -> 0.72588337 | AE15: 209042.8 | AF15: 36281.12 | AG15: =AF15/AE15-1 -> -0.82644167 | AH15: =AE15+AB15 -> 527431.8 | AI15: =AF15+AC15 -> 585783.4 | AJ15: =AI15/AH15-1 -> 0.11063345 | AK15: 78620.76 | AL15: 30684.4 | AM15: =AL15/AK15-1 -> -0.60971631 | AN15: =AK15+AH15 -> 606052.56 | AO15: =AL15+AI15 -> 616467.8 | AP15: =AO15/AN15-1 -> 0.017185374 | AQ15: 153937.2 | AR15: 271358.5 | AS15: =AR15/AQ15-1 -> 0.76278703 | AT15: =AQ15+AN15 -> 759989.76 | AU15: =AR15+AO15 -> 887826.3 | AV15: =AU15/AT15-1 -> 0.16820824 | AW15: 172756.46 | AX15: 91767.56 | AY15: =AX15/AW15-1 -> -0.46880389 | AZ15: =AW15+AT15 -> 932746.22 | BA15: =AX15+AU15 -> 979593.86 | BB15: =BA15/AZ15-1 -> 0.050225494 | BC15: 226467.5 | BD15: 93879.44 | BE15: =BD15/BC15-1 -> -0.58546175 | BF15: =BC15+AZ15 -> 1159213.7 | BG15: =BD15+BA15 -> 1073473.3 | BH15: =BG15/BF15-1 -> -0.07396429 | BI15: 216712.16 | BJ15: 330288.06 | BK15: =BJ15/BI15-1 -> 0.52408642 | BL15: =BI15+BF15 -> 1375925.9 | BM15: =BJ15+BG15 -> 1403761.4 | BN15: =BM15/BL15-1 -> 0.020230363 | BO15: 164087.41 | BP15: 375150.88 | BQ15: 1915164.2 | BR15: =BM15/10000/I15 -> #DIV/0!
A16: 杭州 | B16: 杭州 | C16: 杭州金蝶零售（李燕霞） | D16: 零售 | E16: 零售 | F16: 杭州市区 | G16: 市区 | H16: 李燕霞 | L16: =K16/J16-1 -> #DIV/0! | N16: 6125 | O16: =N16/M16-1 -> #DIV/0! | P16: =J16+M16 -> 0 | Q16: =K16+N16 -> 6125 | R16: =Q16/P16-1 -> #DIV/0! | U16: =T16/S16-1 -> #DIV/0! | V16: =S16+P16 -> 0 | W16: =T16+Q16 -> 6125 | X16: =W16/V16-1 -> #DIV/0! | AA16: =Z16/Y16-1 -> #DIV/0! | AB16: =Y16+V16 -> 0 | AC16: =Z16+W16 -> 6125 | AD16: =AC16/AB16-1 -> #DIV/0! | AE16: 3636 | AG16: =AF16/AE16-1 -> -1 | AH16: =AE16+AB16 -> 3636 | AI16: =AF16+AC16 -> 6125 | AJ16: =AI16/AH16-1 -> 0.68454345 | AK16: 25759 | AM16: =AL16/AK16-1 -> -1 | AN16: =AK16+AH16 -> 29395 | AO16: =AL16+AI16 -> 6125 | AP16: =AO16/AN16-1 -> -0.79163123 | AS16: =AR16/AQ16-1 -> #DIV/0! | AT16: =AQ16+AN16 -> 29395 | AU16: =AR16+AO16 -> 6125 | AV16: =AU16/AT16-1 -> -0.79163123 | AW16: 2400 | AY16: =AX16/AW16-1 -> -1 | AZ16: =AW16+AT16 -> 31795 | BA16: =AX16+AU16 -> 6125 | BB16: =BA16/AZ16-1 -> -0.80735965 | BC16: 29589 | BE16: =BD16/BC16-1 -> -1 | BF16: =BC16+AZ16 -> 61384 | BG16: =BD16+BA16 -> 6125 | BH16: =BG16/BF16-1 -> -0.9002183 | BK16: =BJ16/BI16-1 -> #DIV/0! | BL16: =BI16+BF16 -> 61384 | BM16: =BJ16+BG16 -> 6125 | BN16: =BM16/BL16-1 -> -0.9002183 | BQ16: 61384 | BR16: =BM16/10000/I16 -> #DIV/0!
A17: 杭州 | B17: 杭州 | C17: 萧山世纪龙建材专卖店 | D17: 直营 | E17: 直营 | F17: 萧山区 | G17: 萧山区 | H17: 专卖店 | J17: 52801 | L17: =K17/J17-1 -> -1 | O17: =N17/M17-1 -> #DIV/0! | P17: =J17+M17 -> 52801 | Q17: =K17+N17 -> 0 | R17: =Q17/P17-1 -> -1 | U17: =T17/S17-1 -> #DIV/0! | V17: =S17+P17 -> 52801 | W17: =T17+Q17 -> 0 | X17: =W17/V17-1 -> -1 | AA17: =Z17/Y17-1 -> #DIV/0! | AB17: =Y17+V17 -> 52801 | AC17: =Z17+W17 -> 0 | AD17: =AC17/AB17-1 -> -1 | AG17: =AF17/AE17-1 -> #DIV/0! | AH17: =AE17+AB17 -> 52801 | AI17: =AF17+AC17 -> 0 | AJ17: =AI17/AH17-1 -> -1 | AM17: =AL17/AK17-1 -> #DIV/0! | AN17: =AK17+AH17 -> 52801 | AO17: =AL17+AI17 -> 0 | AP17: =AO17/AN17-1 -> -1 | AS17: =AR17/AQ17-1 -> #DIV/0! | AT17: =AQ17+AN17 -> 52801 | AU17: =AR17+AO17 -> 0 | AV17: =AU17/AT17-1 -> -1 | AY17: =AX17/AW17-1 -> #DIV/0! | AZ17: =AW17+AT17 -> 52801 | BA17: =AX17+AU17 -> 0 | BB17: =BA17/AZ17-1 -> -1 | BE17: =BD17/BC17-1 -> #DIV/0! | BF17: =BC17+AZ17 -> 52801 | BG17: =BD17+BA17 -> 0 | BH17: =BG17/BF17-1 -> -1 | BK17: =BJ17/BI17-1 -> #DIV/0! | BL17: =BI17+BF17 -> 52801 | BM17: =BJ17+BG17 -> 0 | BN17: =BM17/BL17-1 -> -1 | BQ17: 52801 | BR17: =BM17/10000/I17 -> #DIV/0!
A18: 杭州 | B18: 杭州 | C18: （新）古墩新时代专卖店 | D18: 直营 | E18: 直营 | F18: 杭州市区 | G18: 西湖风景名胜区 | H18: 专卖店 | J18: -16596 | L18: =K18/J18-1 -> -1 | O18: =N18/M18-1 -> #DIV/0! | P18: =J18+M18 -> -16596 | Q18: =K18+N18 -> 0 | R18: =Q18/P18-1 -> -1 | U18: =T18/S18-1 -> #DIV/0! | V18: =S18+P18 -> -16596 | W18: =T18+Q18 -> 0 | X18: =W18/V18-1 -> -1 | AA18: =Z18/Y18-1 -> #DIV/0! | AB18: =Y18+V18 -> -16596 | AC18: =Z18+W18 -> 0 | AD18: =AC18/AB18-1 -> -1 | AG18: =AF18/AE18-1 -> #DIV/0! | AH18: =AE18+AB18 -> -16596 | AI18: =AF18+AC18 -> 0 | AJ18: =AI18/AH18-1 -> -1 | AM18: =AL18/AK18-1 -> #DIV/0! | AN18: =AK18+AH18 -> -16596 | AO18: =AL18+AI18 -> 0 | AP18: =AO18/AN18-1 -> -1 | AQ18: 500 | AS18: =AR18/AQ18-1 -> -1 | AT18: =AQ18+AN18 -> -16096 | AU18: =AR18+AO18 -> 0 | AV18: =AU18/AT18-1 -> -1 | AY18: =AX18/AW18-1 -> #DIV/0! | AZ18: =AW18+AT18 -> -16096 | BA18: =AX18+AU18 -> 0 | BB18: =BA18/AZ18-1 -> -1 | BE18: =BD18/BC18-1 -> #DIV/0! | BF18: =BC18+AZ18 -> -16096 | BG18: =BD18+BA18 -> 0 | BH18: =BG18/BF18-1 -> -1 | BK18: =BJ18/BI18-1 -> #DIV/0! | BL18: =BI18+BF18 -> -16096 | BM18: =BJ18+BG18 -> 0 | BN18: =BM18/BL18-1 -> -1 | BO18: -4600 | BQ18: -20696 | BR18: =BM18/10000/I18 -> #DIV/0!
A19: 杭州 | B19: 杭州 | C19: （新）宏丰专卖店 | D19: 直营 | E19: 直营 | F19: 杭州市区 | G19: 市区 | H19: 专卖店 | L19: =K19/J19-1 -> #DIV/0! | M19: -3358 | O19: =N19/M19-1 -> -1 | P19: =J19+M19 -> -3358 | Q19: =K19+N19 -> 0 | R19: =Q19/P19-1 -> -1 | U19: =T19/S19-1 -> #DIV/0! | V19: =S19+P19 -> -3358 | W19: =T19+Q19 -> 0 | X19: =W19/V19-1 -> -1 | AA19: =Z19/Y19-1 -> #DIV/0! | AB19: =Y19+V19 -> -3358 | AC19: =Z19+W19 -> 0 | AD19: =AC19/AB19-1 -> -1 | AG19: =AF19/AE19-1 -> #DIV/0! | AH19: =AE19+AB19 -> -3358 | AI19: =AF19+AC19 -> 0 | AJ19: =AI19/AH19-1 -> -1 | AM19: =AL19/AK19-1 -> #DIV/0! | AN19: =AK19+AH19 -> -3358 | AO19: =AL19+AI19 -> 0 | AP19: =AO19/AN19-1 -> -1 | AS19: =AR19/AQ19-1 -> #DIV/0! | AT19: =AQ19+AN19 -> -3358 | AU19: =AR19+AO19 -> 0 | AV19: =AU19/AT19-1 -> -1 | AY19: =AX19/AW19-1 -> #DIV/0! | AZ19: =AW19+AT19 -> -3358 | BA19: =AX19+AU19 -> 0 | BB19: =BA19/AZ19-1 -> -1 | BE19: =BD19/BC19-1 -> #DIV/0! | BF19: =BC19+AZ19 -> -3358 | BG19: =BD19+BA19 -> 0 | BH19: =BG19/BF19-1 -> -1 | BK19: =BJ19/BI19-1 -> #DIV/0! | BL19: =BI19+BF19 -> -3358 | BM19: =BJ19+BG19 -> 0 | BN19: =BM19/BL19-1 -> -1 | BQ19: -3358 | BR19: =BM19/10000/I19 -> #DIV/0!
A20: 杭州 | B20: 杭州 | C20: 杭州月星家居超级旗舰店 | D20: 直营 | E20: 直营 | F20: 杭州市区 | G20: 拱墅区 | H20: 专卖店 | L20: =K20/J20-1 -> #DIV/0! | O20: =N20/M20-1 -> #DIV/0! | P20: =J20+M20 -> 0 | Q20: =K20+N20 -> 0 | R20: =Q20/P20-1 -> #DIV/0! | U20: =T20/S20-1 -> #DIV/0! | V20: =S20+P20 -> 0 | W20: =T20+Q20 -> 0 | X20: =W20/V20-1 -> #DIV/0! | AA20: =Z20/Y20-1 -> #DIV/0! | AB20: =Y20+V20 -> 0 | AC20: =Z20+W20 -> 0 | AD20: =AC20/AB20-1 -> #DIV/0! | AG20: =AF20/AE20-1 -> #DIV/0! | AH20: =AE20+AB20 -> 0 | AI20: =AF20+AC20 -> 0 | AJ20: =AI20/AH20-1 -> #DIV/0! | AM20: =AL20/AK20-1 -> #DIV/0! | AN20: =AK20+AH20 -> 0 | AO20: =AL20+AI20 -> 0 | AP20: =AO20/AN20-1 -> #DIV/0! | AS20: =AR20/AQ20-1 -> #DIV/0! | AT20: =AQ20+AN20 -> 0 | AU20: =AR20+AO20 -> 0 | AV20: =AU20/AT20-1 -> #DIV/0! | AY20: =AX20/AW20-1 -> #DIV/0! | AZ20: =AW20+AT20 -> 0 | BA20: =AX20+AU20 -> 0 | BB20: =BA20/AZ20-1 -> #DIV/0! | BE20: =BD20/BC20-1 -> #DIV/0! | BF20: =BC20+AZ20 -> 0 | BG20: =BD20+BA20 -> 0 | BH20: =BG20/BF20-1 -> #DIV/0! | BK20: =BJ20/BI20-1 -> #DIV/0! | BL20: =BI20+BF20 -> 0 | BM20: =BJ20+BG20 -> 0 | BN20: =BM20/BL20-1 -> #DIV/0! | BQ20: 0 | BR20: =BM20/10000/I20 -> #DIV/0!
A21: 杭州 | B21: 杭州 | C21: 杭州恒大建材超级旗舰店 | D21: 直营 | E21: 直营 | F21: 杭州市区 | G21: 钱塘区 | H21: 专卖店 | I21: 230 | J21: 164507 | K21: 108230.5 | L21: =K21/J21-1 -> -0.34209183 | M21: 107411 | N21: 59256.4 | O21: =N21/M21-1 -> -0.44832094 | P21: =J21+M21 -> 271918 | Q21: =K21+N21 -> 167486.9 | R21: =Q21/P21-1 -> -0.38405365 | S21: 318901 | T21: 109309.1 | U21: =T21/S21-1 -> -0.65723187 | V21: =S21+P21 -> 590819 | W21: =T21+Q21 -> 276796 | X21: =W21/V21-1 -> -0.53150457 | Y21: 286782 | Z21: 130231 | AA21: =Z21/Y21-1 -> -0.54588851 | AB21: =Y21+V21 -> 877601 | AC21: =Z21+W21 -> 407027 | AD21: =AC21/AB21-1 -> -0.53620495 | AE21: 277032 | AF21: 123067.1 | AG21: =AF21/AE21-1 -> -0.55576576 | AH21: =AE21+AB21 -> 1154633 | AI21: =AF21+AC21 -> 530094.1 | AJ21: =AI21/AH21-1 -> -0.54089819 | AK21: 219679 | AL21: 158341.8 | AM21: =AL21/AK21-1 -> -0.27921285 | AN21: =AK21+AH21 -> 1374312 | AO21: =AL21+AI21 -> 688435.9 | AP21: =AO21/AN21-1 -> -0.4990687 | AQ21: 159081 | AR21: 49102 | AS21: =AR21/AQ21-1 -> -0.69133963 | AT21: =AQ21+AN21 -> 1533393 | AU21: =AR21+AO21 -> 737537.9 | AV21: =AU21/AT21-1 -> -0.51901574 | AW21: 201109 | AX21: =31899-3470 -> 28429 | AY21: =AX21/AW21-1 -> -0.85863885 | AZ21: =AW21+AT21 -> 1734502 | BA21: =AX21+AU21 -> 765966.9 | BB21: =BA21/AZ21-1 -> -0.55839376 | BC21: 242762.6 | BD21: 54601 | BE21: =BD21/BC21-1 -> -0.77508479 | BF21: =BC21+AZ21 -> 1977264.6 | BG21: =BD21+BA21 -> 820567.9 | BH21: =BG21/BF21-1 -> -0.58499844 | BI21: 349831.4 | BJ21: 65384 | BK21: =BJ21/BI21-1 -> -0.81309854 | BL21: =BI21+BF21 -> 2327096 | BM21: =BJ21+BG21 -> 885951.9 | BN21: =BM21/BL21-1 -> -0.61928863 | BO21: 127945.5 | BP21: 212464 | BQ21: 2667505.5 | BR21: =BM21/10000/I21 -> 0.38519648
A22: 杭州 | B22: 杭州 | C22: 二轻爱威专卖店 | D22: 加盟 | E22: 加盟 | F22: 杭州市区 | G22: 拱墅区 | H22: 专卖店 | J22: 78855 | K22: 24931 | L22: =K22/J22-1 -> -0.68383742 | M22: 39609 | N22: =16033+14550 -> 30583 | O22: =N22/M22-1 -> -0.2278775 | P22: =J22+M22 -> 118464 | Q22: =K22+N22 -> 55514 | R22: =Q22/P22-1 -> -0.53138506 | S22: 40486 | T22: 10700 | U22: =T22/S22-1 -> -0.73571111 | V22: =S22+P22 -> 158950 | W22: =T22+Q22 -> 66214 | X22: =W22/V22-1 -> -0.58342875 | Y22: 45990 | AA22: =Z22/Y22-1 -> -1 | AB22: =Y22+V22 -> 204940 | AC22: =Z22+W22 -> 66214 | AD22: =AC22/AB22-1 -> -0.67691032 | AE22: 26265 | AF22: -3281.96 | AG22: =AF22/AE22-1 -> -1.1249556 | AH22: =AE22+AB22 -> 231205 | AI22: =AF22+AC22 -> 62932.04 | AJ22: =AI22/AH22-1 -> -0.72780848 | AK22: 67133 | AM22: =AL22/AK22-1 -> -1 | AN22: =AK22+AH22 -> 298338 | AO22: =AL22+AI22 -> 62932.04 | AP22: =AO22/AN22-1 -> -0.78905791 | AQ22: 58226 | AS22: =AR22/AQ22-1 -> -1 | AT22: =AQ22+AN22 -> 356564 | AU22: =AR22+AO22 -> 62932.04 | AV22: =AU22/AT22-1 -> -0.82350422 | AW22: 24848 | AY22: =AX22/AW22-1 -> -1 | AZ22: =AW22+AT22 -> 381412 | BA22: =AX22+AU22 -> 62932.04 | BB22: =BA22/AZ22-1 -> -0.83500246 | BC22: 34493 | BE22: =BD22/BC22-1 -> -1 | BF22: =BC22+AZ22 -> 415905 | BG22: =BD22+BA22 -> 62932.04 | BH22: =BG22/BF22-1 -> -0.8486865 | BI22: 20231 | BK22: =BJ22/BI22-1 -> -1 | BL22: =BI22+BF22 -> 436136 | BM22: =BJ22+BG22 -> 62932.04 | BN22: =BM22/BL22-1 -> -0.85570547 | BO22: 24237 | BP22: 103577 | BQ22: 563950 | BR22: =BM22/10000/I22 -> #DIV/0!
A23: 杭州 | B23: 杭州 | C23: （新）滨江第六空间专卖店 | D23: 直营 | E23: 直营 | F23: 杭州市区 | G23: 滨江区 | H23: 专卖店 | I23: 280 | J23: 155330 | K23: 156262 | L23: =K23/J23-1 -> 0.0060001288 | M23: 84728 | N23: 143497 | O23: =N23/M23-1 -> 0.69361958 | P23: =J23+M23 -> 240058 | Q23: =K23+N23 -> 299759 | R23: =Q23/P23-1 -> 0.24869407 | S23: 296842 | T23: 199854.6 | U23: =T23/S23-1 -> -0.32673072 | V23: =S23+P23 -> 536900 | W23: =T23+Q23 -> 499613.6 | X23: =W23/V23-1 -> -0.069447569 | Y23: 180500 | Z23: 131199.7 | AA23: =Z23/Y23-1 -> -0.27313186 | AB23: =Y23+V23 -> 717400 | AC23: =Z23+W23 -> 630813.3 | AD23: =AC23/AB23-1 -> -0.12069515 | AE23: 190972 | AF23: 160705 | AG23: =AF23/AE23-1 -> -0.1584892 | AH23: =AE23+AB23 -> 908372 | AI23: =AF23+AC23 -> 791518.3 | AJ23: =AI23/AH23-1 -> -0.1286408 | AK23: 207825 | AL23: 164883 | AM23: =AL23/AK23-1 -> -0.20662577 | AN23: =AK23+AH23 -> 1116197 | AO23: =AL23+AI23 -> 956401.3 | AP23: =AO23/AN23-1 -> -0.14316084 | AQ23: 114990 | AR23: 50432 | AS23: =AR23/AQ23-1 -> -0.56142273 | AT23: =AQ23+AN23 -> 1231187 | AU23: =AR23+AO23 -> 1006833.3 | AV23: =AU23/AT23-1 -> -0.18222553 | AW23: 62417 | AX23: 52672 | AY23: =AX23/AW23-1 -> -0.15612734 | AZ23: =AW23+AT23 -> 1293604 | BA23: =AX23+AU23 -> 1059505.3 | BB23: =BA23/AZ23-1 -> -0.18096628 | BC23: 213083 | BD23: 98642 | BE23: =BD23/BC23-1 -> -0.53707241 | BF23: =BC23+AZ23 -> 1506687 | BG23: =BD23+BA23 -> 1158147.3 | BH23: =BG23/BF23-1 -> -0.23132854 | BI23: 304051.4 | BJ23: 85329 | BK23: =BJ23/BI23-1 -> -0.71935995 | BL23: =BI23+BF23 -> 1810738.4 | BM23: =BJ23+BG23 -> 1243476.3 | BN23: =BM23/BL23-1 -> -0.31327667 | BO23: 330136 | BP23: 394635 | BQ23: 2535509.4 | BR23: =BM23/10000/I23 -> 0.44409868
A24: 杭州 | B24: 杭州 | C24: 杭州日新人工环境工程有限公司 | D24: 暖通 | E24: 暖通 | F24: 杭州市区 | G24: 西湖风景名胜区 | H24: 陈雪君 | L24: =K24/J24-1 -> #DIV/0! | O24: =N24/M24-1 -> #DIV/0! | P24: =J24+M24 -> 0 | Q24: =K24+N24 -> 0 | R24: =Q24/P24-1 -> #DIV/0! | S24: 790 | U24: =T24/S24-1 -> -1 | V24: =S24+P24 -> 790 | W24: =T24+Q24 -> 0 | X24: =W24/V24-1 -> -1 | AA24: =Z24/Y24-1 -> #DIV/0! | AB24: =Y24+V24 -> 790 | AC24: =Z24+W24 -> 0 | AD24: =AC24/AB24-1 -> -1 | AG24: =AF24/AE24-1 -> #DIV/0! | AH24: =AE24+AB24 -> 790 | AI24: =AF24+AC24 -> 0 | AJ24: =AI24/AH24-1 -> -1 | AM24: =AL24/AK24-1 -> #DIV/0! | AN24: =AK24+AH24 -> 790 | AO24: =AL24+AI24 -> 0 | AP24: =AO24/AN24-1 -> -1 | AS24: =AR24/AQ24-1 -> #DIV/0! | AT24: =AQ24+AN24 -> 790 | AU24: =AR24+AO24 -> 0 | AV24: =AU24/AT24-1 -> -1 | AY24: =AX24/AW24-1 -> #DIV/0! | AZ24: =AW24+AT24 -> 790 | BA24: =AX24+AU24 -> 0 | BB24: =BA24/AZ24-1 -> -1 | BE24: =BD24/BC24-1 -> #DIV/0! | BF24: =BC24+AZ24 -> 790 | BG24: =BD24+BA24 -> 0 | BH24: =BG24/BF24-1 -> -1 | BK24: =BJ24/BI24-1 -> #DIV/0! | BL24: =BI24+BF24 -> 790 | BM24: =BJ24+BG24 -> 0 | BN24: =BM24/BL24-1 -> -1 | BQ24: 790 | BR24: =BM24/10000/I24 -> #DIV/0!
A25: 杭州 | B25: 杭州 | C25: 杭州汇意商贸有限公司 | D25: 暖通 | E25: 暖通 | F25: 杭州市区 | G25: 拱墅区 | H25: 陈雪君 | L25: =K25/J25-1 -> #DIV/0! | O25: =N25/M25-1 -> #DIV/0! | P25: =J25+M25 -> 0 | Q25: =K25+N25 -> 0 | R25: =Q25/P25-1 -> #DIV/0! | U25: =T25/S25-1 -> #DIV/0! | V25: =S25+P25 -> 0 | W25: =T25+Q25 -> 0 | X25: =W25/V25-1 -> #DIV/0! | AA25: =Z25/Y25-1 -> #DIV/0! | AB25: =Y25+V25 -> 0 | AC25: =Z25+W25 -> 0 | AD25: =AC25/AB25-1 -> #DIV/0! | AG25: =AF25/AE25-1 -> #DIV/0! | AH25: =AE25+AB25 -> 0 | AI25: =AF25+AC25 -> 0 | AJ25: =AI25/AH25-1 -> #DIV/0! | AM25: =AL25/AK25-1 -> #DIV/0! | AN25: =AK25+AH25 -> 0 | AO25: =AL25+AI25 -> 0 | AP25: =AO25/AN25-1 -> #DIV/0! | AS25: =AR25/AQ25-1 -> #DIV/0! | AT25: =AQ25+AN25 -> 0 | AU25: =AR25+AO25 -> 0 | AV25: =AU25/AT25-1 -> #DIV/0! | AY25: =AX25/AW25-1 -> #DIV/0! | AZ25: =AW25+AT25 -> 0 | BA25: =AX25+AU25 -> 0 | BB25: =BA25/AZ25-1 -> #DIV/0! | BE25: =BD25/BC25-1 -> #DIV/0! | BF25: =BC25+AZ25 -> 0 | BG25: =BD25+BA25 -> 0 | BH25: =BG25/BF25-1 -> #DIV/0! | BI25: 12039 | BK25: =BJ25/BI25-1 -> -1 | BL25: =BI25+BF25 -> 12039 | BM25: =BJ25+BG25 -> 0 | BN25: =BM25/BL25-1 -> -1 | BQ25: 12039 | BR25: =BM25/10000/I25 -> #DIV/0!
A26: 杭州 | B26: 杭州 | C26: 浙江初韵供应链管理有限公司 | D26: 经销 | E26: 经销 | F26: 杭州市区 | G26: 上城区 | H26: 董培培 | I26: 24 | J26: 20000 | K26: 10000 | L26: =K26/J26-1 -> -0.5 | O26: =N26/M26-1 -> #DIV/0! | P26: =J26+M26 -> 20000 | Q26: =K26+N26 -> 10000 | R26: =Q26/P26-1 -> -0.5 | S26: 40000 | T26: 24752.5 | U26: =T26/S26-1 -> -0.3811875 | V26: =S26+P26 -> 60000 | W26: =T26+Q26 -> 34752.5 | X26: =W26/V26-1 -> -0.42079167 | Y26: 30000 | AA26: =Z26/Y26-1 -> -1 | AB26: =Y26+V26 -> 90000 | AC26: =Z26+W26 -> 34752.5 | AD26: =AC26/AB26-1 -> -0.61386111 | AE26: 40100 | AG26: =AF26/AE26-1 -> -1 | AH26: =AE26+AB26 -> 130100 | AI26: =AF26+AC26 -> 34752.5 | AJ26: =AI26/AH26-1 -> -0.73287855 | AM26: =AL26/AK26-1 -> #DIV/0! | AN26: =AK26+AH26 -> 130100 | AO26: =AL26+AI26 -> 34752.5 | AP26: =AO26/AN26-1 -> -0.73287855 | AQ26: 20000 | AS26: =AR26/AQ26-1 -> -1 | AT26: =AQ26+AN26 -> 150100 | AU26: =AR26+AO26 -> 34752.5 | AV26: =AU26/AT26-1 -> -0.76847102 | AW26: 20000 | AY26: =AX26/AW26-1 -> -1 | AZ26: =AW26+AT26 -> 170100 | BA26: =AX26+AU26 -> 34752.5 | BB26: =BA26/AZ26-1 -> -0.79569371 | BD26: 20000 | BE26: =BD26/BC26-1 -> #DIV/0! | BF26: =BC26+AZ26 -> 170100 | BG26: =BD26+BA26 -> 54752.5 | BH26: =BG26/BF26-1 -> -0.67811581 | BI26: 11428 | BK26: =BJ26/BI26-1 -> -1 | BL26: =BI26+BF26 -> 181528 | BM26: =BJ26+BG26 -> 54752.5 | BN26: =BM26/BL26-1 -> -0.69837986 | BO26: 20000 | BP26: 20000 | BQ26: 221528 | BR26: =BM26/10000/I26 -> 0.22813542
A27: 杭州 | B27: 杭州 | C27: 杭州红星美凯龙一号店 | D27: 直营 | E27: 直营 | F27: 杭州市区 | G27: 西湖风景名胜区 | H27: 专卖店 | I27: 400 | J27: 304654 | K27: 248878.5 | L27: =K27/J27-1 -> -0.18307818 | M27: 67549 | N27: 359062 | O27: =N27/M27-1 -> 4.3155783 | P27: =J27+M27 -> 372203 | Q27: =K27+N27 -> 607940.5 | R27: =Q27/P27-1 -> 0.63335733 | S27: 191851 | T27: 586860 | U27: =T27/S27-1 -> 2.0589364 | V27: =S27+P27 -> 564054 | W27: =T27+Q27 -> 1194800.5 | X27: =W27/V27-1 -> 1.1182378 | Y27: 73138 | Z27: 381502 | AA27: =Z27/Y27-1 -> 4.216194 | AB27: =Y27+V27 -> 637192 | AC27: =Z27+W27 -> 1576302.5 | AD27: =AC27/AB27-1 -> 1.4738266 | AE27: 208668 | AF27: 418566 | AG27: =AF27/AE27-1 -> 1.0058945 | AH27: =AE27+AB27 -> 845860 | AI27: =AF27+AC27 -> 1994868.5 | AJ27: =AI27/AH27-1 -> 1.3583909 | AK27: 296204 | AL27: 579201 | AM27: =AL27/AK27-1 -> 0.95541249 | AN27: =AK27+AH27 -> 1142064 | AO27: =AL27+AI27 -> 2574069.5 | AP27: =AO27/AN27-1 -> 1.253875 | AQ27: 217892 | AR27: 250281 | AS27: =AR27/AQ27-1 -> 0.14864704 | AT27: =AQ27+AN27 -> 1359956 | AU27: =AR27+AO27 -> 2824350.5 | AV27: =AU27/AT27-1 -> 1.0767955 | AW27: 307848 | AX27: 403353 | AY27: =AX27/AW27-1 -> 0.31023427 | AZ27: =AW27+AT27 -> 1667804 | BA27: =AX27+AU27 -> 3227703.5 | BB27: =BA27/AZ27-1 -> 0.93530145 | BC27: 427373 | BD27: 322595 | BE27: =BD27/BC27-1 -> -0.24516757 | BF27: =BC27+AZ27 -> 2095177 | BG27: =BD27+BA27 -> 3550298.5 | BH27: =BG27/BF27-1 -> 0.69451006 | BI27: 677990.8 | BJ27: 300290.75 | BK27: =BJ27/BI27-1 -> -0.55708728 | BL27: =BI27+BF27 -> 2773167.8 | BM27: =BJ27+BG27 -> 3850589.2 | BN27: =BM27/BL27-1 -> 0.3885165 | BO27: 260034.45 | BP27: 408726.6 | BQ27: 3441928.9 | BR27: =BM27/10000/I27 -> 0.96264731
A28: 杭州 | B28: 杭州 | C28: 杭州德业电器有限公司 | D28: 经销 | E28: 经销 | F28: 杭州市区 | G28: 上城区 | H28: 吴海林 | I28: 0 | J28: 4124 | L28: =K28/J28-1 -> -1 | O28: =N28/M28-1 -> #DIV/0! | P28: =J28+M28 -> 4124 | Q28: =K28+N28 -> 0 | R28: =Q28/P28-1 -> -1 | S28: 4124 | U28: =T28/S28-1 -> -1 | V28: =S28+P28 -> 8248 | W28: =T28+Q28 -> 0 | X28: =W28/V28-1 -> -1 | AA28: =Z28/Y28-1 -> #DIV/0! | AB28: =Y28+V28 -> 8248 | AC28: =Z28+W28 -> 0 | AD28: =AC28/AB28-1 -> -1 | AG28: =AF28/AE28-1 -> #DIV/0! | AH28: =AE28+AB28 -> 8248 | AI28: =AF28+AC28 -> 0 | AJ28: =AI28/AH28-1 -> -1 | AM28: =AL28/AK28-1 -> #DIV/0! | AN28: =AK28+AH28 -> 8248 | AO28: =AL28+AI28 -> 0 | AP28: =AO28/AN28-1 -> -1 | AS28: =AR28/AQ28-1 -> #DIV/0! | AT28: =AQ28+AN28 -> 8248 | AU28: =AR28+AO28 -> 0 | AV28: =AU28/AT28-1 -> -1 | AY28: =AX28/AW28-1 -> #DIV/0! | AZ28: =AW28+AT28 -> 8248 | BA28: =AX28+AU28 -> 0 | BB28: =BA28/AZ28-1 -> -1 | BE28: =BD28/BC28-1 -> #DIV/0! | BF28: =BC28+AZ28 -> 8248 | BG28: =BD28+BA28 -> 0 | BH28: =BG28/BF28-1 -> -1 | BK28: =BJ28/BI28-1 -> #DIV/0! | BL28: =BI28+BF28 -> 8248 | BM28: =BJ28+BG28 -> 0 | BN28: =BM28/BL28-1 -> -1 | BQ28: 8248 | BR28: =BM28/10000/I28 -> #DIV/0!
A29: 杭州 | B29: 杭州 | C29: 杭州市余杭区临平街道泽晨材料商行 | D29: 经销 | E29: 经销 | F29: 临平区 | G29: 临平区 | H29: 吴海林 | J29: 10000 | L29: =K29/J29-1 -> -1 | O29: =N29/M29-1 -> #DIV/0! | P29: =J29+M29 -> 10000 | Q29: =K29+N29 -> 0 | R29: =Q29/P29-1 -> -1 | U29: =T29/S29-1 -> #DIV/0! | V29: =S29+P29 -> 10000 | W29: =T29+Q29 -> 0 | X29: =W29/V29-1 -> -1 | AA29: =Z29/Y29-1 -> #DIV/0! | AB29: =Y29+V29 -> 10000 | AC29: =Z29+W29 -> 0 | AD29: =AC29/AB29-1 -> -1 | AG29: =AF29/AE29-1 -> #DIV/0! | AH29: =AE29+AB29 -> 10000 | AI29: =AF29+AC29 -> 0 | AJ29: =AI29/AH29-1 -> -1 | AM29: =AL29/AK29-1 -> #DIV/0! | AN29: =AK29+AH29 -> 10000 | AO29: =AL29+AI29 -> 0 | AP29: =AO29/AN29-1 -> -1 | AS29: =AR29/AQ29-1 -> #DIV/0! | AT29: =AQ29+AN29 -> 10000 | AU29: =AR29+AO29 -> 0 | AV29: =AU29/AT29-1 -> -1 | AW29: 491 | AY29: =AX29/AW29-1 -> -1 | AZ29: =AW29+AT29 -> 10491 | BA29: =AX29+AU29 -> 0 | BB29: =BA29/AZ29-1 -> -1 | BE29: =BD29/BC29-1 -> #DIV/0! | BF29: =BC29+AZ29 -> 10491 | BG29: =BD29+BA29 -> 0 | BH29: =BG29/BF29-1 -> -1 | BK29: =BJ29/BI29-1 -> #DIV/0! | BL29: =BI29+BF29 -> 10491 | BM29: =BJ29+BG29 -> 0 | BN29: =BM29/BL29-1 -> -1 | BQ29: 10491 | BR29: =BM29/10000/I29 -> #DIV/0!
A30: 杭州 | B30: 杭州 | C30: 浙江顶戴环境设备有限公司 | D30: 暖通 | E30: 暖通 | F30: 杭州市区 | G30: 钱塘区 | H30: 陈雪君 | J30: 2591 | L30: =K30/J30-1 -> -1 | O30: =N30/M30-1 -> #DIV/0! | P30: =J30+M30 -> 2591 | Q30: =K30+N30 -> 0 | R30: =Q30/P30-1 -> -1 | U30: =T30/S30-1 -> #DIV/0! | V30: =S30+P30 -> 2591 | W30: =T30+Q30 -> 0 | X30: =W30/V30-1 -> -1 | AA30: =Z30/Y30-1 -> #DIV/0! | AB30: =Y30+V30 -> 2591 | AC30: =Z30+W30 -> 0 | AD30: =AC30/AB30-1 -> -1 | AG30: =AF30/AE30-1 -> #DIV/0! | AH30: =AE30+AB30 -> 2591 | AI30: =AF30+AC30 -> 0 | AJ30: =AI30/AH30-1 -> -1 | AM30: =AL30/AK30-1 -> #DIV/0! | AN30: =AK30+AH30 -> 2591 | AO30: =AL30+AI30 -> 0 | AP30: =AO30/AN30-1 -> -1 | AS30: =AR30/AQ30-1 -> #DIV/0! | AT30: =AQ30+AN30 -> 2591 | AU30: =AR30+AO30 -> 0 | AV30: =AU30/AT30-1 -> -1 | AY30: =AX30/AW30-1 -> #DIV/0! | AZ30: =AW30+AT30 -> 2591 | BA30: =AX30+AU30 -> 0 | BB30: =BA30/AZ30-1 -> -1 | BE30: =BD30/BC30-1 -> #DIV/0! | BF30: =BC30+AZ30 -> 2591 | BG30: =BD30+BA30 -> 0 | BH30: =BG30/BF30-1 -> -1 | BK30: =BJ30/BI30-1 -> #DIV/0! | BL30: =BI30+BF30 -> 2591 | BM30: =BJ30+BG30 -> 0 | BN30: =BM30/BL30-1 -> -1 | BQ30: 2591 | BR30: =BM30/10000/I30 -> #DIV/0!
A31: 杭州 | B31: 杭州 | C31: 浙江元天电子商务有限公司 | D31: 经销 | E31: 经销 | F31: 杭州市区 | G31: 滨江区 | H31: 黄颖 | I31: 30 | J31: 20582 | K31: 14679 | L31: =K31/J31-1 -> -0.286804 | M31: 3939 | O31: =N31/M31-1 -> -1 | P31: =J31+M31 -> 24521 | Q31: =K31+N31 -> 14679 | R31: =Q31/P31-1 -> -0.40137025 | T31: 3148 | U31: =T31/S31-1 -> #DIV/0! | V31: =S31+P31 -> 24521 | W31: =T31+Q31 -> 17827 | X31: =W31/V31-1 -> -0.2729905 | Y31: 23069 | Z31: 13909 | AA31: =Z31/Y31-1 -> -0.39706966 | AB31: =Y31+V31 -> 47590 | AC31: =Z31+W31 -> 31736 | AD31: =AC31/AB31-1 -> -0.33313721 | AE31: 27908 | AF31: 8765 | AG31: =AF31/AE31-1 -> -0.68593235 | AH31: =AE31+AB31 -> 75498 | AI31: =AF31+AC31 -> 40501 | AJ31: =AI31/AH31-1 -> -0.4635487 | AK31: 25192 | AL31: 9307 | AM31: =AL31/AK31-1 -> -0.63055732 | AN31: =AK31+AH31 -> 100690 | AO31: =AL31+AI31 -> 49808 | AP31: =AO31/AN31-1 -> -0.5053332 | AR31: 11183 | AS31: =AR31/AQ31-1 -> #DIV/0! | AT31: =AQ31+AN31 -> 100690 | AU31: =AR31+AO31 -> 60991 | AV31: =AU31/AT31-1 -> -0.39426954 | AW31: 16800 | AX31: 6109 | AY31: =AX31/AW31-1 -> -0.63636905 | AZ31: =AW31+AT31 -> 117490 | BA31: =AX31+AU31 -> 67100 | BB31: =BA31/AZ31-1 -> -0.42888756 | BC31: 24480 | BE31: =BD31/BC31-1 -> -1 | BF31: =BC31+AZ31 -> 141970 | BG31: =BD31+BA31 -> 67100 | BH31: =BG31/BF31-1 -> -0.52736494 | BK31: =BJ31/BI31-1 -> #DIV/0! | BL31: =BI31+BF31 -> 141970 | BM31: =BJ31+BG31 -> 67100 | BN31: =BM31/BL31-1 -> -0.52736494 | BO31: 18985 | BQ31: 160955 | BR31: =BM31/10000/I31 -> 0.22366667
A32: 杭州 | B32: 杭州 | C32: 杭州澎湃电器有限公司 | D32: 家装 | E32: 家装 | F32: 杭州市区 | G32: 上城区 | H32: 黄颖 | J32: 7088 | L32: =K32/J32-1 -> -1 | O32: =N32/M32-1 -> #DIV/0! | P32: =J32+M32 -> 7088 | Q32: =K32+N32 -> 0 | R32: =Q32/P32-1 -> -1 | U32: =T32/S32-1 -> #DIV/0! | V32: =S32+P32 -> 7088 | W32: =T32+Q32 -> 0 | X32: =W32/V32-1 -> -1 | AA32: =Z32/Y32-1 -> #DIV/0! | AB32: =Y32+V32 -> 7088 | AC32: =Z32+W32 -> 0 | AD32: =AC32/AB32-1 -> -1 | AG32: =AF32/AE32-1 -> #DIV/0! | AH32: =AE32+AB32 -> 7088 | AI32: =AF32+AC32 -> 0 | AJ32: =AI32/AH32-1 -> -1 | AM32: =AL32/AK32-1 -> #DIV/0! | AN32: =AK32+AH32 -> 7088 | AO32: =AL32+AI32 -> 0 | AP32: =AO32/AN32-1 -> -1 | AS32: =AR32/AQ32-1 -> #DIV/0! | AT32: =AQ32+AN32 -> 7088 | AU32: =AR32+AO32 -> 0 | AV32: =AU32/AT32-1 -> -1 | AY32: =AX32/AW32-1 -> #DIV/0! | AZ32: =AW32+AT32 -> 7088 | BA32: =AX32+AU32 -> 0 | BB32: =BA32/AZ32-1 -> -1 | BE32: =BD32/BC32-1 -> #DIV/0! | BF32: =BC32+AZ32 -> 7088 | BG32: =BD32+BA32 -> 0 | BH32: =BG32/BF32-1 -> -1 | BK32: =BJ32/BI32-1 -> #DIV/0! | BL32: =BI32+BF32 -> 7088 | BM32: =BJ32+BG32 -> 0 | BN32: =BM32/BL32-1 -> -1 | BQ32: 7088 | BR32: =BM32/10000/I32 -> #DIV/0!
